INFO - 2022-09-18 03:48:04,702 - process: 9156 - scheduler.py - gerapy.server.core.scheduler - 105 - scheduler - successfully synced task with jobs with force
ERROR - 2022-09-18 03:50:05,864 - process: 9156 - utils.py - gerapy.server.core.utils - 564 - utils - HTTPConnectionPool(host='http', port=80): Max retries exceeded with url: //192.168.1.103:6800 (Caused by NewConnectionError('<urllib3.connection.HTTPConnection object at 0x00000207219862B0>: Failed to establish a new connection: [Errno 11001] getaddrinfo failed'))
Traceback (most recent call last):
  File "E:\pythonProject\venv\lib\site-packages\urllib3\connection.py", line 174, in _new_conn
    conn = connection.create_connection(
  File "E:\pythonProject\venv\lib\site-packages\urllib3\util\connection.py", line 72, in create_connection
    for res in socket.getaddrinfo(host, port, family, socket.SOCK_STREAM):
  File "D:\develop\python\python\lib\socket.py", line 954, in getaddrinfo
    for res in _socket.getaddrinfo(host, port, family, type, proto, flags):
socket.gaierror: [Errno 11001] getaddrinfo failed

During handling of the above exception, another exception occurred:

Traceback (most recent call last):
  File "E:\pythonProject\venv\lib\site-packages\urllib3\connectionpool.py", line 703, in urlopen
    httplib_response = self._make_request(
  File "E:\pythonProject\venv\lib\site-packages\urllib3\connectionpool.py", line 398, in _make_request
    conn.request(method, url, **httplib_request_kw)
  File "E:\pythonProject\venv\lib\site-packages\urllib3\connection.py", line 239, in request
    super(HTTPConnection, self).request(method, url, body=body, headers=headers)
  File "D:\develop\python\python\lib\http\client.py", line 1285, in request
    self._send_request(method, url, body, headers, encode_chunked)
  File "D:\develop\python\python\lib\http\client.py", line 1331, in _send_request
    self.endheaders(body, encode_chunked=encode_chunked)
  File "D:\develop\python\python\lib\http\client.py", line 1280, in endheaders
    self._send_output(message_body, encode_chunked=encode_chunked)
  File "D:\develop\python\python\lib\http\client.py", line 1040, in _send_output
    self.send(msg)
  File "D:\develop\python\python\lib\http\client.py", line 980, in send
    self.connect()
  File "E:\pythonProject\venv\lib\site-packages\urllib3\connection.py", line 205, in connect
    conn = self._new_conn()
  File "E:\pythonProject\venv\lib\site-packages\urllib3\connection.py", line 186, in _new_conn
    raise NewConnectionError(
urllib3.exceptions.NewConnectionError: <urllib3.connection.HTTPConnection object at 0x00000207219862B0>: Failed to establish a new connection: [Errno 11001] getaddrinfo failed

During handling of the above exception, another exception occurred:

Traceback (most recent call last):
  File "E:\pythonProject\venv\lib\site-packages\requests\adapters.py", line 440, in send
    resp = conn.urlopen(
  File "E:\pythonProject\venv\lib\site-packages\urllib3\connectionpool.py", line 785, in urlopen
    retries = retries.increment(
  File "E:\pythonProject\venv\lib\site-packages\urllib3\util\retry.py", line 592, in increment
    raise MaxRetryError(_pool, url, error or ResponseError(cause))
urllib3.exceptions.MaxRetryError: HTTPConnectionPool(host='http', port=80): Max retries exceeded with url: //192.168.1.103:6800 (Caused by NewConnectionError('<urllib3.connection.HTTPConnection object at 0x00000207219862B0>: Failed to establish a new connection: [Errno 11001] getaddrinfo failed'))

During handling of the above exception, another exception occurred:

Traceback (most recent call last):
  File "E:\pythonProject\venv\lib\site-packages\gerapy\server\core\utils.py", line 562, in wrapper
    result = func(*args, **kwargs)
  File "E:\pythonProject\venv\lib\site-packages\django\views\decorators\csrf.py", line 54, in wrapped_view
    return view_func(*args, **kwargs)
  File "E:\pythonProject\venv\lib\site-packages\django\views\generic\base.py", line 71, in view
    return self.dispatch(request, *args, **kwargs)
  File "E:\pythonProject\venv\lib\site-packages\rest_framework\views.py", line 509, in dispatch
    response = self.handle_exception(exc)
  File "E:\pythonProject\venv\lib\site-packages\rest_framework\views.py", line 469, in handle_exception
    self.raise_uncaught_exception(exc)
  File "E:\pythonProject\venv\lib\site-packages\rest_framework\views.py", line 480, in raise_uncaught_exception
    raise exc
  File "E:\pythonProject\venv\lib\site-packages\rest_framework\views.py", line 506, in dispatch
    response = handler(request, *args, **kwargs)
  File "E:\pythonProject\venv\lib\site-packages\rest_framework\decorators.py", line 50, in handler
    return func(*args, **kwargs)
  File "E:\pythonProject\venv\lib\site-packages\gerapy\server\core\views.py", line 120, in client_status
    requests.get(scrapyd_url(client.ip, client.port), timeout=3)
  File "E:\pythonProject\venv\lib\site-packages\requests\api.py", line 75, in get
    return request('get', url, params=params, **kwargs)
  File "E:\pythonProject\venv\lib\site-packages\requests\api.py", line 61, in request
    return session.request(method=method, url=url, **kwargs)
  File "E:\pythonProject\venv\lib\site-packages\requests\sessions.py", line 529, in request
    resp = self.send(prep, **send_kwargs)
  File "E:\pythonProject\venv\lib\site-packages\requests\sessions.py", line 645, in send
    r = adapter.send(request, **kwargs)
  File "E:\pythonProject\venv\lib\site-packages\requests\adapters.py", line 519, in send
    raise ConnectionError(e, request=request)
requests.exceptions.ConnectionError: HTTPConnectionPool(host='http', port=80): Max retries exceeded with url: //192.168.1.103:6800 (Caused by NewConnectionError('<urllib3.connection.HTTPConnection object at 0x00000207219862B0>: Failed to establish a new connection: [Errno 11001] getaddrinfo failed'))
ERROR - 2022-09-18 03:50:10,486 - process: 9156 - utils.py - gerapy.server.core.utils - 564 - utils - HTTPConnectionPool(host='http', port=80): Max retries exceeded with url: //192.168.1.103:6800 (Caused by NewConnectionError('<urllib3.connection.HTTPConnection object at 0x0000020721900550>: Failed to establish a new connection: [Errno 11001] getaddrinfo failed'))
Traceback (most recent call last):
  File "E:\pythonProject\venv\lib\site-packages\urllib3\connection.py", line 174, in _new_conn
    conn = connection.create_connection(
  File "E:\pythonProject\venv\lib\site-packages\urllib3\util\connection.py", line 72, in create_connection
    for res in socket.getaddrinfo(host, port, family, socket.SOCK_STREAM):
  File "D:\develop\python\python\lib\socket.py", line 954, in getaddrinfo
    for res in _socket.getaddrinfo(host, port, family, type, proto, flags):
socket.gaierror: [Errno 11001] getaddrinfo failed

During handling of the above exception, another exception occurred:

Traceback (most recent call last):
  File "E:\pythonProject\venv\lib\site-packages\urllib3\connectionpool.py", line 703, in urlopen
    httplib_response = self._make_request(
  File "E:\pythonProject\venv\lib\site-packages\urllib3\connectionpool.py", line 398, in _make_request
    conn.request(method, url, **httplib_request_kw)
  File "E:\pythonProject\venv\lib\site-packages\urllib3\connection.py", line 239, in request
    super(HTTPConnection, self).request(method, url, body=body, headers=headers)
  File "D:\develop\python\python\lib\http\client.py", line 1285, in request
    self._send_request(method, url, body, headers, encode_chunked)
  File "D:\develop\python\python\lib\http\client.py", line 1331, in _send_request
    self.endheaders(body, encode_chunked=encode_chunked)
  File "D:\develop\python\python\lib\http\client.py", line 1280, in endheaders
    self._send_output(message_body, encode_chunked=encode_chunked)
  File "D:\develop\python\python\lib\http\client.py", line 1040, in _send_output
    self.send(msg)
  File "D:\develop\python\python\lib\http\client.py", line 980, in send
    self.connect()
  File "E:\pythonProject\venv\lib\site-packages\urllib3\connection.py", line 205, in connect
    conn = self._new_conn()
  File "E:\pythonProject\venv\lib\site-packages\urllib3\connection.py", line 186, in _new_conn
    raise NewConnectionError(
urllib3.exceptions.NewConnectionError: <urllib3.connection.HTTPConnection object at 0x0000020721900550>: Failed to establish a new connection: [Errno 11001] getaddrinfo failed

During handling of the above exception, another exception occurred:

Traceback (most recent call last):
  File "E:\pythonProject\venv\lib\site-packages\requests\adapters.py", line 440, in send
    resp = conn.urlopen(
  File "E:\pythonProject\venv\lib\site-packages\urllib3\connectionpool.py", line 785, in urlopen
    retries = retries.increment(
  File "E:\pythonProject\venv\lib\site-packages\urllib3\util\retry.py", line 592, in increment
    raise MaxRetryError(_pool, url, error or ResponseError(cause))
urllib3.exceptions.MaxRetryError: HTTPConnectionPool(host='http', port=80): Max retries exceeded with url: //192.168.1.103:6800 (Caused by NewConnectionError('<urllib3.connection.HTTPConnection object at 0x0000020721900550>: Failed to establish a new connection: [Errno 11001] getaddrinfo failed'))

During handling of the above exception, another exception occurred:

Traceback (most recent call last):
  File "E:\pythonProject\venv\lib\site-packages\gerapy\server\core\utils.py", line 562, in wrapper
    result = func(*args, **kwargs)
  File "E:\pythonProject\venv\lib\site-packages\django\views\decorators\csrf.py", line 54, in wrapped_view
    return view_func(*args, **kwargs)
  File "E:\pythonProject\venv\lib\site-packages\django\views\generic\base.py", line 71, in view
    return self.dispatch(request, *args, **kwargs)
  File "E:\pythonProject\venv\lib\site-packages\rest_framework\views.py", line 509, in dispatch
    response = self.handle_exception(exc)
  File "E:\pythonProject\venv\lib\site-packages\rest_framework\views.py", line 469, in handle_exception
    self.raise_uncaught_exception(exc)
  File "E:\pythonProject\venv\lib\site-packages\rest_framework\views.py", line 480, in raise_uncaught_exception
    raise exc
  File "E:\pythonProject\venv\lib\site-packages\rest_framework\views.py", line 506, in dispatch
    response = handler(request, *args, **kwargs)
  File "E:\pythonProject\venv\lib\site-packages\rest_framework\decorators.py", line 50, in handler
    return func(*args, **kwargs)
  File "E:\pythonProject\venv\lib\site-packages\gerapy\server\core\views.py", line 120, in client_status
    requests.get(scrapyd_url(client.ip, client.port), timeout=3)
  File "E:\pythonProject\venv\lib\site-packages\requests\api.py", line 75, in get
    return request('get', url, params=params, **kwargs)
  File "E:\pythonProject\venv\lib\site-packages\requests\api.py", line 61, in request
    return session.request(method=method, url=url, **kwargs)
  File "E:\pythonProject\venv\lib\site-packages\requests\sessions.py", line 529, in request
    resp = self.send(prep, **send_kwargs)
  File "E:\pythonProject\venv\lib\site-packages\requests\sessions.py", line 645, in send
    r = adapter.send(request, **kwargs)
  File "E:\pythonProject\venv\lib\site-packages\requests\adapters.py", line 519, in send
    raise ConnectionError(e, request=request)
requests.exceptions.ConnectionError: HTTPConnectionPool(host='http', port=80): Max retries exceeded with url: //192.168.1.103:6800 (Caused by NewConnectionError('<urllib3.connection.HTTPConnection object at 0x0000020721900550>: Failed to establish a new connection: [Errno 11001] getaddrinfo failed'))
ERROR - 2022-09-18 03:50:16,337 - process: 9156 - utils.py - gerapy.server.core.utils - 564 - utils - HTTPConnectionPool(host='http', port=80): Max retries exceeded with url: //192.168.1.103:6800 (Caused by NewConnectionError('<urllib3.connection.HTTPConnection object at 0x000002072197E7C0>: Failed to establish a new connection: [Errno 11001] getaddrinfo failed'))
Traceback (most recent call last):
  File "E:\pythonProject\venv\lib\site-packages\urllib3\connection.py", line 174, in _new_conn
    conn = connection.create_connection(
  File "E:\pythonProject\venv\lib\site-packages\urllib3\util\connection.py", line 72, in create_connection
    for res in socket.getaddrinfo(host, port, family, socket.SOCK_STREAM):
  File "D:\develop\python\python\lib\socket.py", line 954, in getaddrinfo
    for res in _socket.getaddrinfo(host, port, family, type, proto, flags):
socket.gaierror: [Errno 11001] getaddrinfo failed

During handling of the above exception, another exception occurred:

Traceback (most recent call last):
  File "E:\pythonProject\venv\lib\site-packages\urllib3\connectionpool.py", line 703, in urlopen
    httplib_response = self._make_request(
  File "E:\pythonProject\venv\lib\site-packages\urllib3\connectionpool.py", line 398, in _make_request
    conn.request(method, url, **httplib_request_kw)
  File "E:\pythonProject\venv\lib\site-packages\urllib3\connection.py", line 239, in request
    super(HTTPConnection, self).request(method, url, body=body, headers=headers)
  File "D:\develop\python\python\lib\http\client.py", line 1285, in request
    self._send_request(method, url, body, headers, encode_chunked)
  File "D:\develop\python\python\lib\http\client.py", line 1331, in _send_request
    self.endheaders(body, encode_chunked=encode_chunked)
  File "D:\develop\python\python\lib\http\client.py", line 1280, in endheaders
    self._send_output(message_body, encode_chunked=encode_chunked)
  File "D:\develop\python\python\lib\http\client.py", line 1040, in _send_output
    self.send(msg)
  File "D:\develop\python\python\lib\http\client.py", line 980, in send
    self.connect()
  File "E:\pythonProject\venv\lib\site-packages\urllib3\connection.py", line 205, in connect
    conn = self._new_conn()
  File "E:\pythonProject\venv\lib\site-packages\urllib3\connection.py", line 186, in _new_conn
    raise NewConnectionError(
urllib3.exceptions.NewConnectionError: <urllib3.connection.HTTPConnection object at 0x000002072197E7C0>: Failed to establish a new connection: [Errno 11001] getaddrinfo failed

During handling of the above exception, another exception occurred:

Traceback (most recent call last):
  File "E:\pythonProject\venv\lib\site-packages\requests\adapters.py", line 440, in send
    resp = conn.urlopen(
  File "E:\pythonProject\venv\lib\site-packages\urllib3\connectionpool.py", line 785, in urlopen
    retries = retries.increment(
  File "E:\pythonProject\venv\lib\site-packages\urllib3\util\retry.py", line 592, in increment
    raise MaxRetryError(_pool, url, error or ResponseError(cause))
urllib3.exceptions.MaxRetryError: HTTPConnectionPool(host='http', port=80): Max retries exceeded with url: //192.168.1.103:6800 (Caused by NewConnectionError('<urllib3.connection.HTTPConnection object at 0x000002072197E7C0>: Failed to establish a new connection: [Errno 11001] getaddrinfo failed'))

During handling of the above exception, another exception occurred:

Traceback (most recent call last):
  File "E:\pythonProject\venv\lib\site-packages\gerapy\server\core\utils.py", line 562, in wrapper
    result = func(*args, **kwargs)
  File "E:\pythonProject\venv\lib\site-packages\django\views\decorators\csrf.py", line 54, in wrapped_view
    return view_func(*args, **kwargs)
  File "E:\pythonProject\venv\lib\site-packages\django\views\generic\base.py", line 71, in view
    return self.dispatch(request, *args, **kwargs)
  File "E:\pythonProject\venv\lib\site-packages\rest_framework\views.py", line 509, in dispatch
    response = self.handle_exception(exc)
  File "E:\pythonProject\venv\lib\site-packages\rest_framework\views.py", line 469, in handle_exception
    self.raise_uncaught_exception(exc)
  File "E:\pythonProject\venv\lib\site-packages\rest_framework\views.py", line 480, in raise_uncaught_exception
    raise exc
  File "E:\pythonProject\venv\lib\site-packages\rest_framework\views.py", line 506, in dispatch
    response = handler(request, *args, **kwargs)
  File "E:\pythonProject\venv\lib\site-packages\rest_framework\decorators.py", line 50, in handler
    return func(*args, **kwargs)
  File "E:\pythonProject\venv\lib\site-packages\gerapy\server\core\views.py", line 120, in client_status
    requests.get(scrapyd_url(client.ip, client.port), timeout=3)
  File "E:\pythonProject\venv\lib\site-packages\requests\api.py", line 75, in get
    return request('get', url, params=params, **kwargs)
  File "E:\pythonProject\venv\lib\site-packages\requests\api.py", line 61, in request
    return session.request(method=method, url=url, **kwargs)
  File "E:\pythonProject\venv\lib\site-packages\requests\sessions.py", line 529, in request
    resp = self.send(prep, **send_kwargs)
  File "E:\pythonProject\venv\lib\site-packages\requests\sessions.py", line 645, in send
    r = adapter.send(request, **kwargs)
  File "E:\pythonProject\venv\lib\site-packages\requests\adapters.py", line 519, in send
    raise ConnectionError(e, request=request)
requests.exceptions.ConnectionError: HTTPConnectionPool(host='http', port=80): Max retries exceeded with url: //192.168.1.103:6800 (Caused by NewConnectionError('<urllib3.connection.HTTPConnection object at 0x000002072197E7C0>: Failed to establish a new connection: [Errno 11001] getaddrinfo failed'))
ERROR - 2022-09-18 03:51:24,739 - process: 9156 - utils.py - gerapy.server.core.utils - 564 - utils - HTTPConnectionPool(host='http', port=80): Max retries exceeded with url: /listprojects.json (Caused by NewConnectionError('<urllib3.connection.HTTPConnection object at 0x000002072197E550>: Failed to establish a new connection: [Errno 11001] getaddrinfo failed'))
Traceback (most recent call last):
  File "E:\pythonProject\venv\lib\site-packages\urllib3\connection.py", line 174, in _new_conn
    conn = connection.create_connection(
  File "E:\pythonProject\venv\lib\site-packages\urllib3\util\connection.py", line 72, in create_connection
    for res in socket.getaddrinfo(host, port, family, socket.SOCK_STREAM):
  File "D:\develop\python\python\lib\socket.py", line 954, in getaddrinfo
    for res in _socket.getaddrinfo(host, port, family, type, proto, flags):
socket.gaierror: [Errno 11001] getaddrinfo failed

During handling of the above exception, another exception occurred:

Traceback (most recent call last):
  File "E:\pythonProject\venv\lib\site-packages\urllib3\connectionpool.py", line 703, in urlopen
    httplib_response = self._make_request(
  File "E:\pythonProject\venv\lib\site-packages\urllib3\connectionpool.py", line 398, in _make_request
    conn.request(method, url, **httplib_request_kw)
  File "E:\pythonProject\venv\lib\site-packages\urllib3\connection.py", line 239, in request
    super(HTTPConnection, self).request(method, url, body=body, headers=headers)
  File "D:\develop\python\python\lib\http\client.py", line 1285, in request
    self._send_request(method, url, body, headers, encode_chunked)
  File "D:\develop\python\python\lib\http\client.py", line 1331, in _send_request
    self.endheaders(body, encode_chunked=encode_chunked)
  File "D:\develop\python\python\lib\http\client.py", line 1280, in endheaders
    self._send_output(message_body, encode_chunked=encode_chunked)
  File "D:\develop\python\python\lib\http\client.py", line 1040, in _send_output
    self.send(msg)
  File "D:\develop\python\python\lib\http\client.py", line 980, in send
    self.connect()
  File "E:\pythonProject\venv\lib\site-packages\urllib3\connection.py", line 205, in connect
    conn = self._new_conn()
  File "E:\pythonProject\venv\lib\site-packages\urllib3\connection.py", line 186, in _new_conn
    raise NewConnectionError(
urllib3.exceptions.NewConnectionError: <urllib3.connection.HTTPConnection object at 0x000002072197E550>: Failed to establish a new connection: [Errno 11001] getaddrinfo failed

During handling of the above exception, another exception occurred:

Traceback (most recent call last):
  File "E:\pythonProject\venv\lib\site-packages\requests\adapters.py", line 440, in send
    resp = conn.urlopen(
  File "E:\pythonProject\venv\lib\site-packages\urllib3\connectionpool.py", line 785, in urlopen
    retries = retries.increment(
  File "E:\pythonProject\venv\lib\site-packages\urllib3\util\retry.py", line 592, in increment
    raise MaxRetryError(_pool, url, error or ResponseError(cause))
urllib3.exceptions.MaxRetryError: HTTPConnectionPool(host='http', port=80): Max retries exceeded with url: /listprojects.json (Caused by NewConnectionError('<urllib3.connection.HTTPConnection object at 0x000002072197E550>: Failed to establish a new connection: [Errno 11001] getaddrinfo failed'))

During handling of the above exception, another exception occurred:

Traceback (most recent call last):
  File "E:\pythonProject\venv\lib\site-packages\gerapy\server\core\utils.py", line 562, in wrapper
    result = func(*args, **kwargs)
  File "E:\pythonProject\venv\lib\site-packages\django\views\decorators\csrf.py", line 54, in wrapped_view
    return view_func(*args, **kwargs)
  File "E:\pythonProject\venv\lib\site-packages\django\views\generic\base.py", line 71, in view
    return self.dispatch(request, *args, **kwargs)
  File "E:\pythonProject\venv\lib\site-packages\rest_framework\views.py", line 509, in dispatch
    response = self.handle_exception(exc)
  File "E:\pythonProject\venv\lib\site-packages\rest_framework\views.py", line 469, in handle_exception
    self.raise_uncaught_exception(exc)
  File "E:\pythonProject\venv\lib\site-packages\rest_framework\views.py", line 480, in raise_uncaught_exception
    raise exc
  File "E:\pythonProject\venv\lib\site-packages\rest_framework\views.py", line 506, in dispatch
    response = handler(request, *args, **kwargs)
  File "E:\pythonProject\venv\lib\site-packages\rest_framework\decorators.py", line 50, in handler
    return func(*args, **kwargs)
  File "E:\pythonProject\venv\lib\site-packages\gerapy\server\core\views.py", line 227, in project_list
    projects = scrapyd.list_projects()
  File "E:\pythonProject\venv\lib\site-packages\scrapyd_api\wrapper.py", line 148, in list_projects
    json = self.client.get(url, timeout=self.timeout)
  File "E:\pythonProject\venv\lib\site-packages\requests\sessions.py", line 542, in get
    return self.request('GET', url, **kwargs)
  File "E:\pythonProject\venv\lib\site-packages\scrapyd_api\client.py", line 37, in request
    response = super(Client, self).request(*args, **kwargs)
  File "E:\pythonProject\venv\lib\site-packages\requests\sessions.py", line 529, in request
    resp = self.send(prep, **send_kwargs)
  File "E:\pythonProject\venv\lib\site-packages\requests\sessions.py", line 645, in send
    r = adapter.send(request, **kwargs)
  File "E:\pythonProject\venv\lib\site-packages\requests\adapters.py", line 519, in send
    raise ConnectionError(e, request=request)
requests.exceptions.ConnectionError: HTTPConnectionPool(host='http', port=80): Max retries exceeded with url: /listprojects.json (Caused by NewConnectionError('<urllib3.connection.HTTPConnection object at 0x000002072197E550>: Failed to establish a new connection: [Errno 11001] getaddrinfo failed'))
ERROR - 2022-09-18 03:51:27,220 - process: 9156 - utils.py - gerapy.server.core.utils - 564 - utils - HTTPConnectionPool(host='http', port=80): Max retries exceeded with url: //192.168.1.103:6800 (Caused by NewConnectionError('<urllib3.connection.HTTPConnection object at 0x00000207219869A0>: Failed to establish a new connection: [Errno 11001] getaddrinfo failed'))
Traceback (most recent call last):
  File "E:\pythonProject\venv\lib\site-packages\urllib3\connection.py", line 174, in _new_conn
    conn = connection.create_connection(
  File "E:\pythonProject\venv\lib\site-packages\urllib3\util\connection.py", line 72, in create_connection
    for res in socket.getaddrinfo(host, port, family, socket.SOCK_STREAM):
  File "D:\develop\python\python\lib\socket.py", line 954, in getaddrinfo
    for res in _socket.getaddrinfo(host, port, family, type, proto, flags):
socket.gaierror: [Errno 11001] getaddrinfo failed

During handling of the above exception, another exception occurred:

Traceback (most recent call last):
  File "E:\pythonProject\venv\lib\site-packages\urllib3\connectionpool.py", line 703, in urlopen
    httplib_response = self._make_request(
  File "E:\pythonProject\venv\lib\site-packages\urllib3\connectionpool.py", line 398, in _make_request
    conn.request(method, url, **httplib_request_kw)
  File "E:\pythonProject\venv\lib\site-packages\urllib3\connection.py", line 239, in request
    super(HTTPConnection, self).request(method, url, body=body, headers=headers)
  File "D:\develop\python\python\lib\http\client.py", line 1285, in request
    self._send_request(method, url, body, headers, encode_chunked)
  File "D:\develop\python\python\lib\http\client.py", line 1331, in _send_request
    self.endheaders(body, encode_chunked=encode_chunked)
  File "D:\develop\python\python\lib\http\client.py", line 1280, in endheaders
    self._send_output(message_body, encode_chunked=encode_chunked)
  File "D:\develop\python\python\lib\http\client.py", line 1040, in _send_output
    self.send(msg)
  File "D:\develop\python\python\lib\http\client.py", line 980, in send
    self.connect()
  File "E:\pythonProject\venv\lib\site-packages\urllib3\connection.py", line 205, in connect
    conn = self._new_conn()
  File "E:\pythonProject\venv\lib\site-packages\urllib3\connection.py", line 186, in _new_conn
    raise NewConnectionError(
urllib3.exceptions.NewConnectionError: <urllib3.connection.HTTPConnection object at 0x00000207219869A0>: Failed to establish a new connection: [Errno 11001] getaddrinfo failed

During handling of the above exception, another exception occurred:

Traceback (most recent call last):
  File "E:\pythonProject\venv\lib\site-packages\requests\adapters.py", line 440, in send
    resp = conn.urlopen(
  File "E:\pythonProject\venv\lib\site-packages\urllib3\connectionpool.py", line 785, in urlopen
    retries = retries.increment(
  File "E:\pythonProject\venv\lib\site-packages\urllib3\util\retry.py", line 592, in increment
    raise MaxRetryError(_pool, url, error or ResponseError(cause))
urllib3.exceptions.MaxRetryError: HTTPConnectionPool(host='http', port=80): Max retries exceeded with url: //192.168.1.103:6800 (Caused by NewConnectionError('<urllib3.connection.HTTPConnection object at 0x00000207219869A0>: Failed to establish a new connection: [Errno 11001] getaddrinfo failed'))

During handling of the above exception, another exception occurred:

Traceback (most recent call last):
  File "E:\pythonProject\venv\lib\site-packages\gerapy\server\core\utils.py", line 562, in wrapper
    result = func(*args, **kwargs)
  File "E:\pythonProject\venv\lib\site-packages\django\views\decorators\csrf.py", line 54, in wrapped_view
    return view_func(*args, **kwargs)
  File "E:\pythonProject\venv\lib\site-packages\django\views\generic\base.py", line 71, in view
    return self.dispatch(request, *args, **kwargs)
  File "E:\pythonProject\venv\lib\site-packages\rest_framework\views.py", line 509, in dispatch
    response = self.handle_exception(exc)
  File "E:\pythonProject\venv\lib\site-packages\rest_framework\views.py", line 469, in handle_exception
    self.raise_uncaught_exception(exc)
  File "E:\pythonProject\venv\lib\site-packages\rest_framework\views.py", line 480, in raise_uncaught_exception
    raise exc
  File "E:\pythonProject\venv\lib\site-packages\rest_framework\views.py", line 506, in dispatch
    response = handler(request, *args, **kwargs)
  File "E:\pythonProject\venv\lib\site-packages\rest_framework\decorators.py", line 50, in handler
    return func(*args, **kwargs)
  File "E:\pythonProject\venv\lib\site-packages\gerapy\server\core\views.py", line 120, in client_status
    requests.get(scrapyd_url(client.ip, client.port), timeout=3)
  File "E:\pythonProject\venv\lib\site-packages\requests\api.py", line 75, in get
    return request('get', url, params=params, **kwargs)
  File "E:\pythonProject\venv\lib\site-packages\requests\api.py", line 61, in request
    return session.request(method=method, url=url, **kwargs)
  File "E:\pythonProject\venv\lib\site-packages\requests\sessions.py", line 529, in request
    resp = self.send(prep, **send_kwargs)
  File "E:\pythonProject\venv\lib\site-packages\requests\sessions.py", line 645, in send
    r = adapter.send(request, **kwargs)
  File "E:\pythonProject\venv\lib\site-packages\requests\adapters.py", line 519, in send
    raise ConnectionError(e, request=request)
requests.exceptions.ConnectionError: HTTPConnectionPool(host='http', port=80): Max retries exceeded with url: //192.168.1.103:6800 (Caused by NewConnectionError('<urllib3.connection.HTTPConnection object at 0x00000207219869A0>: Failed to establish a new connection: [Errno 11001] getaddrinfo failed'))
ERROR - 2022-09-18 03:51:29,494 - process: 9156 - utils.py - gerapy.server.core.utils - 564 - utils - HTTPConnectionPool(host='http', port=80): Max retries exceeded with url: /listprojects.json (Caused by NewConnectionError('<urllib3.connection.HTTPConnection object at 0x0000020721AC22B0>: Failed to establish a new connection: [Errno 11001] getaddrinfo failed'))
Traceback (most recent call last):
  File "E:\pythonProject\venv\lib\site-packages\urllib3\connection.py", line 174, in _new_conn
    conn = connection.create_connection(
  File "E:\pythonProject\venv\lib\site-packages\urllib3\util\connection.py", line 72, in create_connection
    for res in socket.getaddrinfo(host, port, family, socket.SOCK_STREAM):
  File "D:\develop\python\python\lib\socket.py", line 954, in getaddrinfo
    for res in _socket.getaddrinfo(host, port, family, type, proto, flags):
socket.gaierror: [Errno 11001] getaddrinfo failed

During handling of the above exception, another exception occurred:

Traceback (most recent call last):
  File "E:\pythonProject\venv\lib\site-packages\urllib3\connectionpool.py", line 703, in urlopen
    httplib_response = self._make_request(
  File "E:\pythonProject\venv\lib\site-packages\urllib3\connectionpool.py", line 398, in _make_request
    conn.request(method, url, **httplib_request_kw)
  File "E:\pythonProject\venv\lib\site-packages\urllib3\connection.py", line 239, in request
    super(HTTPConnection, self).request(method, url, body=body, headers=headers)
  File "D:\develop\python\python\lib\http\client.py", line 1285, in request
    self._send_request(method, url, body, headers, encode_chunked)
  File "D:\develop\python\python\lib\http\client.py", line 1331, in _send_request
    self.endheaders(body, encode_chunked=encode_chunked)
  File "D:\develop\python\python\lib\http\client.py", line 1280, in endheaders
    self._send_output(message_body, encode_chunked=encode_chunked)
  File "D:\develop\python\python\lib\http\client.py", line 1040, in _send_output
    self.send(msg)
  File "D:\develop\python\python\lib\http\client.py", line 980, in send
    self.connect()
  File "E:\pythonProject\venv\lib\site-packages\urllib3\connection.py", line 205, in connect
    conn = self._new_conn()
  File "E:\pythonProject\venv\lib\site-packages\urllib3\connection.py", line 186, in _new_conn
    raise NewConnectionError(
urllib3.exceptions.NewConnectionError: <urllib3.connection.HTTPConnection object at 0x0000020721AC22B0>: Failed to establish a new connection: [Errno 11001] getaddrinfo failed

During handling of the above exception, another exception occurred:

Traceback (most recent call last):
  File "E:\pythonProject\venv\lib\site-packages\requests\adapters.py", line 440, in send
    resp = conn.urlopen(
  File "E:\pythonProject\venv\lib\site-packages\urllib3\connectionpool.py", line 785, in urlopen
    retries = retries.increment(
  File "E:\pythonProject\venv\lib\site-packages\urllib3\util\retry.py", line 592, in increment
    raise MaxRetryError(_pool, url, error or ResponseError(cause))
urllib3.exceptions.MaxRetryError: HTTPConnectionPool(host='http', port=80): Max retries exceeded with url: /listprojects.json (Caused by NewConnectionError('<urllib3.connection.HTTPConnection object at 0x0000020721AC22B0>: Failed to establish a new connection: [Errno 11001] getaddrinfo failed'))

During handling of the above exception, another exception occurred:

Traceback (most recent call last):
  File "E:\pythonProject\venv\lib\site-packages\gerapy\server\core\utils.py", line 562, in wrapper
    result = func(*args, **kwargs)
  File "E:\pythonProject\venv\lib\site-packages\django\views\decorators\csrf.py", line 54, in wrapped_view
    return view_func(*args, **kwargs)
  File "E:\pythonProject\venv\lib\site-packages\django\views\generic\base.py", line 71, in view
    return self.dispatch(request, *args, **kwargs)
  File "E:\pythonProject\venv\lib\site-packages\rest_framework\views.py", line 509, in dispatch
    response = self.handle_exception(exc)
  File "E:\pythonProject\venv\lib\site-packages\rest_framework\views.py", line 469, in handle_exception
    self.raise_uncaught_exception(exc)
  File "E:\pythonProject\venv\lib\site-packages\rest_framework\views.py", line 480, in raise_uncaught_exception
    raise exc
  File "E:\pythonProject\venv\lib\site-packages\rest_framework\views.py", line 506, in dispatch
    response = handler(request, *args, **kwargs)
  File "E:\pythonProject\venv\lib\site-packages\rest_framework\decorators.py", line 50, in handler
    return func(*args, **kwargs)
  File "E:\pythonProject\venv\lib\site-packages\gerapy\server\core\views.py", line 227, in project_list
    projects = scrapyd.list_projects()
  File "E:\pythonProject\venv\lib\site-packages\scrapyd_api\wrapper.py", line 148, in list_projects
    json = self.client.get(url, timeout=self.timeout)
  File "E:\pythonProject\venv\lib\site-packages\requests\sessions.py", line 542, in get
    return self.request('GET', url, **kwargs)
  File "E:\pythonProject\venv\lib\site-packages\scrapyd_api\client.py", line 37, in request
    response = super(Client, self).request(*args, **kwargs)
  File "E:\pythonProject\venv\lib\site-packages\requests\sessions.py", line 529, in request
    resp = self.send(prep, **send_kwargs)
  File "E:\pythonProject\venv\lib\site-packages\requests\sessions.py", line 645, in send
    r = adapter.send(request, **kwargs)
  File "E:\pythonProject\venv\lib\site-packages\requests\adapters.py", line 519, in send
    raise ConnectionError(e, request=request)
requests.exceptions.ConnectionError: HTTPConnectionPool(host='http', port=80): Max retries exceeded with url: /listprojects.json (Caused by NewConnectionError('<urllib3.connection.HTTPConnection object at 0x0000020721AC22B0>: Failed to establish a new connection: [Errno 11001] getaddrinfo failed'))
ERROR - 2022-09-18 03:51:32,342 - process: 9156 - utils.py - gerapy.server.core.utils - 564 - utils - HTTPConnectionPool(host='http', port=80): Max retries exceeded with url: /listprojects.json (Caused by NewConnectionError('<urllib3.connection.HTTPConnection object at 0x00000207218D62B0>: Failed to establish a new connection: [Errno 11001] getaddrinfo failed'))
Traceback (most recent call last):
  File "E:\pythonProject\venv\lib\site-packages\urllib3\connection.py", line 174, in _new_conn
    conn = connection.create_connection(
  File "E:\pythonProject\venv\lib\site-packages\urllib3\util\connection.py", line 72, in create_connection
    for res in socket.getaddrinfo(host, port, family, socket.SOCK_STREAM):
  File "D:\develop\python\python\lib\socket.py", line 954, in getaddrinfo
    for res in _socket.getaddrinfo(host, port, family, type, proto, flags):
socket.gaierror: [Errno 11001] getaddrinfo failed

During handling of the above exception, another exception occurred:

Traceback (most recent call last):
  File "E:\pythonProject\venv\lib\site-packages\urllib3\connectionpool.py", line 703, in urlopen
    httplib_response = self._make_request(
  File "E:\pythonProject\venv\lib\site-packages\urllib3\connectionpool.py", line 398, in _make_request
    conn.request(method, url, **httplib_request_kw)
  File "E:\pythonProject\venv\lib\site-packages\urllib3\connection.py", line 239, in request
    super(HTTPConnection, self).request(method, url, body=body, headers=headers)
  File "D:\develop\python\python\lib\http\client.py", line 1285, in request
    self._send_request(method, url, body, headers, encode_chunked)
  File "D:\develop\python\python\lib\http\client.py", line 1331, in _send_request
    self.endheaders(body, encode_chunked=encode_chunked)
  File "D:\develop\python\python\lib\http\client.py", line 1280, in endheaders
    self._send_output(message_body, encode_chunked=encode_chunked)
  File "D:\develop\python\python\lib\http\client.py", line 1040, in _send_output
    self.send(msg)
  File "D:\develop\python\python\lib\http\client.py", line 980, in send
    self.connect()
  File "E:\pythonProject\venv\lib\site-packages\urllib3\connection.py", line 205, in connect
    conn = self._new_conn()
  File "E:\pythonProject\venv\lib\site-packages\urllib3\connection.py", line 186, in _new_conn
    raise NewConnectionError(
urllib3.exceptions.NewConnectionError: <urllib3.connection.HTTPConnection object at 0x00000207218D62B0>: Failed to establish a new connection: [Errno 11001] getaddrinfo failed

During handling of the above exception, another exception occurred:

Traceback (most recent call last):
  File "E:\pythonProject\venv\lib\site-packages\requests\adapters.py", line 440, in send
    resp = conn.urlopen(
  File "E:\pythonProject\venv\lib\site-packages\urllib3\connectionpool.py", line 785, in urlopen
    retries = retries.increment(
  File "E:\pythonProject\venv\lib\site-packages\urllib3\util\retry.py", line 592, in increment
    raise MaxRetryError(_pool, url, error or ResponseError(cause))
urllib3.exceptions.MaxRetryError: HTTPConnectionPool(host='http', port=80): Max retries exceeded with url: /listprojects.json (Caused by NewConnectionError('<urllib3.connection.HTTPConnection object at 0x00000207218D62B0>: Failed to establish a new connection: [Errno 11001] getaddrinfo failed'))

During handling of the above exception, another exception occurred:

Traceback (most recent call last):
  File "E:\pythonProject\venv\lib\site-packages\gerapy\server\core\utils.py", line 562, in wrapper
    result = func(*args, **kwargs)
  File "E:\pythonProject\venv\lib\site-packages\django\views\decorators\csrf.py", line 54, in wrapped_view
    return view_func(*args, **kwargs)
  File "E:\pythonProject\venv\lib\site-packages\django\views\generic\base.py", line 71, in view
    return self.dispatch(request, *args, **kwargs)
  File "E:\pythonProject\venv\lib\site-packages\rest_framework\views.py", line 509, in dispatch
    response = self.handle_exception(exc)
  File "E:\pythonProject\venv\lib\site-packages\rest_framework\views.py", line 469, in handle_exception
    self.raise_uncaught_exception(exc)
  File "E:\pythonProject\venv\lib\site-packages\rest_framework\views.py", line 480, in raise_uncaught_exception
    raise exc
  File "E:\pythonProject\venv\lib\site-packages\rest_framework\views.py", line 506, in dispatch
    response = handler(request, *args, **kwargs)
  File "E:\pythonProject\venv\lib\site-packages\rest_framework\decorators.py", line 50, in handler
    return func(*args, **kwargs)
  File "E:\pythonProject\venv\lib\site-packages\gerapy\server\core\views.py", line 227, in project_list
    projects = scrapyd.list_projects()
  File "E:\pythonProject\venv\lib\site-packages\scrapyd_api\wrapper.py", line 148, in list_projects
    json = self.client.get(url, timeout=self.timeout)
  File "E:\pythonProject\venv\lib\site-packages\requests\sessions.py", line 542, in get
    return self.request('GET', url, **kwargs)
  File "E:\pythonProject\venv\lib\site-packages\scrapyd_api\client.py", line 37, in request
    response = super(Client, self).request(*args, **kwargs)
  File "E:\pythonProject\venv\lib\site-packages\requests\sessions.py", line 529, in request
    resp = self.send(prep, **send_kwargs)
  File "E:\pythonProject\venv\lib\site-packages\requests\sessions.py", line 645, in send
    r = adapter.send(request, **kwargs)
  File "E:\pythonProject\venv\lib\site-packages\requests\adapters.py", line 519, in send
    raise ConnectionError(e, request=request)
requests.exceptions.ConnectionError: HTTPConnectionPool(host='http', port=80): Max retries exceeded with url: /listprojects.json (Caused by NewConnectionError('<urllib3.connection.HTTPConnection object at 0x00000207218D62B0>: Failed to establish a new connection: [Errno 11001] getaddrinfo failed'))
ERROR - 2022-09-18 03:51:37,265 - process: 9156 - utils.py - gerapy.server.core.utils - 564 - utils - HTTPConnectionPool(host='http', port=80): Max retries exceeded with url: //192.168.1.103:6800 (Caused by NewConnectionError('<urllib3.connection.HTTPConnection object at 0x0000020721ABC490>: Failed to establish a new connection: [Errno 11001] getaddrinfo failed'))
Traceback (most recent call last):
  File "E:\pythonProject\venv\lib\site-packages\urllib3\connection.py", line 174, in _new_conn
    conn = connection.create_connection(
  File "E:\pythonProject\venv\lib\site-packages\urllib3\util\connection.py", line 72, in create_connection
    for res in socket.getaddrinfo(host, port, family, socket.SOCK_STREAM):
  File "D:\develop\python\python\lib\socket.py", line 954, in getaddrinfo
    for res in _socket.getaddrinfo(host, port, family, type, proto, flags):
socket.gaierror: [Errno 11001] getaddrinfo failed

During handling of the above exception, another exception occurred:

Traceback (most recent call last):
  File "E:\pythonProject\venv\lib\site-packages\urllib3\connectionpool.py", line 703, in urlopen
    httplib_response = self._make_request(
  File "E:\pythonProject\venv\lib\site-packages\urllib3\connectionpool.py", line 398, in _make_request
    conn.request(method, url, **httplib_request_kw)
  File "E:\pythonProject\venv\lib\site-packages\urllib3\connection.py", line 239, in request
    super(HTTPConnection, self).request(method, url, body=body, headers=headers)
  File "D:\develop\python\python\lib\http\client.py", line 1285, in request
    self._send_request(method, url, body, headers, encode_chunked)
  File "D:\develop\python\python\lib\http\client.py", line 1331, in _send_request
    self.endheaders(body, encode_chunked=encode_chunked)
  File "D:\develop\python\python\lib\http\client.py", line 1280, in endheaders
    self._send_output(message_body, encode_chunked=encode_chunked)
  File "D:\develop\python\python\lib\http\client.py", line 1040, in _send_output
    self.send(msg)
  File "D:\develop\python\python\lib\http\client.py", line 980, in send
    self.connect()
  File "E:\pythonProject\venv\lib\site-packages\urllib3\connection.py", line 205, in connect
    conn = self._new_conn()
  File "E:\pythonProject\venv\lib\site-packages\urllib3\connection.py", line 186, in _new_conn
    raise NewConnectionError(
urllib3.exceptions.NewConnectionError: <urllib3.connection.HTTPConnection object at 0x0000020721ABC490>: Failed to establish a new connection: [Errno 11001] getaddrinfo failed

During handling of the above exception, another exception occurred:

Traceback (most recent call last):
  File "E:\pythonProject\venv\lib\site-packages\requests\adapters.py", line 440, in send
    resp = conn.urlopen(
  File "E:\pythonProject\venv\lib\site-packages\urllib3\connectionpool.py", line 785, in urlopen
    retries = retries.increment(
  File "E:\pythonProject\venv\lib\site-packages\urllib3\util\retry.py", line 592, in increment
    raise MaxRetryError(_pool, url, error or ResponseError(cause))
urllib3.exceptions.MaxRetryError: HTTPConnectionPool(host='http', port=80): Max retries exceeded with url: //192.168.1.103:6800 (Caused by NewConnectionError('<urllib3.connection.HTTPConnection object at 0x0000020721ABC490>: Failed to establish a new connection: [Errno 11001] getaddrinfo failed'))

During handling of the above exception, another exception occurred:

Traceback (most recent call last):
  File "E:\pythonProject\venv\lib\site-packages\gerapy\server\core\utils.py", line 562, in wrapper
    result = func(*args, **kwargs)
  File "E:\pythonProject\venv\lib\site-packages\django\views\decorators\csrf.py", line 54, in wrapped_view
    return view_func(*args, **kwargs)
  File "E:\pythonProject\venv\lib\site-packages\django\views\generic\base.py", line 71, in view
    return self.dispatch(request, *args, **kwargs)
  File "E:\pythonProject\venv\lib\site-packages\rest_framework\views.py", line 509, in dispatch
    response = self.handle_exception(exc)
  File "E:\pythonProject\venv\lib\site-packages\rest_framework\views.py", line 469, in handle_exception
    self.raise_uncaught_exception(exc)
  File "E:\pythonProject\venv\lib\site-packages\rest_framework\views.py", line 480, in raise_uncaught_exception
    raise exc
  File "E:\pythonProject\venv\lib\site-packages\rest_framework\views.py", line 506, in dispatch
    response = handler(request, *args, **kwargs)
  File "E:\pythonProject\venv\lib\site-packages\rest_framework\decorators.py", line 50, in handler
    return func(*args, **kwargs)
  File "E:\pythonProject\venv\lib\site-packages\gerapy\server\core\views.py", line 120, in client_status
    requests.get(scrapyd_url(client.ip, client.port), timeout=3)
  File "E:\pythonProject\venv\lib\site-packages\requests\api.py", line 75, in get
    return request('get', url, params=params, **kwargs)
  File "E:\pythonProject\venv\lib\site-packages\requests\api.py", line 61, in request
    return session.request(method=method, url=url, **kwargs)
  File "E:\pythonProject\venv\lib\site-packages\requests\sessions.py", line 529, in request
    resp = self.send(prep, **send_kwargs)
  File "E:\pythonProject\venv\lib\site-packages\requests\sessions.py", line 645, in send
    r = adapter.send(request, **kwargs)
  File "E:\pythonProject\venv\lib\site-packages\requests\adapters.py", line 519, in send
    raise ConnectionError(e, request=request)
requests.exceptions.ConnectionError: HTTPConnectionPool(host='http', port=80): Max retries exceeded with url: //192.168.1.103:6800 (Caused by NewConnectionError('<urllib3.connection.HTTPConnection object at 0x0000020721ABC490>: Failed to establish a new connection: [Errno 11001] getaddrinfo failed'))
ERROR - 2022-09-18 03:52:02,600 - process: 9156 - utils.py - gerapy.server.core.utils - 564 - utils - HTTPConnectionPool(host='http', port=80): Max retries exceeded with url: //192.168.1.103:6800 (Caused by NewConnectionError('<urllib3.connection.HTTPConnection object at 0x00000207218CAC70>: Failed to establish a new connection: [Errno 11001] getaddrinfo failed'))
Traceback (most recent call last):
  File "E:\pythonProject\venv\lib\site-packages\urllib3\connection.py", line 174, in _new_conn
    conn = connection.create_connection(
  File "E:\pythonProject\venv\lib\site-packages\urllib3\util\connection.py", line 72, in create_connection
    for res in socket.getaddrinfo(host, port, family, socket.SOCK_STREAM):
  File "D:\develop\python\python\lib\socket.py", line 954, in getaddrinfo
    for res in _socket.getaddrinfo(host, port, family, type, proto, flags):
socket.gaierror: [Errno 11001] getaddrinfo failed

During handling of the above exception, another exception occurred:

Traceback (most recent call last):
  File "E:\pythonProject\venv\lib\site-packages\urllib3\connectionpool.py", line 703, in urlopen
    httplib_response = self._make_request(
  File "E:\pythonProject\venv\lib\site-packages\urllib3\connectionpool.py", line 398, in _make_request
    conn.request(method, url, **httplib_request_kw)
  File "E:\pythonProject\venv\lib\site-packages\urllib3\connection.py", line 239, in request
    super(HTTPConnection, self).request(method, url, body=body, headers=headers)
  File "D:\develop\python\python\lib\http\client.py", line 1285, in request
    self._send_request(method, url, body, headers, encode_chunked)
  File "D:\develop\python\python\lib\http\client.py", line 1331, in _send_request
    self.endheaders(body, encode_chunked=encode_chunked)
  File "D:\develop\python\python\lib\http\client.py", line 1280, in endheaders
    self._send_output(message_body, encode_chunked=encode_chunked)
  File "D:\develop\python\python\lib\http\client.py", line 1040, in _send_output
    self.send(msg)
  File "D:\develop\python\python\lib\http\client.py", line 980, in send
    self.connect()
  File "E:\pythonProject\venv\lib\site-packages\urllib3\connection.py", line 205, in connect
    conn = self._new_conn()
  File "E:\pythonProject\venv\lib\site-packages\urllib3\connection.py", line 186, in _new_conn
    raise NewConnectionError(
urllib3.exceptions.NewConnectionError: <urllib3.connection.HTTPConnection object at 0x00000207218CAC70>: Failed to establish a new connection: [Errno 11001] getaddrinfo failed

During handling of the above exception, another exception occurred:

Traceback (most recent call last):
  File "E:\pythonProject\venv\lib\site-packages\requests\adapters.py", line 440, in send
    resp = conn.urlopen(
  File "E:\pythonProject\venv\lib\site-packages\urllib3\connectionpool.py", line 785, in urlopen
    retries = retries.increment(
  File "E:\pythonProject\venv\lib\site-packages\urllib3\util\retry.py", line 592, in increment
    raise MaxRetryError(_pool, url, error or ResponseError(cause))
urllib3.exceptions.MaxRetryError: HTTPConnectionPool(host='http', port=80): Max retries exceeded with url: //192.168.1.103:6800 (Caused by NewConnectionError('<urllib3.connection.HTTPConnection object at 0x00000207218CAC70>: Failed to establish a new connection: [Errno 11001] getaddrinfo failed'))

During handling of the above exception, another exception occurred:

Traceback (most recent call last):
  File "E:\pythonProject\venv\lib\site-packages\gerapy\server\core\utils.py", line 562, in wrapper
    result = func(*args, **kwargs)
  File "E:\pythonProject\venv\lib\site-packages\django\views\decorators\csrf.py", line 54, in wrapped_view
    return view_func(*args, **kwargs)
  File "E:\pythonProject\venv\lib\site-packages\django\views\generic\base.py", line 71, in view
    return self.dispatch(request, *args, **kwargs)
  File "E:\pythonProject\venv\lib\site-packages\rest_framework\views.py", line 509, in dispatch
    response = self.handle_exception(exc)
  File "E:\pythonProject\venv\lib\site-packages\rest_framework\views.py", line 469, in handle_exception
    self.raise_uncaught_exception(exc)
  File "E:\pythonProject\venv\lib\site-packages\rest_framework\views.py", line 480, in raise_uncaught_exception
    raise exc
  File "E:\pythonProject\venv\lib\site-packages\rest_framework\views.py", line 506, in dispatch
    response = handler(request, *args, **kwargs)
  File "E:\pythonProject\venv\lib\site-packages\rest_framework\decorators.py", line 50, in handler
    return func(*args, **kwargs)
  File "E:\pythonProject\venv\lib\site-packages\gerapy\server\core\views.py", line 120, in client_status
    requests.get(scrapyd_url(client.ip, client.port), timeout=3)
  File "E:\pythonProject\venv\lib\site-packages\requests\api.py", line 75, in get
    return request('get', url, params=params, **kwargs)
  File "E:\pythonProject\venv\lib\site-packages\requests\api.py", line 61, in request
    return session.request(method=method, url=url, **kwargs)
  File "E:\pythonProject\venv\lib\site-packages\requests\sessions.py", line 529, in request
    resp = self.send(prep, **send_kwargs)
  File "E:\pythonProject\venv\lib\site-packages\requests\sessions.py", line 645, in send
    r = adapter.send(request, **kwargs)
  File "E:\pythonProject\venv\lib\site-packages\requests\adapters.py", line 519, in send
    raise ConnectionError(e, request=request)
requests.exceptions.ConnectionError: HTTPConnectionPool(host='http', port=80): Max retries exceeded with url: //192.168.1.103:6800 (Caused by NewConnectionError('<urllib3.connection.HTTPConnection object at 0x00000207218CAC70>: Failed to establish a new connection: [Errno 11001] getaddrinfo failed'))
ERROR - 2022-09-18 03:52:46,153 - process: 9156 - utils.py - gerapy.server.core.utils - 564 - utils - HTTPConnectionPool(host='http', port=80): Max retries exceeded with url: //192.168.1.103/:6800 (Caused by NewConnectionError('<urllib3.connection.HTTPConnection object at 0x00000207219DF340>: Failed to establish a new connection: [Errno 11001] getaddrinfo failed'))
Traceback (most recent call last):
  File "E:\pythonProject\venv\lib\site-packages\urllib3\connection.py", line 174, in _new_conn
    conn = connection.create_connection(
  File "E:\pythonProject\venv\lib\site-packages\urllib3\util\connection.py", line 72, in create_connection
    for res in socket.getaddrinfo(host, port, family, socket.SOCK_STREAM):
  File "D:\develop\python\python\lib\socket.py", line 954, in getaddrinfo
    for res in _socket.getaddrinfo(host, port, family, type, proto, flags):
socket.gaierror: [Errno 11001] getaddrinfo failed

During handling of the above exception, another exception occurred:

Traceback (most recent call last):
  File "E:\pythonProject\venv\lib\site-packages\urllib3\connectionpool.py", line 703, in urlopen
    httplib_response = self._make_request(
  File "E:\pythonProject\venv\lib\site-packages\urllib3\connectionpool.py", line 398, in _make_request
    conn.request(method, url, **httplib_request_kw)
  File "E:\pythonProject\venv\lib\site-packages\urllib3\connection.py", line 239, in request
    super(HTTPConnection, self).request(method, url, body=body, headers=headers)
  File "D:\develop\python\python\lib\http\client.py", line 1285, in request
    self._send_request(method, url, body, headers, encode_chunked)
  File "D:\develop\python\python\lib\http\client.py", line 1331, in _send_request
    self.endheaders(body, encode_chunked=encode_chunked)
  File "D:\develop\python\python\lib\http\client.py", line 1280, in endheaders
    self._send_output(message_body, encode_chunked=encode_chunked)
  File "D:\develop\python\python\lib\http\client.py", line 1040, in _send_output
    self.send(msg)
  File "D:\develop\python\python\lib\http\client.py", line 980, in send
    self.connect()
  File "E:\pythonProject\venv\lib\site-packages\urllib3\connection.py", line 205, in connect
    conn = self._new_conn()
  File "E:\pythonProject\venv\lib\site-packages\urllib3\connection.py", line 186, in _new_conn
    raise NewConnectionError(
urllib3.exceptions.NewConnectionError: <urllib3.connection.HTTPConnection object at 0x00000207219DF340>: Failed to establish a new connection: [Errno 11001] getaddrinfo failed

During handling of the above exception, another exception occurred:

Traceback (most recent call last):
  File "E:\pythonProject\venv\lib\site-packages\requests\adapters.py", line 440, in send
    resp = conn.urlopen(
  File "E:\pythonProject\venv\lib\site-packages\urllib3\connectionpool.py", line 785, in urlopen
    retries = retries.increment(
  File "E:\pythonProject\venv\lib\site-packages\urllib3\util\retry.py", line 592, in increment
    raise MaxRetryError(_pool, url, error or ResponseError(cause))
urllib3.exceptions.MaxRetryError: HTTPConnectionPool(host='http', port=80): Max retries exceeded with url: //192.168.1.103/:6800 (Caused by NewConnectionError('<urllib3.connection.HTTPConnection object at 0x00000207219DF340>: Failed to establish a new connection: [Errno 11001] getaddrinfo failed'))

During handling of the above exception, another exception occurred:

Traceback (most recent call last):
  File "E:\pythonProject\venv\lib\site-packages\gerapy\server\core\utils.py", line 562, in wrapper
    result = func(*args, **kwargs)
  File "E:\pythonProject\venv\lib\site-packages\django\views\decorators\csrf.py", line 54, in wrapped_view
    return view_func(*args, **kwargs)
  File "E:\pythonProject\venv\lib\site-packages\django\views\generic\base.py", line 71, in view
    return self.dispatch(request, *args, **kwargs)
  File "E:\pythonProject\venv\lib\site-packages\rest_framework\views.py", line 509, in dispatch
    response = self.handle_exception(exc)
  File "E:\pythonProject\venv\lib\site-packages\rest_framework\views.py", line 469, in handle_exception
    self.raise_uncaught_exception(exc)
  File "E:\pythonProject\venv\lib\site-packages\rest_framework\views.py", line 480, in raise_uncaught_exception
    raise exc
  File "E:\pythonProject\venv\lib\site-packages\rest_framework\views.py", line 506, in dispatch
    response = handler(request, *args, **kwargs)
  File "E:\pythonProject\venv\lib\site-packages\rest_framework\decorators.py", line 50, in handler
    return func(*args, **kwargs)
  File "E:\pythonProject\venv\lib\site-packages\gerapy\server\core\views.py", line 120, in client_status
    requests.get(scrapyd_url(client.ip, client.port), timeout=3)
  File "E:\pythonProject\venv\lib\site-packages\requests\api.py", line 75, in get
    return request('get', url, params=params, **kwargs)
  File "E:\pythonProject\venv\lib\site-packages\requests\api.py", line 61, in request
    return session.request(method=method, url=url, **kwargs)
  File "E:\pythonProject\venv\lib\site-packages\requests\sessions.py", line 529, in request
    resp = self.send(prep, **send_kwargs)
  File "E:\pythonProject\venv\lib\site-packages\requests\sessions.py", line 645, in send
    r = adapter.send(request, **kwargs)
  File "E:\pythonProject\venv\lib\site-packages\requests\adapters.py", line 519, in send
    raise ConnectionError(e, request=request)
requests.exceptions.ConnectionError: HTTPConnectionPool(host='http', port=80): Max retries exceeded with url: //192.168.1.103/:6800 (Caused by NewConnectionError('<urllib3.connection.HTTPConnection object at 0x00000207219DF340>: Failed to establish a new connection: [Errno 11001] getaddrinfo failed'))
ERROR - 2022-09-18 03:56:00,348 - process: 9156 - utils.py - gerapy.server.core.utils - 564 - utils - HTTPConnectionPool(host='http', port=80): Max retries exceeded with url: //192.168.1.103/:6800 (Caused by NewConnectionError('<urllib3.connection.HTTPConnection object at 0x00000207219DF4C0>: Failed to establish a new connection: [Errno 11001] getaddrinfo failed'))
Traceback (most recent call last):
  File "E:\pythonProject\venv\lib\site-packages\urllib3\connection.py", line 174, in _new_conn
    conn = connection.create_connection(
  File "E:\pythonProject\venv\lib\site-packages\urllib3\util\connection.py", line 72, in create_connection
    for res in socket.getaddrinfo(host, port, family, socket.SOCK_STREAM):
  File "D:\develop\python\python\lib\socket.py", line 954, in getaddrinfo
    for res in _socket.getaddrinfo(host, port, family, type, proto, flags):
socket.gaierror: [Errno 11001] getaddrinfo failed

During handling of the above exception, another exception occurred:

Traceback (most recent call last):
  File "E:\pythonProject\venv\lib\site-packages\urllib3\connectionpool.py", line 703, in urlopen
    httplib_response = self._make_request(
  File "E:\pythonProject\venv\lib\site-packages\urllib3\connectionpool.py", line 398, in _make_request
    conn.request(method, url, **httplib_request_kw)
  File "E:\pythonProject\venv\lib\site-packages\urllib3\connection.py", line 239, in request
    super(HTTPConnection, self).request(method, url, body=body, headers=headers)
  File "D:\develop\python\python\lib\http\client.py", line 1285, in request
    self._send_request(method, url, body, headers, encode_chunked)
  File "D:\develop\python\python\lib\http\client.py", line 1331, in _send_request
    self.endheaders(body, encode_chunked=encode_chunked)
  File "D:\develop\python\python\lib\http\client.py", line 1280, in endheaders
    self._send_output(message_body, encode_chunked=encode_chunked)
  File "D:\develop\python\python\lib\http\client.py", line 1040, in _send_output
    self.send(msg)
  File "D:\develop\python\python\lib\http\client.py", line 980, in send
    self.connect()
  File "E:\pythonProject\venv\lib\site-packages\urllib3\connection.py", line 205, in connect
    conn = self._new_conn()
  File "E:\pythonProject\venv\lib\site-packages\urllib3\connection.py", line 186, in _new_conn
    raise NewConnectionError(
urllib3.exceptions.NewConnectionError: <urllib3.connection.HTTPConnection object at 0x00000207219DF4C0>: Failed to establish a new connection: [Errno 11001] getaddrinfo failed

During handling of the above exception, another exception occurred:

Traceback (most recent call last):
  File "E:\pythonProject\venv\lib\site-packages\requests\adapters.py", line 440, in send
    resp = conn.urlopen(
  File "E:\pythonProject\venv\lib\site-packages\urllib3\connectionpool.py", line 785, in urlopen
    retries = retries.increment(
  File "E:\pythonProject\venv\lib\site-packages\urllib3\util\retry.py", line 592, in increment
    raise MaxRetryError(_pool, url, error or ResponseError(cause))
urllib3.exceptions.MaxRetryError: HTTPConnectionPool(host='http', port=80): Max retries exceeded with url: //192.168.1.103/:6800 (Caused by NewConnectionError('<urllib3.connection.HTTPConnection object at 0x00000207219DF4C0>: Failed to establish a new connection: [Errno 11001] getaddrinfo failed'))

During handling of the above exception, another exception occurred:

Traceback (most recent call last):
  File "E:\pythonProject\venv\lib\site-packages\gerapy\server\core\utils.py", line 562, in wrapper
    result = func(*args, **kwargs)
  File "E:\pythonProject\venv\lib\site-packages\django\views\decorators\csrf.py", line 54, in wrapped_view
    return view_func(*args, **kwargs)
  File "E:\pythonProject\venv\lib\site-packages\django\views\generic\base.py", line 71, in view
    return self.dispatch(request, *args, **kwargs)
  File "E:\pythonProject\venv\lib\site-packages\rest_framework\views.py", line 509, in dispatch
    response = self.handle_exception(exc)
  File "E:\pythonProject\venv\lib\site-packages\rest_framework\views.py", line 469, in handle_exception
    self.raise_uncaught_exception(exc)
  File "E:\pythonProject\venv\lib\site-packages\rest_framework\views.py", line 480, in raise_uncaught_exception
    raise exc
  File "E:\pythonProject\venv\lib\site-packages\rest_framework\views.py", line 506, in dispatch
    response = handler(request, *args, **kwargs)
  File "E:\pythonProject\venv\lib\site-packages\rest_framework\decorators.py", line 50, in handler
    return func(*args, **kwargs)
  File "E:\pythonProject\venv\lib\site-packages\gerapy\server\core\views.py", line 120, in client_status
    requests.get(scrapyd_url(client.ip, client.port), timeout=3)
  File "E:\pythonProject\venv\lib\site-packages\requests\api.py", line 75, in get
    return request('get', url, params=params, **kwargs)
  File "E:\pythonProject\venv\lib\site-packages\requests\api.py", line 61, in request
    return session.request(method=method, url=url, **kwargs)
  File "E:\pythonProject\venv\lib\site-packages\requests\sessions.py", line 529, in request
    resp = self.send(prep, **send_kwargs)
  File "E:\pythonProject\venv\lib\site-packages\requests\sessions.py", line 645, in send
    r = adapter.send(request, **kwargs)
  File "E:\pythonProject\venv\lib\site-packages\requests\adapters.py", line 519, in send
    raise ConnectionError(e, request=request)
requests.exceptions.ConnectionError: HTTPConnectionPool(host='http', port=80): Max retries exceeded with url: //192.168.1.103/:6800 (Caused by NewConnectionError('<urllib3.connection.HTTPConnection object at 0x00000207219DF4C0>: Failed to establish a new connection: [Errno 11001] getaddrinfo failed'))
ERROR - 2022-09-18 03:56:02,665 - process: 9156 - utils.py - gerapy.server.core.utils - 564 - utils - HTTPConnectionPool(host='http', port=80): Max retries exceeded with url: //192.168.1.103/:6800 (Caused by NewConnectionError('<urllib3.connection.HTTPConnection object at 0x0000020721A7C6D0>: Failed to establish a new connection: [Errno 11001] getaddrinfo failed'))
Traceback (most recent call last):
  File "E:\pythonProject\venv\lib\site-packages\urllib3\connection.py", line 174, in _new_conn
    conn = connection.create_connection(
  File "E:\pythonProject\venv\lib\site-packages\urllib3\util\connection.py", line 72, in create_connection
    for res in socket.getaddrinfo(host, port, family, socket.SOCK_STREAM):
  File "D:\develop\python\python\lib\socket.py", line 954, in getaddrinfo
    for res in _socket.getaddrinfo(host, port, family, type, proto, flags):
socket.gaierror: [Errno 11001] getaddrinfo failed

During handling of the above exception, another exception occurred:

Traceback (most recent call last):
  File "E:\pythonProject\venv\lib\site-packages\urllib3\connectionpool.py", line 703, in urlopen
    httplib_response = self._make_request(
  File "E:\pythonProject\venv\lib\site-packages\urllib3\connectionpool.py", line 398, in _make_request
    conn.request(method, url, **httplib_request_kw)
  File "E:\pythonProject\venv\lib\site-packages\urllib3\connection.py", line 239, in request
    super(HTTPConnection, self).request(method, url, body=body, headers=headers)
  File "D:\develop\python\python\lib\http\client.py", line 1285, in request
    self._send_request(method, url, body, headers, encode_chunked)
  File "D:\develop\python\python\lib\http\client.py", line 1331, in _send_request
    self.endheaders(body, encode_chunked=encode_chunked)
  File "D:\develop\python\python\lib\http\client.py", line 1280, in endheaders
    self._send_output(message_body, encode_chunked=encode_chunked)
  File "D:\develop\python\python\lib\http\client.py", line 1040, in _send_output
    self.send(msg)
  File "D:\develop\python\python\lib\http\client.py", line 980, in send
    self.connect()
  File "E:\pythonProject\venv\lib\site-packages\urllib3\connection.py", line 205, in connect
    conn = self._new_conn()
  File "E:\pythonProject\venv\lib\site-packages\urllib3\connection.py", line 186, in _new_conn
    raise NewConnectionError(
urllib3.exceptions.NewConnectionError: <urllib3.connection.HTTPConnection object at 0x0000020721A7C6D0>: Failed to establish a new connection: [Errno 11001] getaddrinfo failed

During handling of the above exception, another exception occurred:

Traceback (most recent call last):
  File "E:\pythonProject\venv\lib\site-packages\requests\adapters.py", line 440, in send
    resp = conn.urlopen(
  File "E:\pythonProject\venv\lib\site-packages\urllib3\connectionpool.py", line 785, in urlopen
    retries = retries.increment(
  File "E:\pythonProject\venv\lib\site-packages\urllib3\util\retry.py", line 592, in increment
    raise MaxRetryError(_pool, url, error or ResponseError(cause))
urllib3.exceptions.MaxRetryError: HTTPConnectionPool(host='http', port=80): Max retries exceeded with url: //192.168.1.103/:6800 (Caused by NewConnectionError('<urllib3.connection.HTTPConnection object at 0x0000020721A7C6D0>: Failed to establish a new connection: [Errno 11001] getaddrinfo failed'))

During handling of the above exception, another exception occurred:

Traceback (most recent call last):
  File "E:\pythonProject\venv\lib\site-packages\gerapy\server\core\utils.py", line 562, in wrapper
    result = func(*args, **kwargs)
  File "E:\pythonProject\venv\lib\site-packages\django\views\decorators\csrf.py", line 54, in wrapped_view
    return view_func(*args, **kwargs)
  File "E:\pythonProject\venv\lib\site-packages\django\views\generic\base.py", line 71, in view
    return self.dispatch(request, *args, **kwargs)
  File "E:\pythonProject\venv\lib\site-packages\rest_framework\views.py", line 509, in dispatch
    response = self.handle_exception(exc)
  File "E:\pythonProject\venv\lib\site-packages\rest_framework\views.py", line 469, in handle_exception
    self.raise_uncaught_exception(exc)
  File "E:\pythonProject\venv\lib\site-packages\rest_framework\views.py", line 480, in raise_uncaught_exception
    raise exc
  File "E:\pythonProject\venv\lib\site-packages\rest_framework\views.py", line 506, in dispatch
    response = handler(request, *args, **kwargs)
  File "E:\pythonProject\venv\lib\site-packages\rest_framework\decorators.py", line 50, in handler
    return func(*args, **kwargs)
  File "E:\pythonProject\venv\lib\site-packages\gerapy\server\core\views.py", line 120, in client_status
    requests.get(scrapyd_url(client.ip, client.port), timeout=3)
  File "E:\pythonProject\venv\lib\site-packages\requests\api.py", line 75, in get
    return request('get', url, params=params, **kwargs)
  File "E:\pythonProject\venv\lib\site-packages\requests\api.py", line 61, in request
    return session.request(method=method, url=url, **kwargs)
  File "E:\pythonProject\venv\lib\site-packages\requests\sessions.py", line 529, in request
    resp = self.send(prep, **send_kwargs)
  File "E:\pythonProject\venv\lib\site-packages\requests\sessions.py", line 645, in send
    r = adapter.send(request, **kwargs)
  File "E:\pythonProject\venv\lib\site-packages\requests\adapters.py", line 519, in send
    raise ConnectionError(e, request=request)
requests.exceptions.ConnectionError: HTTPConnectionPool(host='http', port=80): Max retries exceeded with url: //192.168.1.103/:6800 (Caused by NewConnectionError('<urllib3.connection.HTTPConnection object at 0x0000020721A7C6D0>: Failed to establish a new connection: [Errno 11001] getaddrinfo failed'))
ERROR - 2022-09-18 03:56:04,986 - process: 9156 - utils.py - gerapy.server.core.utils - 564 - utils - HTTPConnectionPool(host='http', port=80): Max retries exceeded with url: //192.168.1.103/:6800 (Caused by NewConnectionError('<urllib3.connection.HTTPConnection object at 0x00000207219A7430>: Failed to establish a new connection: [Errno 11001] getaddrinfo failed'))
Traceback (most recent call last):
  File "E:\pythonProject\venv\lib\site-packages\urllib3\connection.py", line 174, in _new_conn
    conn = connection.create_connection(
  File "E:\pythonProject\venv\lib\site-packages\urllib3\util\connection.py", line 72, in create_connection
    for res in socket.getaddrinfo(host, port, family, socket.SOCK_STREAM):
  File "D:\develop\python\python\lib\socket.py", line 954, in getaddrinfo
    for res in _socket.getaddrinfo(host, port, family, type, proto, flags):
socket.gaierror: [Errno 11001] getaddrinfo failed

During handling of the above exception, another exception occurred:

Traceback (most recent call last):
  File "E:\pythonProject\venv\lib\site-packages\urllib3\connectionpool.py", line 703, in urlopen
    httplib_response = self._make_request(
  File "E:\pythonProject\venv\lib\site-packages\urllib3\connectionpool.py", line 398, in _make_request
    conn.request(method, url, **httplib_request_kw)
  File "E:\pythonProject\venv\lib\site-packages\urllib3\connection.py", line 239, in request
    super(HTTPConnection, self).request(method, url, body=body, headers=headers)
  File "D:\develop\python\python\lib\http\client.py", line 1285, in request
    self._send_request(method, url, body, headers, encode_chunked)
  File "D:\develop\python\python\lib\http\client.py", line 1331, in _send_request
    self.endheaders(body, encode_chunked=encode_chunked)
  File "D:\develop\python\python\lib\http\client.py", line 1280, in endheaders
    self._send_output(message_body, encode_chunked=encode_chunked)
  File "D:\develop\python\python\lib\http\client.py", line 1040, in _send_output
    self.send(msg)
  File "D:\develop\python\python\lib\http\client.py", line 980, in send
    self.connect()
  File "E:\pythonProject\venv\lib\site-packages\urllib3\connection.py", line 205, in connect
    conn = self._new_conn()
  File "E:\pythonProject\venv\lib\site-packages\urllib3\connection.py", line 186, in _new_conn
    raise NewConnectionError(
urllib3.exceptions.NewConnectionError: <urllib3.connection.HTTPConnection object at 0x00000207219A7430>: Failed to establish a new connection: [Errno 11001] getaddrinfo failed

During handling of the above exception, another exception occurred:

Traceback (most recent call last):
  File "E:\pythonProject\venv\lib\site-packages\requests\adapters.py", line 440, in send
    resp = conn.urlopen(
  File "E:\pythonProject\venv\lib\site-packages\urllib3\connectionpool.py", line 785, in urlopen
    retries = retries.increment(
  File "E:\pythonProject\venv\lib\site-packages\urllib3\util\retry.py", line 592, in increment
    raise MaxRetryError(_pool, url, error or ResponseError(cause))
urllib3.exceptions.MaxRetryError: HTTPConnectionPool(host='http', port=80): Max retries exceeded with url: //192.168.1.103/:6800 (Caused by NewConnectionError('<urllib3.connection.HTTPConnection object at 0x00000207219A7430>: Failed to establish a new connection: [Errno 11001] getaddrinfo failed'))

During handling of the above exception, another exception occurred:

Traceback (most recent call last):
  File "E:\pythonProject\venv\lib\site-packages\gerapy\server\core\utils.py", line 562, in wrapper
    result = func(*args, **kwargs)
  File "E:\pythonProject\venv\lib\site-packages\django\views\decorators\csrf.py", line 54, in wrapped_view
    return view_func(*args, **kwargs)
  File "E:\pythonProject\venv\lib\site-packages\django\views\generic\base.py", line 71, in view
    return self.dispatch(request, *args, **kwargs)
  File "E:\pythonProject\venv\lib\site-packages\rest_framework\views.py", line 509, in dispatch
    response = self.handle_exception(exc)
  File "E:\pythonProject\venv\lib\site-packages\rest_framework\views.py", line 469, in handle_exception
    self.raise_uncaught_exception(exc)
  File "E:\pythonProject\venv\lib\site-packages\rest_framework\views.py", line 480, in raise_uncaught_exception
    raise exc
  File "E:\pythonProject\venv\lib\site-packages\rest_framework\views.py", line 506, in dispatch
    response = handler(request, *args, **kwargs)
  File "E:\pythonProject\venv\lib\site-packages\rest_framework\decorators.py", line 50, in handler
    return func(*args, **kwargs)
  File "E:\pythonProject\venv\lib\site-packages\gerapy\server\core\views.py", line 120, in client_status
    requests.get(scrapyd_url(client.ip, client.port), timeout=3)
  File "E:\pythonProject\venv\lib\site-packages\requests\api.py", line 75, in get
    return request('get', url, params=params, **kwargs)
  File "E:\pythonProject\venv\lib\site-packages\requests\api.py", line 61, in request
    return session.request(method=method, url=url, **kwargs)
  File "E:\pythonProject\venv\lib\site-packages\requests\sessions.py", line 529, in request
    resp = self.send(prep, **send_kwargs)
  File "E:\pythonProject\venv\lib\site-packages\requests\sessions.py", line 645, in send
    r = adapter.send(request, **kwargs)
  File "E:\pythonProject\venv\lib\site-packages\requests\adapters.py", line 519, in send
    raise ConnectionError(e, request=request)
requests.exceptions.ConnectionError: HTTPConnectionPool(host='http', port=80): Max retries exceeded with url: //192.168.1.103/:6800 (Caused by NewConnectionError('<urllib3.connection.HTTPConnection object at 0x00000207219A7430>: Failed to establish a new connection: [Errno 11001] getaddrinfo failed'))
ERROR - 2022-09-18 03:56:07,317 - process: 9156 - utils.py - gerapy.server.core.utils - 564 - utils - HTTPConnectionPool(host='http', port=80): Max retries exceeded with url: //192.168.1.103/:6800 (Caused by NewConnectionError('<urllib3.connection.HTTPConnection object at 0x00000207219D6AC0>: Failed to establish a new connection: [Errno 11001] getaddrinfo failed'))
Traceback (most recent call last):
  File "E:\pythonProject\venv\lib\site-packages\urllib3\connection.py", line 174, in _new_conn
    conn = connection.create_connection(
  File "E:\pythonProject\venv\lib\site-packages\urllib3\util\connection.py", line 72, in create_connection
    for res in socket.getaddrinfo(host, port, family, socket.SOCK_STREAM):
  File "D:\develop\python\python\lib\socket.py", line 954, in getaddrinfo
    for res in _socket.getaddrinfo(host, port, family, type, proto, flags):
socket.gaierror: [Errno 11001] getaddrinfo failed

During handling of the above exception, another exception occurred:

Traceback (most recent call last):
  File "E:\pythonProject\venv\lib\site-packages\urllib3\connectionpool.py", line 703, in urlopen
    httplib_response = self._make_request(
  File "E:\pythonProject\venv\lib\site-packages\urllib3\connectionpool.py", line 398, in _make_request
    conn.request(method, url, **httplib_request_kw)
  File "E:\pythonProject\venv\lib\site-packages\urllib3\connection.py", line 239, in request
    super(HTTPConnection, self).request(method, url, body=body, headers=headers)
  File "D:\develop\python\python\lib\http\client.py", line 1285, in request
    self._send_request(method, url, body, headers, encode_chunked)
  File "D:\develop\python\python\lib\http\client.py", line 1331, in _send_request
    self.endheaders(body, encode_chunked=encode_chunked)
  File "D:\develop\python\python\lib\http\client.py", line 1280, in endheaders
    self._send_output(message_body, encode_chunked=encode_chunked)
  File "D:\develop\python\python\lib\http\client.py", line 1040, in _send_output
    self.send(msg)
  File "D:\develop\python\python\lib\http\client.py", line 980, in send
    self.connect()
  File "E:\pythonProject\venv\lib\site-packages\urllib3\connection.py", line 205, in connect
    conn = self._new_conn()
  File "E:\pythonProject\venv\lib\site-packages\urllib3\connection.py", line 186, in _new_conn
    raise NewConnectionError(
urllib3.exceptions.NewConnectionError: <urllib3.connection.HTTPConnection object at 0x00000207219D6AC0>: Failed to establish a new connection: [Errno 11001] getaddrinfo failed

During handling of the above exception, another exception occurred:

Traceback (most recent call last):
  File "E:\pythonProject\venv\lib\site-packages\requests\adapters.py", line 440, in send
    resp = conn.urlopen(
  File "E:\pythonProject\venv\lib\site-packages\urllib3\connectionpool.py", line 785, in urlopen
    retries = retries.increment(
  File "E:\pythonProject\venv\lib\site-packages\urllib3\util\retry.py", line 592, in increment
    raise MaxRetryError(_pool, url, error or ResponseError(cause))
urllib3.exceptions.MaxRetryError: HTTPConnectionPool(host='http', port=80): Max retries exceeded with url: //192.168.1.103/:6800 (Caused by NewConnectionError('<urllib3.connection.HTTPConnection object at 0x00000207219D6AC0>: Failed to establish a new connection: [Errno 11001] getaddrinfo failed'))

During handling of the above exception, another exception occurred:

Traceback (most recent call last):
  File "E:\pythonProject\venv\lib\site-packages\gerapy\server\core\utils.py", line 562, in wrapper
    result = func(*args, **kwargs)
  File "E:\pythonProject\venv\lib\site-packages\django\views\decorators\csrf.py", line 54, in wrapped_view
    return view_func(*args, **kwargs)
  File "E:\pythonProject\venv\lib\site-packages\django\views\generic\base.py", line 71, in view
    return self.dispatch(request, *args, **kwargs)
  File "E:\pythonProject\venv\lib\site-packages\rest_framework\views.py", line 509, in dispatch
    response = self.handle_exception(exc)
  File "E:\pythonProject\venv\lib\site-packages\rest_framework\views.py", line 469, in handle_exception
    self.raise_uncaught_exception(exc)
  File "E:\pythonProject\venv\lib\site-packages\rest_framework\views.py", line 480, in raise_uncaught_exception
    raise exc
  File "E:\pythonProject\venv\lib\site-packages\rest_framework\views.py", line 506, in dispatch
    response = handler(request, *args, **kwargs)
  File "E:\pythonProject\venv\lib\site-packages\rest_framework\decorators.py", line 50, in handler
    return func(*args, **kwargs)
  File "E:\pythonProject\venv\lib\site-packages\gerapy\server\core\views.py", line 120, in client_status
    requests.get(scrapyd_url(client.ip, client.port), timeout=3)
  File "E:\pythonProject\venv\lib\site-packages\requests\api.py", line 75, in get
    return request('get', url, params=params, **kwargs)
  File "E:\pythonProject\venv\lib\site-packages\requests\api.py", line 61, in request
    return session.request(method=method, url=url, **kwargs)
  File "E:\pythonProject\venv\lib\site-packages\requests\sessions.py", line 529, in request
    resp = self.send(prep, **send_kwargs)
  File "E:\pythonProject\venv\lib\site-packages\requests\sessions.py", line 645, in send
    r = adapter.send(request, **kwargs)
  File "E:\pythonProject\venv\lib\site-packages\requests\adapters.py", line 519, in send
    raise ConnectionError(e, request=request)
requests.exceptions.ConnectionError: HTTPConnectionPool(host='http', port=80): Max retries exceeded with url: //192.168.1.103/:6800 (Caused by NewConnectionError('<urllib3.connection.HTTPConnection object at 0x00000207219D6AC0>: Failed to establish a new connection: [Errno 11001] getaddrinfo failed'))
ERROR - 2022-09-18 03:56:09,590 - process: 9156 - utils.py - gerapy.server.core.utils - 564 - utils - HTTPConnectionPool(host='http', port=80): Max retries exceeded with url: /listprojects.json (Caused by NewConnectionError('<urllib3.connection.HTTPConnection object at 0x0000020721A7CDC0>: Failed to establish a new connection: [Errno 11001] getaddrinfo failed'))
Traceback (most recent call last):
  File "E:\pythonProject\venv\lib\site-packages\urllib3\connection.py", line 174, in _new_conn
    conn = connection.create_connection(
  File "E:\pythonProject\venv\lib\site-packages\urllib3\util\connection.py", line 72, in create_connection
    for res in socket.getaddrinfo(host, port, family, socket.SOCK_STREAM):
  File "D:\develop\python\python\lib\socket.py", line 954, in getaddrinfo
    for res in _socket.getaddrinfo(host, port, family, type, proto, flags):
socket.gaierror: [Errno 11001] getaddrinfo failed

During handling of the above exception, another exception occurred:

Traceback (most recent call last):
  File "E:\pythonProject\venv\lib\site-packages\urllib3\connectionpool.py", line 703, in urlopen
    httplib_response = self._make_request(
  File "E:\pythonProject\venv\lib\site-packages\urllib3\connectionpool.py", line 398, in _make_request
    conn.request(method, url, **httplib_request_kw)
  File "E:\pythonProject\venv\lib\site-packages\urllib3\connection.py", line 239, in request
    super(HTTPConnection, self).request(method, url, body=body, headers=headers)
  File "D:\develop\python\python\lib\http\client.py", line 1285, in request
    self._send_request(method, url, body, headers, encode_chunked)
  File "D:\develop\python\python\lib\http\client.py", line 1331, in _send_request
    self.endheaders(body, encode_chunked=encode_chunked)
  File "D:\develop\python\python\lib\http\client.py", line 1280, in endheaders
    self._send_output(message_body, encode_chunked=encode_chunked)
  File "D:\develop\python\python\lib\http\client.py", line 1040, in _send_output
    self.send(msg)
  File "D:\develop\python\python\lib\http\client.py", line 980, in send
    self.connect()
  File "E:\pythonProject\venv\lib\site-packages\urllib3\connection.py", line 205, in connect
    conn = self._new_conn()
  File "E:\pythonProject\venv\lib\site-packages\urllib3\connection.py", line 186, in _new_conn
    raise NewConnectionError(
urllib3.exceptions.NewConnectionError: <urllib3.connection.HTTPConnection object at 0x0000020721A7CDC0>: Failed to establish a new connection: [Errno 11001] getaddrinfo failed

During handling of the above exception, another exception occurred:

Traceback (most recent call last):
  File "E:\pythonProject\venv\lib\site-packages\requests\adapters.py", line 440, in send
    resp = conn.urlopen(
  File "E:\pythonProject\venv\lib\site-packages\urllib3\connectionpool.py", line 785, in urlopen
    retries = retries.increment(
  File "E:\pythonProject\venv\lib\site-packages\urllib3\util\retry.py", line 592, in increment
    raise MaxRetryError(_pool, url, error or ResponseError(cause))
urllib3.exceptions.MaxRetryError: HTTPConnectionPool(host='http', port=80): Max retries exceeded with url: /listprojects.json (Caused by NewConnectionError('<urllib3.connection.HTTPConnection object at 0x0000020721A7CDC0>: Failed to establish a new connection: [Errno 11001] getaddrinfo failed'))

During handling of the above exception, another exception occurred:

Traceback (most recent call last):
  File "E:\pythonProject\venv\lib\site-packages\gerapy\server\core\utils.py", line 562, in wrapper
    result = func(*args, **kwargs)
  File "E:\pythonProject\venv\lib\site-packages\django\views\decorators\csrf.py", line 54, in wrapped_view
    return view_func(*args, **kwargs)
  File "E:\pythonProject\venv\lib\site-packages\django\views\generic\base.py", line 71, in view
    return self.dispatch(request, *args, **kwargs)
  File "E:\pythonProject\venv\lib\site-packages\rest_framework\views.py", line 509, in dispatch
    response = self.handle_exception(exc)
  File "E:\pythonProject\venv\lib\site-packages\rest_framework\views.py", line 469, in handle_exception
    self.raise_uncaught_exception(exc)
  File "E:\pythonProject\venv\lib\site-packages\rest_framework\views.py", line 480, in raise_uncaught_exception
    raise exc
  File "E:\pythonProject\venv\lib\site-packages\rest_framework\views.py", line 506, in dispatch
    response = handler(request, *args, **kwargs)
  File "E:\pythonProject\venv\lib\site-packages\rest_framework\decorators.py", line 50, in handler
    return func(*args, **kwargs)
  File "E:\pythonProject\venv\lib\site-packages\gerapy\server\core\views.py", line 227, in project_list
    projects = scrapyd.list_projects()
  File "E:\pythonProject\venv\lib\site-packages\scrapyd_api\wrapper.py", line 148, in list_projects
    json = self.client.get(url, timeout=self.timeout)
  File "E:\pythonProject\venv\lib\site-packages\requests\sessions.py", line 542, in get
    return self.request('GET', url, **kwargs)
  File "E:\pythonProject\venv\lib\site-packages\scrapyd_api\client.py", line 37, in request
    response = super(Client, self).request(*args, **kwargs)
  File "E:\pythonProject\venv\lib\site-packages\requests\sessions.py", line 529, in request
    resp = self.send(prep, **send_kwargs)
  File "E:\pythonProject\venv\lib\site-packages\requests\sessions.py", line 645, in send
    r = adapter.send(request, **kwargs)
  File "E:\pythonProject\venv\lib\site-packages\requests\adapters.py", line 519, in send
    raise ConnectionError(e, request=request)
requests.exceptions.ConnectionError: HTTPConnectionPool(host='http', port=80): Max retries exceeded with url: /listprojects.json (Caused by NewConnectionError('<urllib3.connection.HTTPConnection object at 0x0000020721A7CDC0>: Failed to establish a new connection: [Errno 11001] getaddrinfo failed'))
ERROR - 2022-09-18 03:56:11,859 - process: 9156 - utils.py - gerapy.server.core.utils - 564 - utils - HTTPConnectionPool(host='http', port=80): Max retries exceeded with url: //192.168.1.103/:6800 (Caused by NewConnectionError('<urllib3.connection.HTTPConnection object at 0x0000020721AA6E50>: Failed to establish a new connection: [Errno 11001] getaddrinfo failed'))
Traceback (most recent call last):
  File "E:\pythonProject\venv\lib\site-packages\urllib3\connection.py", line 174, in _new_conn
    conn = connection.create_connection(
  File "E:\pythonProject\venv\lib\site-packages\urllib3\util\connection.py", line 72, in create_connection
    for res in socket.getaddrinfo(host, port, family, socket.SOCK_STREAM):
  File "D:\develop\python\python\lib\socket.py", line 954, in getaddrinfo
    for res in _socket.getaddrinfo(host, port, family, type, proto, flags):
socket.gaierror: [Errno 11001] getaddrinfo failed

During handling of the above exception, another exception occurred:

Traceback (most recent call last):
  File "E:\pythonProject\venv\lib\site-packages\urllib3\connectionpool.py", line 703, in urlopen
    httplib_response = self._make_request(
  File "E:\pythonProject\venv\lib\site-packages\urllib3\connectionpool.py", line 398, in _make_request
    conn.request(method, url, **httplib_request_kw)
  File "E:\pythonProject\venv\lib\site-packages\urllib3\connection.py", line 239, in request
    super(HTTPConnection, self).request(method, url, body=body, headers=headers)
  File "D:\develop\python\python\lib\http\client.py", line 1285, in request
    self._send_request(method, url, body, headers, encode_chunked)
  File "D:\develop\python\python\lib\http\client.py", line 1331, in _send_request
    self.endheaders(body, encode_chunked=encode_chunked)
  File "D:\develop\python\python\lib\http\client.py", line 1280, in endheaders
    self._send_output(message_body, encode_chunked=encode_chunked)
  File "D:\develop\python\python\lib\http\client.py", line 1040, in _send_output
    self.send(msg)
  File "D:\develop\python\python\lib\http\client.py", line 980, in send
    self.connect()
  File "E:\pythonProject\venv\lib\site-packages\urllib3\connection.py", line 205, in connect
    conn = self._new_conn()
  File "E:\pythonProject\venv\lib\site-packages\urllib3\connection.py", line 186, in _new_conn
    raise NewConnectionError(
urllib3.exceptions.NewConnectionError: <urllib3.connection.HTTPConnection object at 0x0000020721AA6E50>: Failed to establish a new connection: [Errno 11001] getaddrinfo failed

During handling of the above exception, another exception occurred:

Traceback (most recent call last):
  File "E:\pythonProject\venv\lib\site-packages\requests\adapters.py", line 440, in send
    resp = conn.urlopen(
  File "E:\pythonProject\venv\lib\site-packages\urllib3\connectionpool.py", line 785, in urlopen
    retries = retries.increment(
  File "E:\pythonProject\venv\lib\site-packages\urllib3\util\retry.py", line 592, in increment
    raise MaxRetryError(_pool, url, error or ResponseError(cause))
urllib3.exceptions.MaxRetryError: HTTPConnectionPool(host='http', port=80): Max retries exceeded with url: //192.168.1.103/:6800 (Caused by NewConnectionError('<urllib3.connection.HTTPConnection object at 0x0000020721AA6E50>: Failed to establish a new connection: [Errno 11001] getaddrinfo failed'))

During handling of the above exception, another exception occurred:

Traceback (most recent call last):
  File "E:\pythonProject\venv\lib\site-packages\gerapy\server\core\utils.py", line 562, in wrapper
    result = func(*args, **kwargs)
  File "E:\pythonProject\venv\lib\site-packages\django\views\decorators\csrf.py", line 54, in wrapped_view
    return view_func(*args, **kwargs)
  File "E:\pythonProject\venv\lib\site-packages\django\views\generic\base.py", line 71, in view
    return self.dispatch(request, *args, **kwargs)
  File "E:\pythonProject\venv\lib\site-packages\rest_framework\views.py", line 509, in dispatch
    response = self.handle_exception(exc)
  File "E:\pythonProject\venv\lib\site-packages\rest_framework\views.py", line 469, in handle_exception
    self.raise_uncaught_exception(exc)
  File "E:\pythonProject\venv\lib\site-packages\rest_framework\views.py", line 480, in raise_uncaught_exception
    raise exc
  File "E:\pythonProject\venv\lib\site-packages\rest_framework\views.py", line 506, in dispatch
    response = handler(request, *args, **kwargs)
  File "E:\pythonProject\venv\lib\site-packages\rest_framework\decorators.py", line 50, in handler
    return func(*args, **kwargs)
  File "E:\pythonProject\venv\lib\site-packages\gerapy\server\core\views.py", line 120, in client_status
    requests.get(scrapyd_url(client.ip, client.port), timeout=3)
  File "E:\pythonProject\venv\lib\site-packages\requests\api.py", line 75, in get
    return request('get', url, params=params, **kwargs)
  File "E:\pythonProject\venv\lib\site-packages\requests\api.py", line 61, in request
    return session.request(method=method, url=url, **kwargs)
  File "E:\pythonProject\venv\lib\site-packages\requests\sessions.py", line 529, in request
    resp = self.send(prep, **send_kwargs)
  File "E:\pythonProject\venv\lib\site-packages\requests\sessions.py", line 645, in send
    r = adapter.send(request, **kwargs)
  File "E:\pythonProject\venv\lib\site-packages\requests\adapters.py", line 519, in send
    raise ConnectionError(e, request=request)
requests.exceptions.ConnectionError: HTTPConnectionPool(host='http', port=80): Max retries exceeded with url: //192.168.1.103/:6800 (Caused by NewConnectionError('<urllib3.connection.HTTPConnection object at 0x0000020721AA6E50>: Failed to establish a new connection: [Errno 11001] getaddrinfo failed'))
ERROR - 2022-09-18 03:56:14,129 - process: 9156 - utils.py - gerapy.server.core.utils - 564 - utils - HTTPConnectionPool(host='http', port=80): Max retries exceeded with url: //192.168.1.103/:6800 (Caused by NewConnectionError('<urllib3.connection.HTTPConnection object at 0x00000207219A7F70>: Failed to establish a new connection: [Errno 11001] getaddrinfo failed'))
Traceback (most recent call last):
  File "E:\pythonProject\venv\lib\site-packages\urllib3\connection.py", line 174, in _new_conn
    conn = connection.create_connection(
  File "E:\pythonProject\venv\lib\site-packages\urllib3\util\connection.py", line 72, in create_connection
    for res in socket.getaddrinfo(host, port, family, socket.SOCK_STREAM):
  File "D:\develop\python\python\lib\socket.py", line 954, in getaddrinfo
    for res in _socket.getaddrinfo(host, port, family, type, proto, flags):
socket.gaierror: [Errno 11001] getaddrinfo failed

During handling of the above exception, another exception occurred:

Traceback (most recent call last):
  File "E:\pythonProject\venv\lib\site-packages\urllib3\connectionpool.py", line 703, in urlopen
    httplib_response = self._make_request(
  File "E:\pythonProject\venv\lib\site-packages\urllib3\connectionpool.py", line 398, in _make_request
    conn.request(method, url, **httplib_request_kw)
  File "E:\pythonProject\venv\lib\site-packages\urllib3\connection.py", line 239, in request
    super(HTTPConnection, self).request(method, url, body=body, headers=headers)
  File "D:\develop\python\python\lib\http\client.py", line 1285, in request
    self._send_request(method, url, body, headers, encode_chunked)
  File "D:\develop\python\python\lib\http\client.py", line 1331, in _send_request
    self.endheaders(body, encode_chunked=encode_chunked)
  File "D:\develop\python\python\lib\http\client.py", line 1280, in endheaders
    self._send_output(message_body, encode_chunked=encode_chunked)
  File "D:\develop\python\python\lib\http\client.py", line 1040, in _send_output
    self.send(msg)
  File "D:\develop\python\python\lib\http\client.py", line 980, in send
    self.connect()
  File "E:\pythonProject\venv\lib\site-packages\urllib3\connection.py", line 205, in connect
    conn = self._new_conn()
  File "E:\pythonProject\venv\lib\site-packages\urllib3\connection.py", line 186, in _new_conn
    raise NewConnectionError(
urllib3.exceptions.NewConnectionError: <urllib3.connection.HTTPConnection object at 0x00000207219A7F70>: Failed to establish a new connection: [Errno 11001] getaddrinfo failed

During handling of the above exception, another exception occurred:

Traceback (most recent call last):
  File "E:\pythonProject\venv\lib\site-packages\requests\adapters.py", line 440, in send
    resp = conn.urlopen(
  File "E:\pythonProject\venv\lib\site-packages\urllib3\connectionpool.py", line 785, in urlopen
    retries = retries.increment(
  File "E:\pythonProject\venv\lib\site-packages\urllib3\util\retry.py", line 592, in increment
    raise MaxRetryError(_pool, url, error or ResponseError(cause))
urllib3.exceptions.MaxRetryError: HTTPConnectionPool(host='http', port=80): Max retries exceeded with url: //192.168.1.103/:6800 (Caused by NewConnectionError('<urllib3.connection.HTTPConnection object at 0x00000207219A7F70>: Failed to establish a new connection: [Errno 11001] getaddrinfo failed'))

During handling of the above exception, another exception occurred:

Traceback (most recent call last):
  File "E:\pythonProject\venv\lib\site-packages\gerapy\server\core\utils.py", line 562, in wrapper
    result = func(*args, **kwargs)
  File "E:\pythonProject\venv\lib\site-packages\django\views\decorators\csrf.py", line 54, in wrapped_view
    return view_func(*args, **kwargs)
  File "E:\pythonProject\venv\lib\site-packages\django\views\generic\base.py", line 71, in view
    return self.dispatch(request, *args, **kwargs)
  File "E:\pythonProject\venv\lib\site-packages\rest_framework\views.py", line 509, in dispatch
    response = self.handle_exception(exc)
  File "E:\pythonProject\venv\lib\site-packages\rest_framework\views.py", line 469, in handle_exception
    self.raise_uncaught_exception(exc)
  File "E:\pythonProject\venv\lib\site-packages\rest_framework\views.py", line 480, in raise_uncaught_exception
    raise exc
  File "E:\pythonProject\venv\lib\site-packages\rest_framework\views.py", line 506, in dispatch
    response = handler(request, *args, **kwargs)
  File "E:\pythonProject\venv\lib\site-packages\rest_framework\decorators.py", line 50, in handler
    return func(*args, **kwargs)
  File "E:\pythonProject\venv\lib\site-packages\gerapy\server\core\views.py", line 120, in client_status
    requests.get(scrapyd_url(client.ip, client.port), timeout=3)
  File "E:\pythonProject\venv\lib\site-packages\requests\api.py", line 75, in get
    return request('get', url, params=params, **kwargs)
  File "E:\pythonProject\venv\lib\site-packages\requests\api.py", line 61, in request
    return session.request(method=method, url=url, **kwargs)
  File "E:\pythonProject\venv\lib\site-packages\requests\sessions.py", line 529, in request
    resp = self.send(prep, **send_kwargs)
  File "E:\pythonProject\venv\lib\site-packages\requests\sessions.py", line 645, in send
    r = adapter.send(request, **kwargs)
  File "E:\pythonProject\venv\lib\site-packages\requests\adapters.py", line 519, in send
    raise ConnectionError(e, request=request)
requests.exceptions.ConnectionError: HTTPConnectionPool(host='http', port=80): Max retries exceeded with url: //192.168.1.103/:6800 (Caused by NewConnectionError('<urllib3.connection.HTTPConnection object at 0x00000207219A7F70>: Failed to establish a new connection: [Errno 11001] getaddrinfo failed'))
ERROR - 2022-09-18 03:56:16,392 - process: 9156 - utils.py - gerapy.server.core.utils - 564 - utils - HTTPConnectionPool(host='http', port=80): Max retries exceeded with url: //192.168.1.103/:6800 (Caused by NewConnectionError('<urllib3.connection.HTTPConnection object at 0x00000207219008B0>: Failed to establish a new connection: [Errno 11001] getaddrinfo failed'))
Traceback (most recent call last):
  File "E:\pythonProject\venv\lib\site-packages\urllib3\connection.py", line 174, in _new_conn
    conn = connection.create_connection(
  File "E:\pythonProject\venv\lib\site-packages\urllib3\util\connection.py", line 72, in create_connection
    for res in socket.getaddrinfo(host, port, family, socket.SOCK_STREAM):
  File "D:\develop\python\python\lib\socket.py", line 954, in getaddrinfo
    for res in _socket.getaddrinfo(host, port, family, type, proto, flags):
socket.gaierror: [Errno 11001] getaddrinfo failed

During handling of the above exception, another exception occurred:

Traceback (most recent call last):
  File "E:\pythonProject\venv\lib\site-packages\urllib3\connectionpool.py", line 703, in urlopen
    httplib_response = self._make_request(
  File "E:\pythonProject\venv\lib\site-packages\urllib3\connectionpool.py", line 398, in _make_request
    conn.request(method, url, **httplib_request_kw)
  File "E:\pythonProject\venv\lib\site-packages\urllib3\connection.py", line 239, in request
    super(HTTPConnection, self).request(method, url, body=body, headers=headers)
  File "D:\develop\python\python\lib\http\client.py", line 1285, in request
    self._send_request(method, url, body, headers, encode_chunked)
  File "D:\develop\python\python\lib\http\client.py", line 1331, in _send_request
    self.endheaders(body, encode_chunked=encode_chunked)
  File "D:\develop\python\python\lib\http\client.py", line 1280, in endheaders
    self._send_output(message_body, encode_chunked=encode_chunked)
  File "D:\develop\python\python\lib\http\client.py", line 1040, in _send_output
    self.send(msg)
  File "D:\develop\python\python\lib\http\client.py", line 980, in send
    self.connect()
  File "E:\pythonProject\venv\lib\site-packages\urllib3\connection.py", line 205, in connect
    conn = self._new_conn()
  File "E:\pythonProject\venv\lib\site-packages\urllib3\connection.py", line 186, in _new_conn
    raise NewConnectionError(
urllib3.exceptions.NewConnectionError: <urllib3.connection.HTTPConnection object at 0x00000207219008B0>: Failed to establish a new connection: [Errno 11001] getaddrinfo failed

During handling of the above exception, another exception occurred:

Traceback (most recent call last):
  File "E:\pythonProject\venv\lib\site-packages\requests\adapters.py", line 440, in send
    resp = conn.urlopen(
  File "E:\pythonProject\venv\lib\site-packages\urllib3\connectionpool.py", line 785, in urlopen
    retries = retries.increment(
  File "E:\pythonProject\venv\lib\site-packages\urllib3\util\retry.py", line 592, in increment
    raise MaxRetryError(_pool, url, error or ResponseError(cause))
urllib3.exceptions.MaxRetryError: HTTPConnectionPool(host='http', port=80): Max retries exceeded with url: //192.168.1.103/:6800 (Caused by NewConnectionError('<urllib3.connection.HTTPConnection object at 0x00000207219008B0>: Failed to establish a new connection: [Errno 11001] getaddrinfo failed'))

During handling of the above exception, another exception occurred:

Traceback (most recent call last):
  File "E:\pythonProject\venv\lib\site-packages\gerapy\server\core\utils.py", line 562, in wrapper
    result = func(*args, **kwargs)
  File "E:\pythonProject\venv\lib\site-packages\django\views\decorators\csrf.py", line 54, in wrapped_view
    return view_func(*args, **kwargs)
  File "E:\pythonProject\venv\lib\site-packages\django\views\generic\base.py", line 71, in view
    return self.dispatch(request, *args, **kwargs)
  File "E:\pythonProject\venv\lib\site-packages\rest_framework\views.py", line 509, in dispatch
    response = self.handle_exception(exc)
  File "E:\pythonProject\venv\lib\site-packages\rest_framework\views.py", line 469, in handle_exception
    self.raise_uncaught_exception(exc)
  File "E:\pythonProject\venv\lib\site-packages\rest_framework\views.py", line 480, in raise_uncaught_exception
    raise exc
  File "E:\pythonProject\venv\lib\site-packages\rest_framework\views.py", line 506, in dispatch
    response = handler(request, *args, **kwargs)
  File "E:\pythonProject\venv\lib\site-packages\rest_framework\decorators.py", line 50, in handler
    return func(*args, **kwargs)
  File "E:\pythonProject\venv\lib\site-packages\gerapy\server\core\views.py", line 120, in client_status
    requests.get(scrapyd_url(client.ip, client.port), timeout=3)
  File "E:\pythonProject\venv\lib\site-packages\requests\api.py", line 75, in get
    return request('get', url, params=params, **kwargs)
  File "E:\pythonProject\venv\lib\site-packages\requests\api.py", line 61, in request
    return session.request(method=method, url=url, **kwargs)
  File "E:\pythonProject\venv\lib\site-packages\requests\sessions.py", line 529, in request
    resp = self.send(prep, **send_kwargs)
  File "E:\pythonProject\venv\lib\site-packages\requests\sessions.py", line 645, in send
    r = adapter.send(request, **kwargs)
  File "E:\pythonProject\venv\lib\site-packages\requests\adapters.py", line 519, in send
    raise ConnectionError(e, request=request)
requests.exceptions.ConnectionError: HTTPConnectionPool(host='http', port=80): Max retries exceeded with url: //192.168.1.103/:6800 (Caused by NewConnectionError('<urllib3.connection.HTTPConnection object at 0x00000207219008B0>: Failed to establish a new connection: [Errno 11001] getaddrinfo failed'))
ERROR - 2022-09-18 03:56:18,661 - process: 9156 - utils.py - gerapy.server.core.utils - 564 - utils - HTTPConnectionPool(host='http', port=80): Max retries exceeded with url: //192.168.1.103/:6800 (Caused by NewConnectionError('<urllib3.connection.HTTPConnection object at 0x0000020721ABDBE0>: Failed to establish a new connection: [Errno 11001] getaddrinfo failed'))
Traceback (most recent call last):
  File "E:\pythonProject\venv\lib\site-packages\urllib3\connection.py", line 174, in _new_conn
    conn = connection.create_connection(
  File "E:\pythonProject\venv\lib\site-packages\urllib3\util\connection.py", line 72, in create_connection
    for res in socket.getaddrinfo(host, port, family, socket.SOCK_STREAM):
  File "D:\develop\python\python\lib\socket.py", line 954, in getaddrinfo
    for res in _socket.getaddrinfo(host, port, family, type, proto, flags):
socket.gaierror: [Errno 11001] getaddrinfo failed

During handling of the above exception, another exception occurred:

Traceback (most recent call last):
  File "E:\pythonProject\venv\lib\site-packages\urllib3\connectionpool.py", line 703, in urlopen
    httplib_response = self._make_request(
  File "E:\pythonProject\venv\lib\site-packages\urllib3\connectionpool.py", line 398, in _make_request
    conn.request(method, url, **httplib_request_kw)
  File "E:\pythonProject\venv\lib\site-packages\urllib3\connection.py", line 239, in request
    super(HTTPConnection, self).request(method, url, body=body, headers=headers)
  File "D:\develop\python\python\lib\http\client.py", line 1285, in request
    self._send_request(method, url, body, headers, encode_chunked)
  File "D:\develop\python\python\lib\http\client.py", line 1331, in _send_request
    self.endheaders(body, encode_chunked=encode_chunked)
  File "D:\develop\python\python\lib\http\client.py", line 1280, in endheaders
    self._send_output(message_body, encode_chunked=encode_chunked)
  File "D:\develop\python\python\lib\http\client.py", line 1040, in _send_output
    self.send(msg)
  File "D:\develop\python\python\lib\http\client.py", line 980, in send
    self.connect()
  File "E:\pythonProject\venv\lib\site-packages\urllib3\connection.py", line 205, in connect
    conn = self._new_conn()
  File "E:\pythonProject\venv\lib\site-packages\urllib3\connection.py", line 186, in _new_conn
    raise NewConnectionError(
urllib3.exceptions.NewConnectionError: <urllib3.connection.HTTPConnection object at 0x0000020721ABDBE0>: Failed to establish a new connection: [Errno 11001] getaddrinfo failed

During handling of the above exception, another exception occurred:

Traceback (most recent call last):
  File "E:\pythonProject\venv\lib\site-packages\requests\adapters.py", line 440, in send
    resp = conn.urlopen(
  File "E:\pythonProject\venv\lib\site-packages\urllib3\connectionpool.py", line 785, in urlopen
    retries = retries.increment(
  File "E:\pythonProject\venv\lib\site-packages\urllib3\util\retry.py", line 592, in increment
    raise MaxRetryError(_pool, url, error or ResponseError(cause))
urllib3.exceptions.MaxRetryError: HTTPConnectionPool(host='http', port=80): Max retries exceeded with url: //192.168.1.103/:6800 (Caused by NewConnectionError('<urllib3.connection.HTTPConnection object at 0x0000020721ABDBE0>: Failed to establish a new connection: [Errno 11001] getaddrinfo failed'))

During handling of the above exception, another exception occurred:

Traceback (most recent call last):
  File "E:\pythonProject\venv\lib\site-packages\gerapy\server\core\utils.py", line 562, in wrapper
    result = func(*args, **kwargs)
  File "E:\pythonProject\venv\lib\site-packages\django\views\decorators\csrf.py", line 54, in wrapped_view
    return view_func(*args, **kwargs)
  File "E:\pythonProject\venv\lib\site-packages\django\views\generic\base.py", line 71, in view
    return self.dispatch(request, *args, **kwargs)
  File "E:\pythonProject\venv\lib\site-packages\rest_framework\views.py", line 509, in dispatch
    response = self.handle_exception(exc)
  File "E:\pythonProject\venv\lib\site-packages\rest_framework\views.py", line 469, in handle_exception
    self.raise_uncaught_exception(exc)
  File "E:\pythonProject\venv\lib\site-packages\rest_framework\views.py", line 480, in raise_uncaught_exception
    raise exc
  File "E:\pythonProject\venv\lib\site-packages\rest_framework\views.py", line 506, in dispatch
    response = handler(request, *args, **kwargs)
  File "E:\pythonProject\venv\lib\site-packages\rest_framework\decorators.py", line 50, in handler
    return func(*args, **kwargs)
  File "E:\pythonProject\venv\lib\site-packages\gerapy\server\core\views.py", line 120, in client_status
    requests.get(scrapyd_url(client.ip, client.port), timeout=3)
  File "E:\pythonProject\venv\lib\site-packages\requests\api.py", line 75, in get
    return request('get', url, params=params, **kwargs)
  File "E:\pythonProject\venv\lib\site-packages\requests\api.py", line 61, in request
    return session.request(method=method, url=url, **kwargs)
  File "E:\pythonProject\venv\lib\site-packages\requests\sessions.py", line 529, in request
    resp = self.send(prep, **send_kwargs)
  File "E:\pythonProject\venv\lib\site-packages\requests\sessions.py", line 645, in send
    r = adapter.send(request, **kwargs)
  File "E:\pythonProject\venv\lib\site-packages\requests\adapters.py", line 519, in send
    raise ConnectionError(e, request=request)
requests.exceptions.ConnectionError: HTTPConnectionPool(host='http', port=80): Max retries exceeded with url: //192.168.1.103/:6800 (Caused by NewConnectionError('<urllib3.connection.HTTPConnection object at 0x0000020721ABDBE0>: Failed to establish a new connection: [Errno 11001] getaddrinfo failed'))
ERROR - 2022-09-18 03:56:20,932 - process: 9156 - utils.py - gerapy.server.core.utils - 564 - utils - HTTPConnectionPool(host='http', port=80): Max retries exceeded with url: //192.168.1.103/:6800 (Caused by NewConnectionError('<urllib3.connection.HTTPConnection object at 0x0000020721AC6B80>: Failed to establish a new connection: [Errno 11001] getaddrinfo failed'))
Traceback (most recent call last):
  File "E:\pythonProject\venv\lib\site-packages\urllib3\connection.py", line 174, in _new_conn
    conn = connection.create_connection(
  File "E:\pythonProject\venv\lib\site-packages\urllib3\util\connection.py", line 72, in create_connection
    for res in socket.getaddrinfo(host, port, family, socket.SOCK_STREAM):
  File "D:\develop\python\python\lib\socket.py", line 954, in getaddrinfo
    for res in _socket.getaddrinfo(host, port, family, type, proto, flags):
socket.gaierror: [Errno 11001] getaddrinfo failed

During handling of the above exception, another exception occurred:

Traceback (most recent call last):
  File "E:\pythonProject\venv\lib\site-packages\urllib3\connectionpool.py", line 703, in urlopen
    httplib_response = self._make_request(
  File "E:\pythonProject\venv\lib\site-packages\urllib3\connectionpool.py", line 398, in _make_request
    conn.request(method, url, **httplib_request_kw)
  File "E:\pythonProject\venv\lib\site-packages\urllib3\connection.py", line 239, in request
    super(HTTPConnection, self).request(method, url, body=body, headers=headers)
  File "D:\develop\python\python\lib\http\client.py", line 1285, in request
    self._send_request(method, url, body, headers, encode_chunked)
  File "D:\develop\python\python\lib\http\client.py", line 1331, in _send_request
    self.endheaders(body, encode_chunked=encode_chunked)
  File "D:\develop\python\python\lib\http\client.py", line 1280, in endheaders
    self._send_output(message_body, encode_chunked=encode_chunked)
  File "D:\develop\python\python\lib\http\client.py", line 1040, in _send_output
    self.send(msg)
  File "D:\develop\python\python\lib\http\client.py", line 980, in send
    self.connect()
  File "E:\pythonProject\venv\lib\site-packages\urllib3\connection.py", line 205, in connect
    conn = self._new_conn()
  File "E:\pythonProject\venv\lib\site-packages\urllib3\connection.py", line 186, in _new_conn
    raise NewConnectionError(
urllib3.exceptions.NewConnectionError: <urllib3.connection.HTTPConnection object at 0x0000020721AC6B80>: Failed to establish a new connection: [Errno 11001] getaddrinfo failed

During handling of the above exception, another exception occurred:

Traceback (most recent call last):
  File "E:\pythonProject\venv\lib\site-packages\requests\adapters.py", line 440, in send
    resp = conn.urlopen(
  File "E:\pythonProject\venv\lib\site-packages\urllib3\connectionpool.py", line 785, in urlopen
    retries = retries.increment(
  File "E:\pythonProject\venv\lib\site-packages\urllib3\util\retry.py", line 592, in increment
    raise MaxRetryError(_pool, url, error or ResponseError(cause))
urllib3.exceptions.MaxRetryError: HTTPConnectionPool(host='http', port=80): Max retries exceeded with url: //192.168.1.103/:6800 (Caused by NewConnectionError('<urllib3.connection.HTTPConnection object at 0x0000020721AC6B80>: Failed to establish a new connection: [Errno 11001] getaddrinfo failed'))

During handling of the above exception, another exception occurred:

Traceback (most recent call last):
  File "E:\pythonProject\venv\lib\site-packages\gerapy\server\core\utils.py", line 562, in wrapper
    result = func(*args, **kwargs)
  File "E:\pythonProject\venv\lib\site-packages\django\views\decorators\csrf.py", line 54, in wrapped_view
    return view_func(*args, **kwargs)
  File "E:\pythonProject\venv\lib\site-packages\django\views\generic\base.py", line 71, in view
    return self.dispatch(request, *args, **kwargs)
  File "E:\pythonProject\venv\lib\site-packages\rest_framework\views.py", line 509, in dispatch
    response = self.handle_exception(exc)
  File "E:\pythonProject\venv\lib\site-packages\rest_framework\views.py", line 469, in handle_exception
    self.raise_uncaught_exception(exc)
  File "E:\pythonProject\venv\lib\site-packages\rest_framework\views.py", line 480, in raise_uncaught_exception
    raise exc
  File "E:\pythonProject\venv\lib\site-packages\rest_framework\views.py", line 506, in dispatch
    response = handler(request, *args, **kwargs)
  File "E:\pythonProject\venv\lib\site-packages\rest_framework\decorators.py", line 50, in handler
    return func(*args, **kwargs)
  File "E:\pythonProject\venv\lib\site-packages\gerapy\server\core\views.py", line 120, in client_status
    requests.get(scrapyd_url(client.ip, client.port), timeout=3)
  File "E:\pythonProject\venv\lib\site-packages\requests\api.py", line 75, in get
    return request('get', url, params=params, **kwargs)
  File "E:\pythonProject\venv\lib\site-packages\requests\api.py", line 61, in request
    return session.request(method=method, url=url, **kwargs)
  File "E:\pythonProject\venv\lib\site-packages\requests\sessions.py", line 529, in request
    resp = self.send(prep, **send_kwargs)
  File "E:\pythonProject\venv\lib\site-packages\requests\sessions.py", line 645, in send
    r = adapter.send(request, **kwargs)
  File "E:\pythonProject\venv\lib\site-packages\requests\adapters.py", line 519, in send
    raise ConnectionError(e, request=request)
requests.exceptions.ConnectionError: HTTPConnectionPool(host='http', port=80): Max retries exceeded with url: //192.168.1.103/:6800 (Caused by NewConnectionError('<urllib3.connection.HTTPConnection object at 0x0000020721AC6B80>: Failed to establish a new connection: [Errno 11001] getaddrinfo failed'))
ERROR - 2022-09-18 03:56:23,227 - process: 9156 - utils.py - gerapy.server.core.utils - 564 - utils - HTTPConnectionPool(host='http', port=80): Max retries exceeded with url: /listprojects.json (Caused by NewConnectionError('<urllib3.connection.HTTPConnection object at 0x0000020721AA79A0>: Failed to establish a new connection: [Errno 11001] getaddrinfo failed'))
Traceback (most recent call last):
  File "E:\pythonProject\venv\lib\site-packages\urllib3\connection.py", line 174, in _new_conn
    conn = connection.create_connection(
  File "E:\pythonProject\venv\lib\site-packages\urllib3\util\connection.py", line 72, in create_connection
    for res in socket.getaddrinfo(host, port, family, socket.SOCK_STREAM):
  File "D:\develop\python\python\lib\socket.py", line 954, in getaddrinfo
    for res in _socket.getaddrinfo(host, port, family, type, proto, flags):
socket.gaierror: [Errno 11001] getaddrinfo failed

During handling of the above exception, another exception occurred:

Traceback (most recent call last):
  File "E:\pythonProject\venv\lib\site-packages\urllib3\connectionpool.py", line 703, in urlopen
    httplib_response = self._make_request(
  File "E:\pythonProject\venv\lib\site-packages\urllib3\connectionpool.py", line 398, in _make_request
    conn.request(method, url, **httplib_request_kw)
  File "E:\pythonProject\venv\lib\site-packages\urllib3\connection.py", line 239, in request
    super(HTTPConnection, self).request(method, url, body=body, headers=headers)
  File "D:\develop\python\python\lib\http\client.py", line 1285, in request
    self._send_request(method, url, body, headers, encode_chunked)
  File "D:\develop\python\python\lib\http\client.py", line 1331, in _send_request
    self.endheaders(body, encode_chunked=encode_chunked)
  File "D:\develop\python\python\lib\http\client.py", line 1280, in endheaders
    self._send_output(message_body, encode_chunked=encode_chunked)
  File "D:\develop\python\python\lib\http\client.py", line 1040, in _send_output
    self.send(msg)
  File "D:\develop\python\python\lib\http\client.py", line 980, in send
    self.connect()
  File "E:\pythonProject\venv\lib\site-packages\urllib3\connection.py", line 205, in connect
    conn = self._new_conn()
  File "E:\pythonProject\venv\lib\site-packages\urllib3\connection.py", line 186, in _new_conn
    raise NewConnectionError(
urllib3.exceptions.NewConnectionError: <urllib3.connection.HTTPConnection object at 0x0000020721AA79A0>: Failed to establish a new connection: [Errno 11001] getaddrinfo failed

During handling of the above exception, another exception occurred:

Traceback (most recent call last):
  File "E:\pythonProject\venv\lib\site-packages\requests\adapters.py", line 440, in send
    resp = conn.urlopen(
  File "E:\pythonProject\venv\lib\site-packages\urllib3\connectionpool.py", line 785, in urlopen
    retries = retries.increment(
  File "E:\pythonProject\venv\lib\site-packages\urllib3\util\retry.py", line 592, in increment
    raise MaxRetryError(_pool, url, error or ResponseError(cause))
urllib3.exceptions.MaxRetryError: HTTPConnectionPool(host='http', port=80): Max retries exceeded with url: /listprojects.json (Caused by NewConnectionError('<urllib3.connection.HTTPConnection object at 0x0000020721AA79A0>: Failed to establish a new connection: [Errno 11001] getaddrinfo failed'))

During handling of the above exception, another exception occurred:

Traceback (most recent call last):
  File "E:\pythonProject\venv\lib\site-packages\gerapy\server\core\utils.py", line 562, in wrapper
    result = func(*args, **kwargs)
  File "E:\pythonProject\venv\lib\site-packages\django\views\decorators\csrf.py", line 54, in wrapped_view
    return view_func(*args, **kwargs)
  File "E:\pythonProject\venv\lib\site-packages\django\views\generic\base.py", line 71, in view
    return self.dispatch(request, *args, **kwargs)
  File "E:\pythonProject\venv\lib\site-packages\rest_framework\views.py", line 509, in dispatch
    response = self.handle_exception(exc)
  File "E:\pythonProject\venv\lib\site-packages\rest_framework\views.py", line 469, in handle_exception
    self.raise_uncaught_exception(exc)
  File "E:\pythonProject\venv\lib\site-packages\rest_framework\views.py", line 480, in raise_uncaught_exception
    raise exc
  File "E:\pythonProject\venv\lib\site-packages\rest_framework\views.py", line 506, in dispatch
    response = handler(request, *args, **kwargs)
  File "E:\pythonProject\venv\lib\site-packages\rest_framework\decorators.py", line 50, in handler
    return func(*args, **kwargs)
  File "E:\pythonProject\venv\lib\site-packages\gerapy\server\core\views.py", line 227, in project_list
    projects = scrapyd.list_projects()
  File "E:\pythonProject\venv\lib\site-packages\scrapyd_api\wrapper.py", line 148, in list_projects
    json = self.client.get(url, timeout=self.timeout)
  File "E:\pythonProject\venv\lib\site-packages\requests\sessions.py", line 542, in get
    return self.request('GET', url, **kwargs)
  File "E:\pythonProject\venv\lib\site-packages\scrapyd_api\client.py", line 37, in request
    response = super(Client, self).request(*args, **kwargs)
  File "E:\pythonProject\venv\lib\site-packages\requests\sessions.py", line 529, in request
    resp = self.send(prep, **send_kwargs)
  File "E:\pythonProject\venv\lib\site-packages\requests\sessions.py", line 645, in send
    r = adapter.send(request, **kwargs)
  File "E:\pythonProject\venv\lib\site-packages\requests\adapters.py", line 519, in send
    raise ConnectionError(e, request=request)
requests.exceptions.ConnectionError: HTTPConnectionPool(host='http', port=80): Max retries exceeded with url: /listprojects.json (Caused by NewConnectionError('<urllib3.connection.HTTPConnection object at 0x0000020721AA79A0>: Failed to establish a new connection: [Errno 11001] getaddrinfo failed'))
ERROR - 2022-09-18 03:56:25,531 - process: 9156 - utils.py - gerapy.server.core.utils - 564 - utils - HTTPConnectionPool(host='http', port=80): Max retries exceeded with url: /listprojects.json (Caused by NewConnectionError('<urllib3.connection.HTTPConnection object at 0x0000020721AB0070>: Failed to establish a new connection: [Errno 11001] getaddrinfo failed'))
Traceback (most recent call last):
  File "E:\pythonProject\venv\lib\site-packages\urllib3\connection.py", line 174, in _new_conn
    conn = connection.create_connection(
  File "E:\pythonProject\venv\lib\site-packages\urllib3\util\connection.py", line 72, in create_connection
    for res in socket.getaddrinfo(host, port, family, socket.SOCK_STREAM):
  File "D:\develop\python\python\lib\socket.py", line 954, in getaddrinfo
    for res in _socket.getaddrinfo(host, port, family, type, proto, flags):
socket.gaierror: [Errno 11001] getaddrinfo failed

During handling of the above exception, another exception occurred:

Traceback (most recent call last):
  File "E:\pythonProject\venv\lib\site-packages\urllib3\connectionpool.py", line 703, in urlopen
    httplib_response = self._make_request(
  File "E:\pythonProject\venv\lib\site-packages\urllib3\connectionpool.py", line 398, in _make_request
    conn.request(method, url, **httplib_request_kw)
  File "E:\pythonProject\venv\lib\site-packages\urllib3\connection.py", line 239, in request
    super(HTTPConnection, self).request(method, url, body=body, headers=headers)
  File "D:\develop\python\python\lib\http\client.py", line 1285, in request
    self._send_request(method, url, body, headers, encode_chunked)
  File "D:\develop\python\python\lib\http\client.py", line 1331, in _send_request
    self.endheaders(body, encode_chunked=encode_chunked)
  File "D:\develop\python\python\lib\http\client.py", line 1280, in endheaders
    self._send_output(message_body, encode_chunked=encode_chunked)
  File "D:\develop\python\python\lib\http\client.py", line 1040, in _send_output
    self.send(msg)
  File "D:\develop\python\python\lib\http\client.py", line 980, in send
    self.connect()
  File "E:\pythonProject\venv\lib\site-packages\urllib3\connection.py", line 205, in connect
    conn = self._new_conn()
  File "E:\pythonProject\venv\lib\site-packages\urllib3\connection.py", line 186, in _new_conn
    raise NewConnectionError(
urllib3.exceptions.NewConnectionError: <urllib3.connection.HTTPConnection object at 0x0000020721AB0070>: Failed to establish a new connection: [Errno 11001] getaddrinfo failed

During handling of the above exception, another exception occurred:

Traceback (most recent call last):
  File "E:\pythonProject\venv\lib\site-packages\requests\adapters.py", line 440, in send
    resp = conn.urlopen(
  File "E:\pythonProject\venv\lib\site-packages\urllib3\connectionpool.py", line 785, in urlopen
    retries = retries.increment(
  File "E:\pythonProject\venv\lib\site-packages\urllib3\util\retry.py", line 592, in increment
    raise MaxRetryError(_pool, url, error or ResponseError(cause))
urllib3.exceptions.MaxRetryError: HTTPConnectionPool(host='http', port=80): Max retries exceeded with url: /listprojects.json (Caused by NewConnectionError('<urllib3.connection.HTTPConnection object at 0x0000020721AB0070>: Failed to establish a new connection: [Errno 11001] getaddrinfo failed'))

During handling of the above exception, another exception occurred:

Traceback (most recent call last):
  File "E:\pythonProject\venv\lib\site-packages\gerapy\server\core\utils.py", line 562, in wrapper
    result = func(*args, **kwargs)
  File "E:\pythonProject\venv\lib\site-packages\django\views\decorators\csrf.py", line 54, in wrapped_view
    return view_func(*args, **kwargs)
  File "E:\pythonProject\venv\lib\site-packages\django\views\generic\base.py", line 71, in view
    return self.dispatch(request, *args, **kwargs)
  File "E:\pythonProject\venv\lib\site-packages\rest_framework\views.py", line 509, in dispatch
    response = self.handle_exception(exc)
  File "E:\pythonProject\venv\lib\site-packages\rest_framework\views.py", line 469, in handle_exception
    self.raise_uncaught_exception(exc)
  File "E:\pythonProject\venv\lib\site-packages\rest_framework\views.py", line 480, in raise_uncaught_exception
    raise exc
  File "E:\pythonProject\venv\lib\site-packages\rest_framework\views.py", line 506, in dispatch
    response = handler(request, *args, **kwargs)
  File "E:\pythonProject\venv\lib\site-packages\rest_framework\decorators.py", line 50, in handler
    return func(*args, **kwargs)
  File "E:\pythonProject\venv\lib\site-packages\gerapy\server\core\views.py", line 227, in project_list
    projects = scrapyd.list_projects()
  File "E:\pythonProject\venv\lib\site-packages\scrapyd_api\wrapper.py", line 148, in list_projects
    json = self.client.get(url, timeout=self.timeout)
  File "E:\pythonProject\venv\lib\site-packages\requests\sessions.py", line 542, in get
    return self.request('GET', url, **kwargs)
  File "E:\pythonProject\venv\lib\site-packages\scrapyd_api\client.py", line 37, in request
    response = super(Client, self).request(*args, **kwargs)
  File "E:\pythonProject\venv\lib\site-packages\requests\sessions.py", line 529, in request
    resp = self.send(prep, **send_kwargs)
  File "E:\pythonProject\venv\lib\site-packages\requests\sessions.py", line 645, in send
    r = adapter.send(request, **kwargs)
  File "E:\pythonProject\venv\lib\site-packages\requests\adapters.py", line 519, in send
    raise ConnectionError(e, request=request)
requests.exceptions.ConnectionError: HTTPConnectionPool(host='http', port=80): Max retries exceeded with url: /listprojects.json (Caused by NewConnectionError('<urllib3.connection.HTTPConnection object at 0x0000020721AB0070>: Failed to establish a new connection: [Errno 11001] getaddrinfo failed'))
