INFO - 2022-09-19 22:12:53,531 - process: 704 - scheduler.py - gerapy.server.core.scheduler - 105 - scheduler - successfully synced task with jobs with force
ERROR - 2022-09-19 22:23:12,989 - process: 704 - utils.py - gerapy.server.core.utils - 564 - utils - HTTPConnectionPool(host='92.168.1.102', port=6800): Max retries exceeded with url: / (Caused by ConnectTimeoutError(<urllib3.connection.HTTPConnection object at 0x00000240F90338E0>, 'Connection to 92.168.1.102 timed out. (connect timeout=3)'))
Traceback (most recent call last):
  File "E:\pythonProject\venv\lib\site-packages\urllib3\connection.py", line 174, in _new_conn
    conn = connection.create_connection(
  File "E:\pythonProject\venv\lib\site-packages\urllib3\util\connection.py", line 95, in create_connection
    raise err
  File "E:\pythonProject\venv\lib\site-packages\urllib3\util\connection.py", line 85, in create_connection
    sock.connect(sa)
socket.timeout: timed out

During handling of the above exception, another exception occurred:

Traceback (most recent call last):
  File "E:\pythonProject\venv\lib\site-packages\urllib3\connectionpool.py", line 703, in urlopen
    httplib_response = self._make_request(
  File "E:\pythonProject\venv\lib\site-packages\urllib3\connectionpool.py", line 398, in _make_request
    conn.request(method, url, **httplib_request_kw)
  File "E:\pythonProject\venv\lib\site-packages\urllib3\connection.py", line 239, in request
    super(HTTPConnection, self).request(method, url, body=body, headers=headers)
  File "D:\develop\python\python\lib\http\client.py", line 1285, in request
    self._send_request(method, url, body, headers, encode_chunked)
  File "D:\develop\python\python\lib\http\client.py", line 1331, in _send_request
    self.endheaders(body, encode_chunked=encode_chunked)
  File "D:\develop\python\python\lib\http\client.py", line 1280, in endheaders
    self._send_output(message_body, encode_chunked=encode_chunked)
  File "D:\develop\python\python\lib\http\client.py", line 1040, in _send_output
    self.send(msg)
  File "D:\develop\python\python\lib\http\client.py", line 980, in send
    self.connect()
  File "E:\pythonProject\venv\lib\site-packages\urllib3\connection.py", line 205, in connect
    conn = self._new_conn()
  File "E:\pythonProject\venv\lib\site-packages\urllib3\connection.py", line 179, in _new_conn
    raise ConnectTimeoutError(
urllib3.exceptions.ConnectTimeoutError: (<urllib3.connection.HTTPConnection object at 0x00000240F90338E0>, 'Connection to 92.168.1.102 timed out. (connect timeout=3)')

During handling of the above exception, another exception occurred:

Traceback (most recent call last):
  File "E:\pythonProject\venv\lib\site-packages\requests\adapters.py", line 440, in send
    resp = conn.urlopen(
  File "E:\pythonProject\venv\lib\site-packages\urllib3\connectionpool.py", line 785, in urlopen
    retries = retries.increment(
  File "E:\pythonProject\venv\lib\site-packages\urllib3\util\retry.py", line 592, in increment
    raise MaxRetryError(_pool, url, error or ResponseError(cause))
urllib3.exceptions.MaxRetryError: HTTPConnectionPool(host='92.168.1.102', port=6800): Max retries exceeded with url: / (Caused by ConnectTimeoutError(<urllib3.connection.HTTPConnection object at 0x00000240F90338E0>, 'Connection to 92.168.1.102 timed out. (connect timeout=3)'))

During handling of the above exception, another exception occurred:

Traceback (most recent call last):
  File "E:\pythonProject\venv\lib\site-packages\gerapy\server\core\utils.py", line 562, in wrapper
    result = func(*args, **kwargs)
  File "E:\pythonProject\venv\lib\site-packages\django\views\decorators\csrf.py", line 54, in wrapped_view
    return view_func(*args, **kwargs)
  File "E:\pythonProject\venv\lib\site-packages\django\views\generic\base.py", line 71, in view
    return self.dispatch(request, *args, **kwargs)
  File "E:\pythonProject\venv\lib\site-packages\rest_framework\views.py", line 509, in dispatch
    response = self.handle_exception(exc)
  File "E:\pythonProject\venv\lib\site-packages\rest_framework\views.py", line 469, in handle_exception
    self.raise_uncaught_exception(exc)
  File "E:\pythonProject\venv\lib\site-packages\rest_framework\views.py", line 480, in raise_uncaught_exception
    raise exc
  File "E:\pythonProject\venv\lib\site-packages\rest_framework\views.py", line 506, in dispatch
    response = handler(request, *args, **kwargs)
  File "E:\pythonProject\venv\lib\site-packages\rest_framework\decorators.py", line 50, in handler
    return func(*args, **kwargs)
  File "E:\pythonProject\venv\lib\site-packages\gerapy\server\core\views.py", line 120, in client_status
    requests.get(scrapyd_url(client.ip, client.port), timeout=3)
  File "E:\pythonProject\venv\lib\site-packages\requests\api.py", line 75, in get
    return request('get', url, params=params, **kwargs)
  File "E:\pythonProject\venv\lib\site-packages\requests\api.py", line 61, in request
    return session.request(method=method, url=url, **kwargs)
  File "E:\pythonProject\venv\lib\site-packages\requests\sessions.py", line 529, in request
    resp = self.send(prep, **send_kwargs)
  File "E:\pythonProject\venv\lib\site-packages\requests\sessions.py", line 645, in send
    r = adapter.send(request, **kwargs)
  File "E:\pythonProject\venv\lib\site-packages\requests\adapters.py", line 507, in send
    raise ConnectTimeout(e, request=request)
requests.exceptions.ConnectTimeout: HTTPConnectionPool(host='92.168.1.102', port=6800): Max retries exceeded with url: / (Caused by ConnectTimeoutError(<urllib3.connection.HTTPConnection object at 0x00000240F90338E0>, 'Connection to 92.168.1.102 timed out. (connect timeout=3)'))
ERROR - 2022-09-19 22:23:29,204 - process: 704 - utils.py - gerapy.server.core.utils - 564 - utils - HTTPConnectionPool(host='92.168.1.102', port=6800): Max retries exceeded with url: / (Caused by ConnectTimeoutError(<urllib3.connection.HTTPConnection object at 0x00000240F9240F40>, 'Connection to 92.168.1.102 timed out. (connect timeout=3)'))
Traceback (most recent call last):
  File "E:\pythonProject\venv\lib\site-packages\urllib3\connection.py", line 174, in _new_conn
    conn = connection.create_connection(
  File "E:\pythonProject\venv\lib\site-packages\urllib3\util\connection.py", line 95, in create_connection
    raise err
  File "E:\pythonProject\venv\lib\site-packages\urllib3\util\connection.py", line 85, in create_connection
    sock.connect(sa)
socket.timeout: timed out

During handling of the above exception, another exception occurred:

Traceback (most recent call last):
  File "E:\pythonProject\venv\lib\site-packages\urllib3\connectionpool.py", line 703, in urlopen
    httplib_response = self._make_request(
  File "E:\pythonProject\venv\lib\site-packages\urllib3\connectionpool.py", line 398, in _make_request
    conn.request(method, url, **httplib_request_kw)
  File "E:\pythonProject\venv\lib\site-packages\urllib3\connection.py", line 239, in request
    super(HTTPConnection, self).request(method, url, body=body, headers=headers)
  File "D:\develop\python\python\lib\http\client.py", line 1285, in request
    self._send_request(method, url, body, headers, encode_chunked)
  File "D:\develop\python\python\lib\http\client.py", line 1331, in _send_request
    self.endheaders(body, encode_chunked=encode_chunked)
  File "D:\develop\python\python\lib\http\client.py", line 1280, in endheaders
    self._send_output(message_body, encode_chunked=encode_chunked)
  File "D:\develop\python\python\lib\http\client.py", line 1040, in _send_output
    self.send(msg)
  File "D:\develop\python\python\lib\http\client.py", line 980, in send
    self.connect()
  File "E:\pythonProject\venv\lib\site-packages\urllib3\connection.py", line 205, in connect
    conn = self._new_conn()
  File "E:\pythonProject\venv\lib\site-packages\urllib3\connection.py", line 179, in _new_conn
    raise ConnectTimeoutError(
urllib3.exceptions.ConnectTimeoutError: (<urllib3.connection.HTTPConnection object at 0x00000240F9240F40>, 'Connection to 92.168.1.102 timed out. (connect timeout=3)')

During handling of the above exception, another exception occurred:

Traceback (most recent call last):
  File "E:\pythonProject\venv\lib\site-packages\requests\adapters.py", line 440, in send
    resp = conn.urlopen(
  File "E:\pythonProject\venv\lib\site-packages\urllib3\connectionpool.py", line 785, in urlopen
    retries = retries.increment(
  File "E:\pythonProject\venv\lib\site-packages\urllib3\util\retry.py", line 592, in increment
    raise MaxRetryError(_pool, url, error or ResponseError(cause))
urllib3.exceptions.MaxRetryError: HTTPConnectionPool(host='92.168.1.102', port=6800): Max retries exceeded with url: / (Caused by ConnectTimeoutError(<urllib3.connection.HTTPConnection object at 0x00000240F9240F40>, 'Connection to 92.168.1.102 timed out. (connect timeout=3)'))

During handling of the above exception, another exception occurred:

Traceback (most recent call last):
  File "E:\pythonProject\venv\lib\site-packages\gerapy\server\core\utils.py", line 562, in wrapper
    result = func(*args, **kwargs)
  File "E:\pythonProject\venv\lib\site-packages\django\views\decorators\csrf.py", line 54, in wrapped_view
    return view_func(*args, **kwargs)
  File "E:\pythonProject\venv\lib\site-packages\django\views\generic\base.py", line 71, in view
    return self.dispatch(request, *args, **kwargs)
  File "E:\pythonProject\venv\lib\site-packages\rest_framework\views.py", line 509, in dispatch
    response = self.handle_exception(exc)
  File "E:\pythonProject\venv\lib\site-packages\rest_framework\views.py", line 469, in handle_exception
    self.raise_uncaught_exception(exc)
  File "E:\pythonProject\venv\lib\site-packages\rest_framework\views.py", line 480, in raise_uncaught_exception
    raise exc
  File "E:\pythonProject\venv\lib\site-packages\rest_framework\views.py", line 506, in dispatch
    response = handler(request, *args, **kwargs)
  File "E:\pythonProject\venv\lib\site-packages\rest_framework\decorators.py", line 50, in handler
    return func(*args, **kwargs)
  File "E:\pythonProject\venv\lib\site-packages\gerapy\server\core\views.py", line 120, in client_status
    requests.get(scrapyd_url(client.ip, client.port), timeout=3)
  File "E:\pythonProject\venv\lib\site-packages\requests\api.py", line 75, in get
    return request('get', url, params=params, **kwargs)
  File "E:\pythonProject\venv\lib\site-packages\requests\api.py", line 61, in request
    return session.request(method=method, url=url, **kwargs)
  File "E:\pythonProject\venv\lib\site-packages\requests\sessions.py", line 529, in request
    resp = self.send(prep, **send_kwargs)
  File "E:\pythonProject\venv\lib\site-packages\requests\sessions.py", line 645, in send
    r = adapter.send(request, **kwargs)
  File "E:\pythonProject\venv\lib\site-packages\requests\adapters.py", line 507, in send
    raise ConnectTimeout(e, request=request)
requests.exceptions.ConnectTimeout: HTTPConnectionPool(host='92.168.1.102', port=6800): Max retries exceeded with url: / (Caused by ConnectTimeoutError(<urllib3.connection.HTTPConnection object at 0x00000240F9240F40>, 'Connection to 92.168.1.102 timed out. (connect timeout=3)'))
ERROR - 2022-09-19 22:23:41,502 - process: 704 - utils.py - gerapy.server.core.utils - 564 - utils - HTTPConnectionPool(host='92.168.1.102', port=6800): Max retries exceeded with url: / (Caused by ConnectTimeoutError(<urllib3.connection.HTTPConnection object at 0x00000240F9201B50>, 'Connection to 92.168.1.102 timed out. (connect timeout=3)'))
Traceback (most recent call last):
  File "E:\pythonProject\venv\lib\site-packages\urllib3\connection.py", line 174, in _new_conn
    conn = connection.create_connection(
  File "E:\pythonProject\venv\lib\site-packages\urllib3\util\connection.py", line 95, in create_connection
    raise err
  File "E:\pythonProject\venv\lib\site-packages\urllib3\util\connection.py", line 85, in create_connection
    sock.connect(sa)
socket.timeout: timed out

During handling of the above exception, another exception occurred:

Traceback (most recent call last):
  File "E:\pythonProject\venv\lib\site-packages\urllib3\connectionpool.py", line 703, in urlopen
    httplib_response = self._make_request(
  File "E:\pythonProject\venv\lib\site-packages\urllib3\connectionpool.py", line 398, in _make_request
    conn.request(method, url, **httplib_request_kw)
  File "E:\pythonProject\venv\lib\site-packages\urllib3\connection.py", line 239, in request
    super(HTTPConnection, self).request(method, url, body=body, headers=headers)
  File "D:\develop\python\python\lib\http\client.py", line 1285, in request
    self._send_request(method, url, body, headers, encode_chunked)
  File "D:\develop\python\python\lib\http\client.py", line 1331, in _send_request
    self.endheaders(body, encode_chunked=encode_chunked)
  File "D:\develop\python\python\lib\http\client.py", line 1280, in endheaders
    self._send_output(message_body, encode_chunked=encode_chunked)
  File "D:\develop\python\python\lib\http\client.py", line 1040, in _send_output
    self.send(msg)
  File "D:\develop\python\python\lib\http\client.py", line 980, in send
    self.connect()
  File "E:\pythonProject\venv\lib\site-packages\urllib3\connection.py", line 205, in connect
    conn = self._new_conn()
  File "E:\pythonProject\venv\lib\site-packages\urllib3\connection.py", line 179, in _new_conn
    raise ConnectTimeoutError(
urllib3.exceptions.ConnectTimeoutError: (<urllib3.connection.HTTPConnection object at 0x00000240F9201B50>, 'Connection to 92.168.1.102 timed out. (connect timeout=3)')

During handling of the above exception, another exception occurred:

Traceback (most recent call last):
  File "E:\pythonProject\venv\lib\site-packages\requests\adapters.py", line 440, in send
    resp = conn.urlopen(
  File "E:\pythonProject\venv\lib\site-packages\urllib3\connectionpool.py", line 785, in urlopen
    retries = retries.increment(
  File "E:\pythonProject\venv\lib\site-packages\urllib3\util\retry.py", line 592, in increment
    raise MaxRetryError(_pool, url, error or ResponseError(cause))
urllib3.exceptions.MaxRetryError: HTTPConnectionPool(host='92.168.1.102', port=6800): Max retries exceeded with url: / (Caused by ConnectTimeoutError(<urllib3.connection.HTTPConnection object at 0x00000240F9201B50>, 'Connection to 92.168.1.102 timed out. (connect timeout=3)'))

During handling of the above exception, another exception occurred:

Traceback (most recent call last):
  File "E:\pythonProject\venv\lib\site-packages\gerapy\server\core\utils.py", line 562, in wrapper
    result = func(*args, **kwargs)
  File "E:\pythonProject\venv\lib\site-packages\django\views\decorators\csrf.py", line 54, in wrapped_view
    return view_func(*args, **kwargs)
  File "E:\pythonProject\venv\lib\site-packages\django\views\generic\base.py", line 71, in view
    return self.dispatch(request, *args, **kwargs)
  File "E:\pythonProject\venv\lib\site-packages\rest_framework\views.py", line 509, in dispatch
    response = self.handle_exception(exc)
  File "E:\pythonProject\venv\lib\site-packages\rest_framework\views.py", line 469, in handle_exception
    self.raise_uncaught_exception(exc)
  File "E:\pythonProject\venv\lib\site-packages\rest_framework\views.py", line 480, in raise_uncaught_exception
    raise exc
  File "E:\pythonProject\venv\lib\site-packages\rest_framework\views.py", line 506, in dispatch
    response = handler(request, *args, **kwargs)
  File "E:\pythonProject\venv\lib\site-packages\rest_framework\decorators.py", line 50, in handler
    return func(*args, **kwargs)
  File "E:\pythonProject\venv\lib\site-packages\gerapy\server\core\views.py", line 120, in client_status
    requests.get(scrapyd_url(client.ip, client.port), timeout=3)
  File "E:\pythonProject\venv\lib\site-packages\requests\api.py", line 75, in get
    return request('get', url, params=params, **kwargs)
  File "E:\pythonProject\venv\lib\site-packages\requests\api.py", line 61, in request
    return session.request(method=method, url=url, **kwargs)
  File "E:\pythonProject\venv\lib\site-packages\requests\sessions.py", line 529, in request
    resp = self.send(prep, **send_kwargs)
  File "E:\pythonProject\venv\lib\site-packages\requests\sessions.py", line 645, in send
    r = adapter.send(request, **kwargs)
  File "E:\pythonProject\venv\lib\site-packages\requests\adapters.py", line 507, in send
    raise ConnectTimeout(e, request=request)
requests.exceptions.ConnectTimeout: HTTPConnectionPool(host='92.168.1.102', port=6800): Max retries exceeded with url: / (Caused by ConnectTimeoutError(<urllib3.connection.HTTPConnection object at 0x00000240F9201B50>, 'Connection to 92.168.1.102 timed out. (connect timeout=3)'))
ERROR - 2022-09-19 22:23:53,658 - process: 704 - utils.py - gerapy.server.core.utils - 564 - utils - Scrapy 2.6.1 - no active project

Unknown command: list

Use "scrapy" to see available commands
Traceback (most recent call last):
  File "E:\pythonProject\venv\lib\site-packages\gerapy\server\core\utils.py", line 562, in wrapper
    result = func(*args, **kwargs)
  File "E:\pythonProject\venv\lib\site-packages\django\views\decorators\csrf.py", line 54, in wrapped_view
    return view_func(*args, **kwargs)
  File "E:\pythonProject\venv\lib\site-packages\django\views\generic\base.py", line 71, in view
    return self.dispatch(request, *args, **kwargs)
  File "E:\pythonProject\venv\lib\site-packages\rest_framework\views.py", line 509, in dispatch
    response = self.handle_exception(exc)
  File "E:\pythonProject\venv\lib\site-packages\rest_framework\views.py", line 469, in handle_exception
    self.raise_uncaught_exception(exc)
  File "E:\pythonProject\venv\lib\site-packages\rest_framework\views.py", line 480, in raise_uncaught_exception
    raise exc
  File "E:\pythonProject\venv\lib\site-packages\rest_framework\views.py", line 506, in dispatch
    response = handler(request, *args, **kwargs)
  File "E:\pythonProject\venv\lib\site-packages\rest_framework\decorators.py", line 50, in handler
    return func(*args, **kwargs)
  File "E:\pythonProject\venv\lib\site-packages\gerapy\server\core\views.py", line 189, in spider_list
    spiders = scrapyd.list_spiders(project_name)
  File "E:\pythonProject\venv\lib\site-packages\scrapyd_api\wrapper.py", line 158, in list_spiders
    json = self.client.get(url, params=params, timeout=self.timeout)
  File "E:\pythonProject\venv\lib\site-packages\requests\sessions.py", line 542, in get
    return self.request('GET', url, **kwargs)
  File "E:\pythonProject\venv\lib\site-packages\scrapyd_api\client.py", line 38, in request
    return self._handle_response(response)
  File "E:\pythonProject\venv\lib\site-packages\scrapyd_api\client.py", line 34, in _handle_response
    raise ScrapydResponseError(json['message'])
scrapyd_api.exceptions.ScrapydResponseError: Scrapy 2.6.1 - no active project

Unknown command: list

Use "scrapy" to see available commands

ERROR - 2022-09-19 22:23:55,976 - process: 704 - utils.py - gerapy.server.core.utils - 564 - utils - HTTPConnectionPool(host='92.168.1.102', port=6800): Max retries exceeded with url: /listprojects.json (Caused by NewConnectionError('<urllib3.connection.HTTPConnection object at 0x00000240F90E0790>: Failed to establish a new connection: [WinError 10060] 由于连接方在一段时间后没有正确答复或连接的主机没有反应，连接尝试失败。'))
Traceback (most recent call last):
  File "E:\pythonProject\venv\lib\site-packages\urllib3\connection.py", line 174, in _new_conn
    conn = connection.create_connection(
  File "E:\pythonProject\venv\lib\site-packages\urllib3\util\connection.py", line 95, in create_connection
    raise err
  File "E:\pythonProject\venv\lib\site-packages\urllib3\util\connection.py", line 85, in create_connection
    sock.connect(sa)
TimeoutError: [WinError 10060] 由于连接方在一段时间后没有正确答复或连接的主机没有反应，连接尝试失败。

During handling of the above exception, another exception occurred:

Traceback (most recent call last):
  File "E:\pythonProject\venv\lib\site-packages\urllib3\connectionpool.py", line 703, in urlopen
    httplib_response = self._make_request(
  File "E:\pythonProject\venv\lib\site-packages\urllib3\connectionpool.py", line 398, in _make_request
    conn.request(method, url, **httplib_request_kw)
  File "E:\pythonProject\venv\lib\site-packages\urllib3\connection.py", line 239, in request
    super(HTTPConnection, self).request(method, url, body=body, headers=headers)
  File "D:\develop\python\python\lib\http\client.py", line 1285, in request
    self._send_request(method, url, body, headers, encode_chunked)
  File "D:\develop\python\python\lib\http\client.py", line 1331, in _send_request
    self.endheaders(body, encode_chunked=encode_chunked)
  File "D:\develop\python\python\lib\http\client.py", line 1280, in endheaders
    self._send_output(message_body, encode_chunked=encode_chunked)
  File "D:\develop\python\python\lib\http\client.py", line 1040, in _send_output
    self.send(msg)
  File "D:\develop\python\python\lib\http\client.py", line 980, in send
    self.connect()
  File "E:\pythonProject\venv\lib\site-packages\urllib3\connection.py", line 205, in connect
    conn = self._new_conn()
  File "E:\pythonProject\venv\lib\site-packages\urllib3\connection.py", line 186, in _new_conn
    raise NewConnectionError(
urllib3.exceptions.NewConnectionError: <urllib3.connection.HTTPConnection object at 0x00000240F90E0790>: Failed to establish a new connection: [WinError 10060] 由于连接方在一段时间后没有正确答复或连接的主机没有反应，连接尝试失败。

During handling of the above exception, another exception occurred:

Traceback (most recent call last):
  File "E:\pythonProject\venv\lib\site-packages\requests\adapters.py", line 440, in send
    resp = conn.urlopen(
  File "E:\pythonProject\venv\lib\site-packages\urllib3\connectionpool.py", line 785, in urlopen
    retries = retries.increment(
  File "E:\pythonProject\venv\lib\site-packages\urllib3\util\retry.py", line 592, in increment
    raise MaxRetryError(_pool, url, error or ResponseError(cause))
urllib3.exceptions.MaxRetryError: HTTPConnectionPool(host='92.168.1.102', port=6800): Max retries exceeded with url: /listprojects.json (Caused by NewConnectionError('<urllib3.connection.HTTPConnection object at 0x00000240F90E0790>: Failed to establish a new connection: [WinError 10060] 由于连接方在一段时间后没有正确答复或连接的主机没有反应，连接尝试失败。'))

During handling of the above exception, another exception occurred:

Traceback (most recent call last):
  File "E:\pythonProject\venv\lib\site-packages\gerapy\server\core\utils.py", line 562, in wrapper
    result = func(*args, **kwargs)
  File "E:\pythonProject\venv\lib\site-packages\django\views\decorators\csrf.py", line 54, in wrapped_view
    return view_func(*args, **kwargs)
  File "E:\pythonProject\venv\lib\site-packages\django\views\generic\base.py", line 71, in view
    return self.dispatch(request, *args, **kwargs)
  File "E:\pythonProject\venv\lib\site-packages\rest_framework\views.py", line 509, in dispatch
    response = self.handle_exception(exc)
  File "E:\pythonProject\venv\lib\site-packages\rest_framework\views.py", line 469, in handle_exception
    self.raise_uncaught_exception(exc)
  File "E:\pythonProject\venv\lib\site-packages\rest_framework\views.py", line 480, in raise_uncaught_exception
    raise exc
  File "E:\pythonProject\venv\lib\site-packages\rest_framework\views.py", line 506, in dispatch
    response = handler(request, *args, **kwargs)
  File "E:\pythonProject\venv\lib\site-packages\rest_framework\decorators.py", line 50, in handler
    return func(*args, **kwargs)
  File "E:\pythonProject\venv\lib\site-packages\gerapy\server\core\views.py", line 227, in project_list
    projects = scrapyd.list_projects()
  File "E:\pythonProject\venv\lib\site-packages\scrapyd_api\wrapper.py", line 148, in list_projects
    json = self.client.get(url, timeout=self.timeout)
  File "E:\pythonProject\venv\lib\site-packages\requests\sessions.py", line 542, in get
    return self.request('GET', url, **kwargs)
  File "E:\pythonProject\venv\lib\site-packages\scrapyd_api\client.py", line 37, in request
    response = super(Client, self).request(*args, **kwargs)
  File "E:\pythonProject\venv\lib\site-packages\requests\sessions.py", line 529, in request
    resp = self.send(prep, **send_kwargs)
  File "E:\pythonProject\venv\lib\site-packages\requests\sessions.py", line 645, in send
    r = adapter.send(request, **kwargs)
  File "E:\pythonProject\venv\lib\site-packages\requests\adapters.py", line 519, in send
    raise ConnectionError(e, request=request)
requests.exceptions.ConnectionError: HTTPConnectionPool(host='92.168.1.102', port=6800): Max retries exceeded with url: /listprojects.json (Caused by NewConnectionError('<urllib3.connection.HTTPConnection object at 0x00000240F90E0790>: Failed to establish a new connection: [WinError 10060] 由于连接方在一段时间后没有正确答复或连接的主机没有反应，连接尝试失败。'))
INFO - 2022-09-19 22:24:15,394 - process: 704 - build.py - gerapy.server.core.build - 24 - build - successfully build project pro to egg file E:\pythonProject\yamaxun\gerapy\projects\pro\pro-1.0-py3.9.egg
ERROR - 2022-09-19 22:24:21,747 - process: 704 - utils.py - gerapy.server.core.utils - 564 - utils - /usr/local/lib/python3.9/dist-packages/scrapy/utils/project.py:81: ScrapyDeprecationWarning: Use of environment variables prefixed with SCRAPY_ to override settings is deprecated. The following environment variables are currently defined: EGG_VERSION
  warnings.warn(
Traceback (most recent call last):
  File "/usr/lib/python3.9/runpy.py", line 197, in _run_module_as_main
    return _run_code(code, main_globals, None,
  File "/usr/lib/python3.9/runpy.py", line 87, in _run_code
    exec(code, run_globals)
  File "/usr/local/lib/python3.9/dist-packages/scrapyd/runner.py", line 46, in <module>
    main()
  File "/usr/local/lib/python3.9/dist-packages/scrapyd/runner.py", line 43, in main
    execute()
  File "/usr/local/lib/python3.9/dist-packages/scrapy/cmdline.py", line 144, in execute
    cmd.crawler_process = CrawlerProcess(settings)
  File "/usr/local/lib/python3.9/dist-packages/scrapy/crawler.py", line 290, in __init__
    super().__init__(settings)
  File "/usr/local/lib/python3.9/dist-packages/scrapy/crawler.py", line 167, in __init__
    self.spider_loader = self._get_spider_loader(settings)
  File "/usr/local/lib/python3.9/dist-packages/scrapy/crawler.py", line 161, in _get_spider_loader
    return loader_cls.from_settings(settings.frozencopy())
  File "/usr/local/lib/python3.9/dist-packages/scrapy/spiderloader.py", line 67, in from_settings
    return cls(settings)
  File "/usr/local/lib/python3.9/dist-packages/scrapy/spiderloader.py", line 24, in __init__
    self._load_all_spiders()
  File "/usr/local/lib/python3.9/dist-packages/scrapy/spiderloader.py", line 51, in _load_all_spiders
    for module in walk_modules(name):
  File "/usr/local/lib/python3.9/dist-packages/scrapy/utils/misc.py", line 88, in walk_modules
    submod = import_module(fullpath)
  File "/usr/lib/python3.9/importlib/__init__.py", line 127, in import_module
    return _bootstrap._gcd_import(name[level:], package, level)
  File "<frozen importlib._bootstrap>", line 1030, in _gcd_import
  File "<frozen importlib._bootstrap>", line 1007, in _find_and_load
  File "<frozen importlib._bootstrap>", line 986, in _find_and_load_unlocked
  File "<frozen importlib._bootstrap>", line 664, in _load_unlocked
  File "<frozen importlib._bootstrap>", line 627, in _load_backward_compatible
  File "<frozen zipimport>", line 259, in load_module
  File "/tmp/pro-1663597460-cu5uy03b.egg/yamaxun/spiders/aibabab.py", line 6, in <module>
ModuleNotFoundError: No module named 'numpy'
Traceback (most recent call last):
  File "E:\pythonProject\venv\lib\site-packages\gerapy\server\core\utils.py", line 562, in wrapper
    result = func(*args, **kwargs)
  File "E:\pythonProject\venv\lib\site-packages\django\views\decorators\csrf.py", line 54, in wrapped_view
    return view_func(*args, **kwargs)
  File "E:\pythonProject\venv\lib\site-packages\django\views\generic\base.py", line 71, in view
    return self.dispatch(request, *args, **kwargs)
  File "E:\pythonProject\venv\lib\site-packages\rest_framework\views.py", line 509, in dispatch
    response = self.handle_exception(exc)
  File "E:\pythonProject\venv\lib\site-packages\rest_framework\views.py", line 469, in handle_exception
    self.raise_uncaught_exception(exc)
  File "E:\pythonProject\venv\lib\site-packages\rest_framework\views.py", line 480, in raise_uncaught_exception
    raise exc
  File "E:\pythonProject\venv\lib\site-packages\rest_framework\views.py", line 506, in dispatch
    response = handler(request, *args, **kwargs)
  File "E:\pythonProject\venv\lib\site-packages\rest_framework\decorators.py", line 50, in handler
    return func(*args, **kwargs)
  File "E:\pythonProject\venv\lib\site-packages\gerapy\server\core\views.py", line 461, in project_deploy
    scrapyd.add_version(project_name, int(time.time()), egg_file.read())
  File "E:\pythonProject\venv\lib\site-packages\scrapyd_api\wrapper.py", line 76, in add_version
    json = self.client.post(url, data=data, files=files,
  File "E:\pythonProject\venv\lib\site-packages\requests\sessions.py", line 577, in post
    return self.request('POST', url, data=data, json=json, **kwargs)
  File "E:\pythonProject\venv\lib\site-packages\scrapyd_api\client.py", line 38, in request
    return self._handle_response(response)
  File "E:\pythonProject\venv\lib\site-packages\scrapyd_api\client.py", line 34, in _handle_response
    raise ScrapydResponseError(json['message'])
scrapyd_api.exceptions.ScrapydResponseError: /usr/local/lib/python3.9/dist-packages/scrapy/utils/project.py:81: ScrapyDeprecationWarning: Use of environment variables prefixed with SCRAPY_ to override settings is deprecated. The following environment variables are currently defined: EGG_VERSION
  warnings.warn(
Traceback (most recent call last):
  File "/usr/lib/python3.9/runpy.py", line 197, in _run_module_as_main
    return _run_code(code, main_globals, None,
  File "/usr/lib/python3.9/runpy.py", line 87, in _run_code
    exec(code, run_globals)
  File "/usr/local/lib/python3.9/dist-packages/scrapyd/runner.py", line 46, in <module>
    main()
  File "/usr/local/lib/python3.9/dist-packages/scrapyd/runner.py", line 43, in main
    execute()
  File "/usr/local/lib/python3.9/dist-packages/scrapy/cmdline.py", line 144, in execute
    cmd.crawler_process = CrawlerProcess(settings)
  File "/usr/local/lib/python3.9/dist-packages/scrapy/crawler.py", line 290, in __init__
    super().__init__(settings)
  File "/usr/local/lib/python3.9/dist-packages/scrapy/crawler.py", line 167, in __init__
    self.spider_loader = self._get_spider_loader(settings)
  File "/usr/local/lib/python3.9/dist-packages/scrapy/crawler.py", line 161, in _get_spider_loader
    return loader_cls.from_settings(settings.frozencopy())
  File "/usr/local/lib/python3.9/dist-packages/scrapy/spiderloader.py", line 67, in from_settings
    return cls(settings)
  File "/usr/local/lib/python3.9/dist-packages/scrapy/spiderloader.py", line 24, in __init__
    self._load_all_spiders()
  File "/usr/local/lib/python3.9/dist-packages/scrapy/spiderloader.py", line 51, in _load_all_spiders
    for module in walk_modules(name):
  File "/usr/local/lib/python3.9/dist-packages/scrapy/utils/misc.py", line 88, in walk_modules
    submod = import_module(fullpath)
  File "/usr/lib/python3.9/importlib/__init__.py", line 127, in import_module
    return _bootstrap._gcd_import(name[level:], package, level)
  File "<frozen importlib._bootstrap>", line 1030, in _gcd_import
  File "<frozen importlib._bootstrap>", line 1007, in _find_and_load
  File "<frozen importlib._bootstrap>", line 986, in _find_and_load_unlocked
  File "<frozen importlib._bootstrap>", line 664, in _load_unlocked
  File "<frozen importlib._bootstrap>", line 627, in _load_backward_compatible
  File "<frozen zipimport>", line 259, in load_module
  File "/tmp/pro-1663597460-cu5uy03b.egg/yamaxun/spiders/aibabab.py", line 6, in <module>
ModuleNotFoundError: No module named 'numpy'

ERROR - 2022-09-19 22:24:32,419 - process: 704 - utils.py - gerapy.server.core.utils - 564 - utils - /usr/local/lib/python3.9/dist-packages/scrapy/utils/project.py:81: ScrapyDeprecationWarning: Use of environment variables prefixed with SCRAPY_ to override settings is deprecated. The following environment variables are currently defined: EGG_VERSION
  warnings.warn(
Traceback (most recent call last):
  File "/usr/lib/python3.9/runpy.py", line 197, in _run_module_as_main
    return _run_code(code, main_globals, None,
  File "/usr/lib/python3.9/runpy.py", line 87, in _run_code
    exec(code, run_globals)
  File "/usr/local/lib/python3.9/dist-packages/scrapyd/runner.py", line 46, in <module>
    main()
  File "/usr/local/lib/python3.9/dist-packages/scrapyd/runner.py", line 43, in main
    execute()
  File "/usr/local/lib/python3.9/dist-packages/scrapy/cmdline.py", line 144, in execute
    cmd.crawler_process = CrawlerProcess(settings)
  File "/usr/local/lib/python3.9/dist-packages/scrapy/crawler.py", line 290, in __init__
    super().__init__(settings)
  File "/usr/local/lib/python3.9/dist-packages/scrapy/crawler.py", line 167, in __init__
    self.spider_loader = self._get_spider_loader(settings)
  File "/usr/local/lib/python3.9/dist-packages/scrapy/crawler.py", line 161, in _get_spider_loader
    return loader_cls.from_settings(settings.frozencopy())
  File "/usr/local/lib/python3.9/dist-packages/scrapy/spiderloader.py", line 67, in from_settings
    return cls(settings)
  File "/usr/local/lib/python3.9/dist-packages/scrapy/spiderloader.py", line 24, in __init__
    self._load_all_spiders()
  File "/usr/local/lib/python3.9/dist-packages/scrapy/spiderloader.py", line 51, in _load_all_spiders
    for module in walk_modules(name):
  File "/usr/local/lib/python3.9/dist-packages/scrapy/utils/misc.py", line 88, in walk_modules
    submod = import_module(fullpath)
  File "/usr/lib/python3.9/importlib/__init__.py", line 127, in import_module
    return _bootstrap._gcd_import(name[level:], package, level)
  File "<frozen importlib._bootstrap>", line 1030, in _gcd_import
  File "<frozen importlib._bootstrap>", line 1007, in _find_and_load
  File "<frozen importlib._bootstrap>", line 986, in _find_and_load_unlocked
  File "<frozen importlib._bootstrap>", line 664, in _load_unlocked
  File "<frozen importlib._bootstrap>", line 627, in _load_backward_compatible
  File "<frozen zipimport>", line 259, in load_module
  File "/tmp/pro-1663597471-o0o7e_d7.egg/yamaxun/spiders/aibabab.py", line 6, in <module>
ModuleNotFoundError: No module named 'numpy'
Traceback (most recent call last):
  File "E:\pythonProject\venv\lib\site-packages\gerapy\server\core\utils.py", line 562, in wrapper
    result = func(*args, **kwargs)
  File "E:\pythonProject\venv\lib\site-packages\django\views\decorators\csrf.py", line 54, in wrapped_view
    return view_func(*args, **kwargs)
  File "E:\pythonProject\venv\lib\site-packages\django\views\generic\base.py", line 71, in view
    return self.dispatch(request, *args, **kwargs)
  File "E:\pythonProject\venv\lib\site-packages\rest_framework\views.py", line 509, in dispatch
    response = self.handle_exception(exc)
  File "E:\pythonProject\venv\lib\site-packages\rest_framework\views.py", line 469, in handle_exception
    self.raise_uncaught_exception(exc)
  File "E:\pythonProject\venv\lib\site-packages\rest_framework\views.py", line 480, in raise_uncaught_exception
    raise exc
  File "E:\pythonProject\venv\lib\site-packages\rest_framework\views.py", line 506, in dispatch
    response = handler(request, *args, **kwargs)
  File "E:\pythonProject\venv\lib\site-packages\rest_framework\decorators.py", line 50, in handler
    return func(*args, **kwargs)
  File "E:\pythonProject\venv\lib\site-packages\gerapy\server\core\views.py", line 461, in project_deploy
    scrapyd.add_version(project_name, int(time.time()), egg_file.read())
  File "E:\pythonProject\venv\lib\site-packages\scrapyd_api\wrapper.py", line 76, in add_version
    json = self.client.post(url, data=data, files=files,
  File "E:\pythonProject\venv\lib\site-packages\requests\sessions.py", line 577, in post
    return self.request('POST', url, data=data, json=json, **kwargs)
  File "E:\pythonProject\venv\lib\site-packages\scrapyd_api\client.py", line 38, in request
    return self._handle_response(response)
  File "E:\pythonProject\venv\lib\site-packages\scrapyd_api\client.py", line 34, in _handle_response
    raise ScrapydResponseError(json['message'])
scrapyd_api.exceptions.ScrapydResponseError: /usr/local/lib/python3.9/dist-packages/scrapy/utils/project.py:81: ScrapyDeprecationWarning: Use of environment variables prefixed with SCRAPY_ to override settings is deprecated. The following environment variables are currently defined: EGG_VERSION
  warnings.warn(
Traceback (most recent call last):
  File "/usr/lib/python3.9/runpy.py", line 197, in _run_module_as_main
    return _run_code(code, main_globals, None,
  File "/usr/lib/python3.9/runpy.py", line 87, in _run_code
    exec(code, run_globals)
  File "/usr/local/lib/python3.9/dist-packages/scrapyd/runner.py", line 46, in <module>
    main()
  File "/usr/local/lib/python3.9/dist-packages/scrapyd/runner.py", line 43, in main
    execute()
  File "/usr/local/lib/python3.9/dist-packages/scrapy/cmdline.py", line 144, in execute
    cmd.crawler_process = CrawlerProcess(settings)
  File "/usr/local/lib/python3.9/dist-packages/scrapy/crawler.py", line 290, in __init__
    super().__init__(settings)
  File "/usr/local/lib/python3.9/dist-packages/scrapy/crawler.py", line 167, in __init__
    self.spider_loader = self._get_spider_loader(settings)
  File "/usr/local/lib/python3.9/dist-packages/scrapy/crawler.py", line 161, in _get_spider_loader
    return loader_cls.from_settings(settings.frozencopy())
  File "/usr/local/lib/python3.9/dist-packages/scrapy/spiderloader.py", line 67, in from_settings
    return cls(settings)
  File "/usr/local/lib/python3.9/dist-packages/scrapy/spiderloader.py", line 24, in __init__
    self._load_all_spiders()
  File "/usr/local/lib/python3.9/dist-packages/scrapy/spiderloader.py", line 51, in _load_all_spiders
    for module in walk_modules(name):
  File "/usr/local/lib/python3.9/dist-packages/scrapy/utils/misc.py", line 88, in walk_modules
    submod = import_module(fullpath)
  File "/usr/lib/python3.9/importlib/__init__.py", line 127, in import_module
    return _bootstrap._gcd_import(name[level:], package, level)
  File "<frozen importlib._bootstrap>", line 1030, in _gcd_import
  File "<frozen importlib._bootstrap>", line 1007, in _find_and_load
  File "<frozen importlib._bootstrap>", line 986, in _find_and_load_unlocked
  File "<frozen importlib._bootstrap>", line 664, in _load_unlocked
  File "<frozen importlib._bootstrap>", line 627, in _load_backward_compatible
  File "<frozen zipimport>", line 259, in load_module
  File "/tmp/pro-1663597471-o0o7e_d7.egg/yamaxun/spiders/aibabab.py", line 6, in <module>
ModuleNotFoundError: No module named 'numpy'

ERROR - 2022-09-19 22:24:35,634 - process: 704 - utils.py - gerapy.server.core.utils - 564 - utils - /usr/local/lib/python3.9/dist-packages/scrapy/utils/project.py:81: ScrapyDeprecationWarning: Use of environment variables prefixed with SCRAPY_ to override settings is deprecated. The following environment variables are currently defined: EGG_VERSION
  warnings.warn(
Traceback (most recent call last):
  File "/usr/lib/python3.9/runpy.py", line 197, in _run_module_as_main
    return _run_code(code, main_globals, None,
  File "/usr/lib/python3.9/runpy.py", line 87, in _run_code
    exec(code, run_globals)
  File "/usr/local/lib/python3.9/dist-packages/scrapyd/runner.py", line 46, in <module>
    main()
  File "/usr/local/lib/python3.9/dist-packages/scrapyd/runner.py", line 43, in main
    execute()
  File "/usr/local/lib/python3.9/dist-packages/scrapy/cmdline.py", line 144, in execute
    cmd.crawler_process = CrawlerProcess(settings)
  File "/usr/local/lib/python3.9/dist-packages/scrapy/crawler.py", line 290, in __init__
    super().__init__(settings)
  File "/usr/local/lib/python3.9/dist-packages/scrapy/crawler.py", line 167, in __init__
    self.spider_loader = self._get_spider_loader(settings)
  File "/usr/local/lib/python3.9/dist-packages/scrapy/crawler.py", line 161, in _get_spider_loader
    return loader_cls.from_settings(settings.frozencopy())
  File "/usr/local/lib/python3.9/dist-packages/scrapy/spiderloader.py", line 67, in from_settings
    return cls(settings)
  File "/usr/local/lib/python3.9/dist-packages/scrapy/spiderloader.py", line 24, in __init__
    self._load_all_spiders()
  File "/usr/local/lib/python3.9/dist-packages/scrapy/spiderloader.py", line 51, in _load_all_spiders
    for module in walk_modules(name):
  File "/usr/local/lib/python3.9/dist-packages/scrapy/utils/misc.py", line 88, in walk_modules
    submod = import_module(fullpath)
  File "/usr/lib/python3.9/importlib/__init__.py", line 127, in import_module
    return _bootstrap._gcd_import(name[level:], package, level)
  File "<frozen importlib._bootstrap>", line 1030, in _gcd_import
  File "<frozen importlib._bootstrap>", line 1007, in _find_and_load
  File "<frozen importlib._bootstrap>", line 986, in _find_and_load_unlocked
  File "<frozen importlib._bootstrap>", line 664, in _load_unlocked
  File "<frozen importlib._bootstrap>", line 627, in _load_backward_compatible
  File "<frozen zipimport>", line 259, in load_module
  File "/tmp/pro-1663597475-959y0kft.egg/yamaxun/spiders/aibabab.py", line 6, in <module>
ModuleNotFoundError: No module named 'numpy'
Traceback (most recent call last):
  File "E:\pythonProject\venv\lib\site-packages\gerapy\server\core\utils.py", line 562, in wrapper
    result = func(*args, **kwargs)
  File "E:\pythonProject\venv\lib\site-packages\django\views\decorators\csrf.py", line 54, in wrapped_view
    return view_func(*args, **kwargs)
  File "E:\pythonProject\venv\lib\site-packages\django\views\generic\base.py", line 71, in view
    return self.dispatch(request, *args, **kwargs)
  File "E:\pythonProject\venv\lib\site-packages\rest_framework\views.py", line 509, in dispatch
    response = self.handle_exception(exc)
  File "E:\pythonProject\venv\lib\site-packages\rest_framework\views.py", line 469, in handle_exception
    self.raise_uncaught_exception(exc)
  File "E:\pythonProject\venv\lib\site-packages\rest_framework\views.py", line 480, in raise_uncaught_exception
    raise exc
  File "E:\pythonProject\venv\lib\site-packages\rest_framework\views.py", line 506, in dispatch
    response = handler(request, *args, **kwargs)
  File "E:\pythonProject\venv\lib\site-packages\rest_framework\decorators.py", line 50, in handler
    return func(*args, **kwargs)
  File "E:\pythonProject\venv\lib\site-packages\gerapy\server\core\views.py", line 461, in project_deploy
    scrapyd.add_version(project_name, int(time.time()), egg_file.read())
  File "E:\pythonProject\venv\lib\site-packages\scrapyd_api\wrapper.py", line 76, in add_version
    json = self.client.post(url, data=data, files=files,
  File "E:\pythonProject\venv\lib\site-packages\requests\sessions.py", line 577, in post
    return self.request('POST', url, data=data, json=json, **kwargs)
  File "E:\pythonProject\venv\lib\site-packages\scrapyd_api\client.py", line 38, in request
    return self._handle_response(response)
  File "E:\pythonProject\venv\lib\site-packages\scrapyd_api\client.py", line 34, in _handle_response
    raise ScrapydResponseError(json['message'])
scrapyd_api.exceptions.ScrapydResponseError: /usr/local/lib/python3.9/dist-packages/scrapy/utils/project.py:81: ScrapyDeprecationWarning: Use of environment variables prefixed with SCRAPY_ to override settings is deprecated. The following environment variables are currently defined: EGG_VERSION
  warnings.warn(
Traceback (most recent call last):
  File "/usr/lib/python3.9/runpy.py", line 197, in _run_module_as_main
    return _run_code(code, main_globals, None,
  File "/usr/lib/python3.9/runpy.py", line 87, in _run_code
    exec(code, run_globals)
  File "/usr/local/lib/python3.9/dist-packages/scrapyd/runner.py", line 46, in <module>
    main()
  File "/usr/local/lib/python3.9/dist-packages/scrapyd/runner.py", line 43, in main
    execute()
  File "/usr/local/lib/python3.9/dist-packages/scrapy/cmdline.py", line 144, in execute
    cmd.crawler_process = CrawlerProcess(settings)
  File "/usr/local/lib/python3.9/dist-packages/scrapy/crawler.py", line 290, in __init__
    super().__init__(settings)
  File "/usr/local/lib/python3.9/dist-packages/scrapy/crawler.py", line 167, in __init__
    self.spider_loader = self._get_spider_loader(settings)
  File "/usr/local/lib/python3.9/dist-packages/scrapy/crawler.py", line 161, in _get_spider_loader
    return loader_cls.from_settings(settings.frozencopy())
  File "/usr/local/lib/python3.9/dist-packages/scrapy/spiderloader.py", line 67, in from_settings
    return cls(settings)
  File "/usr/local/lib/python3.9/dist-packages/scrapy/spiderloader.py", line 24, in __init__
    self._load_all_spiders()
  File "/usr/local/lib/python3.9/dist-packages/scrapy/spiderloader.py", line 51, in _load_all_spiders
    for module in walk_modules(name):
  File "/usr/local/lib/python3.9/dist-packages/scrapy/utils/misc.py", line 88, in walk_modules
    submod = import_module(fullpath)
  File "/usr/lib/python3.9/importlib/__init__.py", line 127, in import_module
    return _bootstrap._gcd_import(name[level:], package, level)
  File "<frozen importlib._bootstrap>", line 1030, in _gcd_import
  File "<frozen importlib._bootstrap>", line 1007, in _find_and_load
  File "<frozen importlib._bootstrap>", line 986, in _find_and_load_unlocked
  File "<frozen importlib._bootstrap>", line 664, in _load_unlocked
  File "<frozen importlib._bootstrap>", line 627, in _load_backward_compatible
  File "<frozen zipimport>", line 259, in load_module
  File "/tmp/pro-1663597475-959y0kft.egg/yamaxun/spiders/aibabab.py", line 6, in <module>
ModuleNotFoundError: No module named 'numpy'

ERROR - 2022-09-19 22:32:36,832 - process: 704 - utils.py - gerapy.server.core.utils - 564 - utils - HTTPConnectionPool(host='192.168.1.103', port=6800): Max retries exceeded with url: / (Caused by ConnectTimeoutError(<urllib3.connection.HTTPConnection object at 0x00000240F91EEE80>, 'Connection to 192.168.1.103 timed out. (connect timeout=3)'))
Traceback (most recent call last):
  File "E:\pythonProject\venv\lib\site-packages\urllib3\connection.py", line 174, in _new_conn
    conn = connection.create_connection(
  File "E:\pythonProject\venv\lib\site-packages\urllib3\util\connection.py", line 95, in create_connection
    raise err
  File "E:\pythonProject\venv\lib\site-packages\urllib3\util\connection.py", line 85, in create_connection
    sock.connect(sa)
socket.timeout: timed out

During handling of the above exception, another exception occurred:

Traceback (most recent call last):
  File "E:\pythonProject\venv\lib\site-packages\urllib3\connectionpool.py", line 703, in urlopen
    httplib_response = self._make_request(
  File "E:\pythonProject\venv\lib\site-packages\urllib3\connectionpool.py", line 398, in _make_request
    conn.request(method, url, **httplib_request_kw)
  File "E:\pythonProject\venv\lib\site-packages\urllib3\connection.py", line 239, in request
    super(HTTPConnection, self).request(method, url, body=body, headers=headers)
  File "D:\develop\python\python\lib\http\client.py", line 1285, in request
    self._send_request(method, url, body, headers, encode_chunked)
  File "D:\develop\python\python\lib\http\client.py", line 1331, in _send_request
    self.endheaders(body, encode_chunked=encode_chunked)
  File "D:\develop\python\python\lib\http\client.py", line 1280, in endheaders
    self._send_output(message_body, encode_chunked=encode_chunked)
  File "D:\develop\python\python\lib\http\client.py", line 1040, in _send_output
    self.send(msg)
  File "D:\develop\python\python\lib\http\client.py", line 980, in send
    self.connect()
  File "E:\pythonProject\venv\lib\site-packages\urllib3\connection.py", line 205, in connect
    conn = self._new_conn()
  File "E:\pythonProject\venv\lib\site-packages\urllib3\connection.py", line 179, in _new_conn
    raise ConnectTimeoutError(
urllib3.exceptions.ConnectTimeoutError: (<urllib3.connection.HTTPConnection object at 0x00000240F91EEE80>, 'Connection to 192.168.1.103 timed out. (connect timeout=3)')

During handling of the above exception, another exception occurred:

Traceback (most recent call last):
  File "E:\pythonProject\venv\lib\site-packages\requests\adapters.py", line 440, in send
    resp = conn.urlopen(
  File "E:\pythonProject\venv\lib\site-packages\urllib3\connectionpool.py", line 785, in urlopen
    retries = retries.increment(
  File "E:\pythonProject\venv\lib\site-packages\urllib3\util\retry.py", line 592, in increment
    raise MaxRetryError(_pool, url, error or ResponseError(cause))
urllib3.exceptions.MaxRetryError: HTTPConnectionPool(host='192.168.1.103', port=6800): Max retries exceeded with url: / (Caused by ConnectTimeoutError(<urllib3.connection.HTTPConnection object at 0x00000240F91EEE80>, 'Connection to 192.168.1.103 timed out. (connect timeout=3)'))

During handling of the above exception, another exception occurred:

Traceback (most recent call last):
  File "E:\pythonProject\venv\lib\site-packages\gerapy\server\core\utils.py", line 562, in wrapper
    result = func(*args, **kwargs)
  File "E:\pythonProject\venv\lib\site-packages\django\views\decorators\csrf.py", line 54, in wrapped_view
    return view_func(*args, **kwargs)
  File "E:\pythonProject\venv\lib\site-packages\django\views\generic\base.py", line 71, in view
    return self.dispatch(request, *args, **kwargs)
  File "E:\pythonProject\venv\lib\site-packages\rest_framework\views.py", line 509, in dispatch
    response = self.handle_exception(exc)
  File "E:\pythonProject\venv\lib\site-packages\rest_framework\views.py", line 469, in handle_exception
    self.raise_uncaught_exception(exc)
  File "E:\pythonProject\venv\lib\site-packages\rest_framework\views.py", line 480, in raise_uncaught_exception
    raise exc
  File "E:\pythonProject\venv\lib\site-packages\rest_framework\views.py", line 506, in dispatch
    response = handler(request, *args, **kwargs)
  File "E:\pythonProject\venv\lib\site-packages\rest_framework\decorators.py", line 50, in handler
    return func(*args, **kwargs)
  File "E:\pythonProject\venv\lib\site-packages\gerapy\server\core\views.py", line 120, in client_status
    requests.get(scrapyd_url(client.ip, client.port), timeout=3)
  File "E:\pythonProject\venv\lib\site-packages\requests\api.py", line 75, in get
    return request('get', url, params=params, **kwargs)
  File "E:\pythonProject\venv\lib\site-packages\requests\api.py", line 61, in request
    return session.request(method=method, url=url, **kwargs)
  File "E:\pythonProject\venv\lib\site-packages\requests\sessions.py", line 529, in request
    resp = self.send(prep, **send_kwargs)
  File "E:\pythonProject\venv\lib\site-packages\requests\sessions.py", line 645, in send
    r = adapter.send(request, **kwargs)
  File "E:\pythonProject\venv\lib\site-packages\requests\adapters.py", line 507, in send
    raise ConnectTimeout(e, request=request)
requests.exceptions.ConnectTimeout: HTTPConnectionPool(host='192.168.1.103', port=6800): Max retries exceeded with url: / (Caused by ConnectTimeoutError(<urllib3.connection.HTTPConnection object at 0x00000240F91EEE80>, 'Connection to 192.168.1.103 timed out. (connect timeout=3)'))
