INFO - 2022-09-18 17:59:51,476 - process: 3140 - scheduler.py - gerapy.server.core.scheduler - 105 - scheduler - successfully synced task with jobs with force
ERROR - 2022-09-18 18:01:22,644 - process: 3140 - utils.py - gerapy.server.core.utils - 564 - utils - HTTPConnectionPool(host='192.168.1.103', port=6800): Max retries exceeded with url: / (Caused by NewConnectionError('<urllib3.connection.HTTPConnection object at 0x000002984801A370>: Failed to establish a new connection: [WinError 10061] 由于目标计算机积极拒绝，无法连接。'))
Traceback (most recent call last):
  File "E:\pythonProject\venv\lib\site-packages\urllib3\connection.py", line 174, in _new_conn
    conn = connection.create_connection(
  File "E:\pythonProject\venv\lib\site-packages\urllib3\util\connection.py", line 95, in create_connection
    raise err
  File "E:\pythonProject\venv\lib\site-packages\urllib3\util\connection.py", line 85, in create_connection
    sock.connect(sa)
ConnectionRefusedError: [WinError 10061] 由于目标计算机积极拒绝，无法连接。

During handling of the above exception, another exception occurred:

Traceback (most recent call last):
  File "E:\pythonProject\venv\lib\site-packages\urllib3\connectionpool.py", line 703, in urlopen
    httplib_response = self._make_request(
  File "E:\pythonProject\venv\lib\site-packages\urllib3\connectionpool.py", line 398, in _make_request
    conn.request(method, url, **httplib_request_kw)
  File "E:\pythonProject\venv\lib\site-packages\urllib3\connection.py", line 239, in request
    super(HTTPConnection, self).request(method, url, body=body, headers=headers)
  File "D:\develop\python\python\lib\http\client.py", line 1285, in request
    self._send_request(method, url, body, headers, encode_chunked)
  File "D:\develop\python\python\lib\http\client.py", line 1331, in _send_request
    self.endheaders(body, encode_chunked=encode_chunked)
  File "D:\develop\python\python\lib\http\client.py", line 1280, in endheaders
    self._send_output(message_body, encode_chunked=encode_chunked)
  File "D:\develop\python\python\lib\http\client.py", line 1040, in _send_output
    self.send(msg)
  File "D:\develop\python\python\lib\http\client.py", line 980, in send
    self.connect()
  File "E:\pythonProject\venv\lib\site-packages\urllib3\connection.py", line 205, in connect
    conn = self._new_conn()
  File "E:\pythonProject\venv\lib\site-packages\urllib3\connection.py", line 186, in _new_conn
    raise NewConnectionError(
urllib3.exceptions.NewConnectionError: <urllib3.connection.HTTPConnection object at 0x000002984801A370>: Failed to establish a new connection: [WinError 10061] 由于目标计算机积极拒绝，无法连接。

During handling of the above exception, another exception occurred:

Traceback (most recent call last):
  File "E:\pythonProject\venv\lib\site-packages\requests\adapters.py", line 440, in send
    resp = conn.urlopen(
  File "E:\pythonProject\venv\lib\site-packages\urllib3\connectionpool.py", line 785, in urlopen
    retries = retries.increment(
  File "E:\pythonProject\venv\lib\site-packages\urllib3\util\retry.py", line 592, in increment
    raise MaxRetryError(_pool, url, error or ResponseError(cause))
urllib3.exceptions.MaxRetryError: HTTPConnectionPool(host='192.168.1.103', port=6800): Max retries exceeded with url: / (Caused by NewConnectionError('<urllib3.connection.HTTPConnection object at 0x000002984801A370>: Failed to establish a new connection: [WinError 10061] 由于目标计算机积极拒绝，无法连接。'))

During handling of the above exception, another exception occurred:

Traceback (most recent call last):
  File "E:\pythonProject\venv\lib\site-packages\gerapy\server\core\utils.py", line 562, in wrapper
    result = func(*args, **kwargs)
  File "E:\pythonProject\venv\lib\site-packages\django\views\decorators\csrf.py", line 54, in wrapped_view
    return view_func(*args, **kwargs)
  File "E:\pythonProject\venv\lib\site-packages\django\views\generic\base.py", line 71, in view
    return self.dispatch(request, *args, **kwargs)
  File "E:\pythonProject\venv\lib\site-packages\rest_framework\views.py", line 509, in dispatch
    response = self.handle_exception(exc)
  File "E:\pythonProject\venv\lib\site-packages\rest_framework\views.py", line 469, in handle_exception
    self.raise_uncaught_exception(exc)
  File "E:\pythonProject\venv\lib\site-packages\rest_framework\views.py", line 480, in raise_uncaught_exception
    raise exc
  File "E:\pythonProject\venv\lib\site-packages\rest_framework\views.py", line 506, in dispatch
    response = handler(request, *args, **kwargs)
  File "E:\pythonProject\venv\lib\site-packages\rest_framework\decorators.py", line 50, in handler
    return func(*args, **kwargs)
  File "E:\pythonProject\venv\lib\site-packages\gerapy\server\core\views.py", line 120, in client_status
    requests.get(scrapyd_url(client.ip, client.port), timeout=3)
  File "E:\pythonProject\venv\lib\site-packages\requests\api.py", line 75, in get
    return request('get', url, params=params, **kwargs)
  File "E:\pythonProject\venv\lib\site-packages\requests\api.py", line 61, in request
    return session.request(method=method, url=url, **kwargs)
  File "E:\pythonProject\venv\lib\site-packages\requests\sessions.py", line 529, in request
    resp = self.send(prep, **send_kwargs)
  File "E:\pythonProject\venv\lib\site-packages\requests\sessions.py", line 645, in send
    r = adapter.send(request, **kwargs)
  File "E:\pythonProject\venv\lib\site-packages\requests\adapters.py", line 519, in send
    raise ConnectionError(e, request=request)
requests.exceptions.ConnectionError: HTTPConnectionPool(host='192.168.1.103', port=6800): Max retries exceeded with url: / (Caused by NewConnectionError('<urllib3.connection.HTTPConnection object at 0x000002984801A370>: Failed to establish a new connection: [WinError 10061] 由于目标计算机积极拒绝，无法连接。'))
ERROR - 2022-09-18 18:04:11,303 - process: 3140 - utils.py - gerapy.server.core.utils - 564 - utils - HTTPConnectionPool(host='192.168.1.103', port=6800): Max retries exceeded with url: /listjobs.json?project=test (Caused by NewConnectionError('<urllib3.connection.HTTPConnection object at 0x0000029847EAE520>: Failed to establish a new connection: [WinError 10061] 由于目标计算机积极拒绝，无法连接。'))
Traceback (most recent call last):
  File "E:\pythonProject\venv\lib\site-packages\urllib3\connection.py", line 174, in _new_conn
    conn = connection.create_connection(
  File "E:\pythonProject\venv\lib\site-packages\urllib3\util\connection.py", line 95, in create_connection
    raise err
  File "E:\pythonProject\venv\lib\site-packages\urllib3\util\connection.py", line 85, in create_connection
    sock.connect(sa)
ConnectionRefusedError: [WinError 10061] 由于目标计算机积极拒绝，无法连接。

During handling of the above exception, another exception occurred:

Traceback (most recent call last):
  File "E:\pythonProject\venv\lib\site-packages\urllib3\connectionpool.py", line 703, in urlopen
    httplib_response = self._make_request(
  File "E:\pythonProject\venv\lib\site-packages\urllib3\connectionpool.py", line 398, in _make_request
    conn.request(method, url, **httplib_request_kw)
  File "E:\pythonProject\venv\lib\site-packages\urllib3\connection.py", line 239, in request
    super(HTTPConnection, self).request(method, url, body=body, headers=headers)
  File "D:\develop\python\python\lib\http\client.py", line 1285, in request
    self._send_request(method, url, body, headers, encode_chunked)
  File "D:\develop\python\python\lib\http\client.py", line 1331, in _send_request
    self.endheaders(body, encode_chunked=encode_chunked)
  File "D:\develop\python\python\lib\http\client.py", line 1280, in endheaders
    self._send_output(message_body, encode_chunked=encode_chunked)
  File "D:\develop\python\python\lib\http\client.py", line 1040, in _send_output
    self.send(msg)
  File "D:\develop\python\python\lib\http\client.py", line 980, in send
    self.connect()
  File "E:\pythonProject\venv\lib\site-packages\urllib3\connection.py", line 205, in connect
    conn = self._new_conn()
  File "E:\pythonProject\venv\lib\site-packages\urllib3\connection.py", line 186, in _new_conn
    raise NewConnectionError(
urllib3.exceptions.NewConnectionError: <urllib3.connection.HTTPConnection object at 0x0000029847EAE520>: Failed to establish a new connection: [WinError 10061] 由于目标计算机积极拒绝，无法连接。

During handling of the above exception, another exception occurred:

Traceback (most recent call last):
  File "E:\pythonProject\venv\lib\site-packages\requests\adapters.py", line 440, in send
    resp = conn.urlopen(
  File "E:\pythonProject\venv\lib\site-packages\urllib3\connectionpool.py", line 785, in urlopen
    retries = retries.increment(
  File "E:\pythonProject\venv\lib\site-packages\urllib3\util\retry.py", line 592, in increment
    raise MaxRetryError(_pool, url, error or ResponseError(cause))
urllib3.exceptions.MaxRetryError: HTTPConnectionPool(host='192.168.1.103', port=6800): Max retries exceeded with url: /listjobs.json?project=test (Caused by NewConnectionError('<urllib3.connection.HTTPConnection object at 0x0000029847EAE520>: Failed to establish a new connection: [WinError 10061] 由于目标计算机积极拒绝，无法连接。'))

During handling of the above exception, another exception occurred:

Traceback (most recent call last):
  File "E:\pythonProject\venv\lib\site-packages\gerapy\server\core\utils.py", line 562, in wrapper
    result = func(*args, **kwargs)
  File "E:\pythonProject\venv\lib\site-packages\django\views\decorators\csrf.py", line 54, in wrapped_view
    return view_func(*args, **kwargs)
  File "E:\pythonProject\venv\lib\site-packages\django\views\generic\base.py", line 71, in view
    return self.dispatch(request, *args, **kwargs)
  File "E:\pythonProject\venv\lib\site-packages\rest_framework\views.py", line 509, in dispatch
    response = self.handle_exception(exc)
  File "E:\pythonProject\venv\lib\site-packages\rest_framework\views.py", line 469, in handle_exception
    self.raise_uncaught_exception(exc)
  File "E:\pythonProject\venv\lib\site-packages\rest_framework\views.py", line 480, in raise_uncaught_exception
    raise exc
  File "E:\pythonProject\venv\lib\site-packages\rest_framework\views.py", line 506, in dispatch
    response = handler(request, *args, **kwargs)
  File "E:\pythonProject\venv\lib\site-packages\rest_framework\decorators.py", line 50, in handler
    return func(*args, **kwargs)
  File "E:\pythonProject\venv\lib\site-packages\gerapy\server\core\views.py", line 690, in job_list
    result = scrapyd.list_jobs(project_name)
  File "E:\pythonProject\venv\lib\site-packages\scrapyd_api\wrapper.py", line 139, in list_jobs
    jobs = self.client.get(url, params=params, timeout=self.timeout)
  File "E:\pythonProject\venv\lib\site-packages\requests\sessions.py", line 542, in get
    return self.request('GET', url, **kwargs)
  File "E:\pythonProject\venv\lib\site-packages\scrapyd_api\client.py", line 37, in request
    response = super(Client, self).request(*args, **kwargs)
  File "E:\pythonProject\venv\lib\site-packages\requests\sessions.py", line 529, in request
    resp = self.send(prep, **send_kwargs)
  File "E:\pythonProject\venv\lib\site-packages\requests\sessions.py", line 645, in send
    r = adapter.send(request, **kwargs)
  File "E:\pythonProject\venv\lib\site-packages\requests\adapters.py", line 519, in send
    raise ConnectionError(e, request=request)
requests.exceptions.ConnectionError: HTTPConnectionPool(host='192.168.1.103', port=6800): Max retries exceeded with url: /listjobs.json?project=test (Caused by NewConnectionError('<urllib3.connection.HTTPConnection object at 0x0000029847EAE520>: Failed to establish a new connection: [WinError 10061] 由于目标计算机积极拒绝，无法连接。'))
ERROR - 2022-09-18 18:04:13,312 - process: 3140 - utils.py - gerapy.server.core.utils - 564 - utils - HTTPConnectionPool(host='192.168.1.103', port=6800): Max retries exceeded with url: /logs/test/amazon/e8256f1a373811ed8a2afda4a4fa5fe0.log (Caused by NewConnectionError('<urllib3.connection.HTTPConnection object at 0x0000029847D555B0>: Failed to establish a new connection: [WinError 10061] 由于目标计算机积极拒绝，无法连接。'))
Traceback (most recent call last):
  File "E:\pythonProject\venv\lib\site-packages\urllib3\connection.py", line 174, in _new_conn
    conn = connection.create_connection(
  File "E:\pythonProject\venv\lib\site-packages\urllib3\util\connection.py", line 95, in create_connection
    raise err
  File "E:\pythonProject\venv\lib\site-packages\urllib3\util\connection.py", line 85, in create_connection
    sock.connect(sa)
ConnectionRefusedError: [WinError 10061] 由于目标计算机积极拒绝，无法连接。

During handling of the above exception, another exception occurred:

Traceback (most recent call last):
  File "E:\pythonProject\venv\lib\site-packages\urllib3\connectionpool.py", line 703, in urlopen
    httplib_response = self._make_request(
  File "E:\pythonProject\venv\lib\site-packages\urllib3\connectionpool.py", line 398, in _make_request
    conn.request(method, url, **httplib_request_kw)
  File "E:\pythonProject\venv\lib\site-packages\urllib3\connection.py", line 239, in request
    super(HTTPConnection, self).request(method, url, body=body, headers=headers)
  File "D:\develop\python\python\lib\http\client.py", line 1285, in request
    self._send_request(method, url, body, headers, encode_chunked)
  File "D:\develop\python\python\lib\http\client.py", line 1331, in _send_request
    self.endheaders(body, encode_chunked=encode_chunked)
  File "D:\develop\python\python\lib\http\client.py", line 1280, in endheaders
    self._send_output(message_body, encode_chunked=encode_chunked)
  File "D:\develop\python\python\lib\http\client.py", line 1040, in _send_output
    self.send(msg)
  File "D:\develop\python\python\lib\http\client.py", line 980, in send
    self.connect()
  File "E:\pythonProject\venv\lib\site-packages\urllib3\connection.py", line 205, in connect
    conn = self._new_conn()
  File "E:\pythonProject\venv\lib\site-packages\urllib3\connection.py", line 186, in _new_conn
    raise NewConnectionError(
urllib3.exceptions.NewConnectionError: <urllib3.connection.HTTPConnection object at 0x0000029847D555B0>: Failed to establish a new connection: [WinError 10061] 由于目标计算机积极拒绝，无法连接。

During handling of the above exception, another exception occurred:

Traceback (most recent call last):
  File "E:\pythonProject\venv\lib\site-packages\requests\adapters.py", line 440, in send
    resp = conn.urlopen(
  File "E:\pythonProject\venv\lib\site-packages\urllib3\connectionpool.py", line 785, in urlopen
    retries = retries.increment(
  File "E:\pythonProject\venv\lib\site-packages\urllib3\util\retry.py", line 592, in increment
    raise MaxRetryError(_pool, url, error or ResponseError(cause))
urllib3.exceptions.MaxRetryError: HTTPConnectionPool(host='192.168.1.103', port=6800): Max retries exceeded with url: /logs/test/amazon/e8256f1a373811ed8a2afda4a4fa5fe0.log (Caused by NewConnectionError('<urllib3.connection.HTTPConnection object at 0x0000029847D555B0>: Failed to establish a new connection: [WinError 10061] 由于目标计算机积极拒绝，无法连接。'))

During handling of the above exception, another exception occurred:

Traceback (most recent call last):
  File "E:\pythonProject\venv\lib\site-packages\gerapy\server\core\utils.py", line 562, in wrapper
    result = func(*args, **kwargs)
  File "E:\pythonProject\venv\lib\site-packages\django\views\decorators\csrf.py", line 54, in wrapped_view
    return view_func(*args, **kwargs)
  File "E:\pythonProject\venv\lib\site-packages\django\views\generic\base.py", line 71, in view
    return self.dispatch(request, *args, **kwargs)
  File "E:\pythonProject\venv\lib\site-packages\rest_framework\views.py", line 509, in dispatch
    response = self.handle_exception(exc)
  File "E:\pythonProject\venv\lib\site-packages\rest_framework\views.py", line 469, in handle_exception
    self.raise_uncaught_exception(exc)
  File "E:\pythonProject\venv\lib\site-packages\rest_framework\views.py", line 480, in raise_uncaught_exception
    raise exc
  File "E:\pythonProject\venv\lib\site-packages\rest_framework\views.py", line 506, in dispatch
    response = handler(request, *args, **kwargs)
  File "E:\pythonProject\venv\lib\site-packages\rest_framework\decorators.py", line 50, in handler
    return func(*args, **kwargs)
  File "E:\pythonProject\venv\lib\site-packages\gerapy\server\core\views.py", line 719, in job_log
    response = requests.get(url, timeout=5, headers={
  File "E:\pythonProject\venv\lib\site-packages\requests\api.py", line 75, in get
    return request('get', url, params=params, **kwargs)
  File "E:\pythonProject\venv\lib\site-packages\requests\api.py", line 61, in request
    return session.request(method=method, url=url, **kwargs)
  File "E:\pythonProject\venv\lib\site-packages\requests\sessions.py", line 529, in request
    resp = self.send(prep, **send_kwargs)
  File "E:\pythonProject\venv\lib\site-packages\requests\sessions.py", line 645, in send
    r = adapter.send(request, **kwargs)
  File "E:\pythonProject\venv\lib\site-packages\requests\adapters.py", line 519, in send
    raise ConnectionError(e, request=request)
requests.exceptions.ConnectionError: HTTPConnectionPool(host='192.168.1.103', port=6800): Max retries exceeded with url: /logs/test/amazon/e8256f1a373811ed8a2afda4a4fa5fe0.log (Caused by NewConnectionError('<urllib3.connection.HTTPConnection object at 0x0000029847D555B0>: Failed to establish a new connection: [WinError 10061] 由于目标计算机积极拒绝，无法连接。'))
ERROR - 2022-09-18 18:04:16,284 - process: 3140 - utils.py - gerapy.server.core.utils - 564 - utils - HTTPConnectionPool(host='192.168.1.103', port=6800): Max retries exceeded with url: /listjobs.json?project=test (Caused by NewConnectionError('<urllib3.connection.HTTPConnection object at 0x000002984806AD60>: Failed to establish a new connection: [WinError 10061] 由于目标计算机积极拒绝，无法连接。'))
Traceback (most recent call last):
  File "E:\pythonProject\venv\lib\site-packages\urllib3\connection.py", line 174, in _new_conn
    conn = connection.create_connection(
  File "E:\pythonProject\venv\lib\site-packages\urllib3\util\connection.py", line 95, in create_connection
    raise err
  File "E:\pythonProject\venv\lib\site-packages\urllib3\util\connection.py", line 85, in create_connection
    sock.connect(sa)
ConnectionRefusedError: [WinError 10061] 由于目标计算机积极拒绝，无法连接。

During handling of the above exception, another exception occurred:

Traceback (most recent call last):
  File "E:\pythonProject\venv\lib\site-packages\urllib3\connectionpool.py", line 703, in urlopen
    httplib_response = self._make_request(
  File "E:\pythonProject\venv\lib\site-packages\urllib3\connectionpool.py", line 398, in _make_request
    conn.request(method, url, **httplib_request_kw)
  File "E:\pythonProject\venv\lib\site-packages\urllib3\connection.py", line 239, in request
    super(HTTPConnection, self).request(method, url, body=body, headers=headers)
  File "D:\develop\python\python\lib\http\client.py", line 1285, in request
    self._send_request(method, url, body, headers, encode_chunked)
  File "D:\develop\python\python\lib\http\client.py", line 1331, in _send_request
    self.endheaders(body, encode_chunked=encode_chunked)
  File "D:\develop\python\python\lib\http\client.py", line 1280, in endheaders
    self._send_output(message_body, encode_chunked=encode_chunked)
  File "D:\develop\python\python\lib\http\client.py", line 1040, in _send_output
    self.send(msg)
  File "D:\develop\python\python\lib\http\client.py", line 980, in send
    self.connect()
  File "E:\pythonProject\venv\lib\site-packages\urllib3\connection.py", line 205, in connect
    conn = self._new_conn()
  File "E:\pythonProject\venv\lib\site-packages\urllib3\connection.py", line 186, in _new_conn
    raise NewConnectionError(
urllib3.exceptions.NewConnectionError: <urllib3.connection.HTTPConnection object at 0x000002984806AD60>: Failed to establish a new connection: [WinError 10061] 由于目标计算机积极拒绝，无法连接。

During handling of the above exception, another exception occurred:

Traceback (most recent call last):
  File "E:\pythonProject\venv\lib\site-packages\requests\adapters.py", line 440, in send
    resp = conn.urlopen(
  File "E:\pythonProject\venv\lib\site-packages\urllib3\connectionpool.py", line 785, in urlopen
    retries = retries.increment(
  File "E:\pythonProject\venv\lib\site-packages\urllib3\util\retry.py", line 592, in increment
    raise MaxRetryError(_pool, url, error or ResponseError(cause))
urllib3.exceptions.MaxRetryError: HTTPConnectionPool(host='192.168.1.103', port=6800): Max retries exceeded with url: /listjobs.json?project=test (Caused by NewConnectionError('<urllib3.connection.HTTPConnection object at 0x000002984806AD60>: Failed to establish a new connection: [WinError 10061] 由于目标计算机积极拒绝，无法连接。'))

During handling of the above exception, another exception occurred:

Traceback (most recent call last):
  File "E:\pythonProject\venv\lib\site-packages\gerapy\server\core\utils.py", line 562, in wrapper
    result = func(*args, **kwargs)
  File "E:\pythonProject\venv\lib\site-packages\django\views\decorators\csrf.py", line 54, in wrapped_view
    return view_func(*args, **kwargs)
  File "E:\pythonProject\venv\lib\site-packages\django\views\generic\base.py", line 71, in view
    return self.dispatch(request, *args, **kwargs)
  File "E:\pythonProject\venv\lib\site-packages\rest_framework\views.py", line 509, in dispatch
    response = self.handle_exception(exc)
  File "E:\pythonProject\venv\lib\site-packages\rest_framework\views.py", line 469, in handle_exception
    self.raise_uncaught_exception(exc)
  File "E:\pythonProject\venv\lib\site-packages\rest_framework\views.py", line 480, in raise_uncaught_exception
    raise exc
  File "E:\pythonProject\venv\lib\site-packages\rest_framework\views.py", line 506, in dispatch
    response = handler(request, *args, **kwargs)
  File "E:\pythonProject\venv\lib\site-packages\rest_framework\decorators.py", line 50, in handler
    return func(*args, **kwargs)
  File "E:\pythonProject\venv\lib\site-packages\gerapy\server\core\views.py", line 690, in job_list
    result = scrapyd.list_jobs(project_name)
  File "E:\pythonProject\venv\lib\site-packages\scrapyd_api\wrapper.py", line 139, in list_jobs
    jobs = self.client.get(url, params=params, timeout=self.timeout)
  File "E:\pythonProject\venv\lib\site-packages\requests\sessions.py", line 542, in get
    return self.request('GET', url, **kwargs)
  File "E:\pythonProject\venv\lib\site-packages\scrapyd_api\client.py", line 37, in request
    response = super(Client, self).request(*args, **kwargs)
  File "E:\pythonProject\venv\lib\site-packages\requests\sessions.py", line 529, in request
    resp = self.send(prep, **send_kwargs)
  File "E:\pythonProject\venv\lib\site-packages\requests\sessions.py", line 645, in send
    r = adapter.send(request, **kwargs)
  File "E:\pythonProject\venv\lib\site-packages\requests\adapters.py", line 519, in send
    raise ConnectionError(e, request=request)
requests.exceptions.ConnectionError: HTTPConnectionPool(host='192.168.1.103', port=6800): Max retries exceeded with url: /listjobs.json?project=test (Caused by NewConnectionError('<urllib3.connection.HTTPConnection object at 0x000002984806AD60>: Failed to establish a new connection: [WinError 10061] 由于目标计算机积极拒绝，无法连接。'))
